Workbook

Sheet Delivery Plan
A1: Delivery Plan ID | B1: Campaign | C1: Planning Date | D1: LBA Code | E1: Supplier Name | F1: Expected Origin | G1: Destination Warehouse | H1: Expected Delivery Start | I1: Expected Delivery End | J1: Expected Quantity (kg) | K1: Expected Trucks | L1: Purchase / Funding Reference | M1: Plan Status | N1: Actual Received Quantity (kg) | O1: Actual Arrivals | P1: Accepted Trucks | Q1: Remaining Quantity (kg) | R1: Quantity Variance (kg) | S1: Planning Scenario | T1: Planning Basis
A2: DP-BKE-2026-001 | B2: 2026 | C2: 46069 | D2: LBA-002-SCA | E2: SCAAMT COOP CA | F2: VAVOUA | G2: BKE-003 | H2: 46071 | I2: 46149 | J2: 142424 | K2: 4 | L2: Not available in 2026 source | M2: DELIVERED | N2: =SUMIFS('Truck Reception'!$AD$2:$AD$500,'Truck Reception'!$AJ$2:$AJ$500,A2) -> 142424 | O2: =COUNTIF('Truck Reception'!$AJ$2:$AJ$500,A2) -> 4 | P2: =COUNTIFS('Truck Reception'!$AJ$2:$AJ$500,A2,'Truck Reception'!$AO$2:$AO$500,"STOCKED") -> 3 | Q2: =J2-N2 -> 0 | R2: =N2-J2 -> 0 | S2: NORMAL | T2: Reconstructed from 2026 actual receipts; Delivery Plan did not exist as a structured legacy field.
A3: DP-BKE-2026-002 | B3: 2026 | C3: 46068 | D3: LBA-011-ASR | E3: SCOOP ASER | F3: MANKONO | G3: BKE-001 | H3: 46071 | I3: 46146 | J3: 149036 | K3: 4 | L3: Not available in 2026 source | M3: DELIVERED | N3: =SUMIFS('Truck Reception'!$AD$2:$AD$500,'Truck Reception'!$AJ$2:$AJ$500,A3) -> 149036 | O3: =COUNTIF('Truck Reception'!$AJ$2:$AJ$500,A3) -> 4 | P3: =COUNTIFS('Truck Reception'!$AJ$2:$AJ$500,A3,'Truck Reception'!$AO$2:$AO$500,"STOCKED") -> 3 | Q3: =J3-N3 -> 0 | R3: =N3-J3 -> 0 | S3: EARLY DELIVERY | T3: Reconstructed from 2026 actual receipts; Delivery Plan did not exist as a structured legacy field.
A4: DP-BKE-2026-003 | B4: 2026 | C4: 46075 | D4: LBA-018-COP | E4: SCOOPS COOPRAKA | F4: KATIOLA | G4: BKE-003 | H4: 46077 | I4: 46145 | J4: 116106 | K4: 4 | L4: Not available in 2026 source | M4: DELIVERED | N4: =SUMIFS('Truck Reception'!$AD$2:$AD$500,'Truck Reception'!$AJ$2:$AJ$500,A4) -> 116106 | O4: =COUNTIF('Truck Reception'!$AJ$2:$AJ$500,A4) -> 4 | P4: =COUNTIFS('Truck Reception'!$AJ$2:$AJ$500,A4,'Truck Reception'!$AO$2:$AO$500,"STOCKED") -> 3 | Q4: =J4-N4 -> 0 | R4: =N4-J4 -> 0 | S4: LATE DELIVERY | T4: Reconstructed from 2026 actual receipts; Delivery Plan did not exist as a structured legacy field.
A5: DP-BKE-2026-004 | B5: 2026 | C5: 46120 | D5: LBA-021-SAN | E5: SANOGO SINDOU | F5: MANKONO | H5: 46122 | I5: 46146 | J5: 134389 | K5: 4 | L5: Not available in 2026 source | M5: DELIVERED | N5: =SUMIFS('Truck Reception'!$AD$2:$AD$500,'Truck Reception'!$AJ$2:$AJ$500,A5) -> 134389 | O5: =COUNTIF('Truck Reception'!$AJ$2:$AJ$500,A5) -> 4 | P5: =COUNTIFS('Truck Reception'!$AJ$2:$AJ$500,A5,'Truck Reception'!$AO$2:$AO$500,"STOCKED") -> 3 | Q5: =J5-N5 -> 0 | R5: =N5-J5 -> 0 | S5: ORIGIN MISMATCH | T5: Reconstructed from 2026 actual receipts; Delivery Plan did not exist as a structured legacy field.
A6: DP-BKE-2026-005 | B6: 2026 | C6: 46069 | D6: LBA-004-WEB | E6: SCOOPS WEBE | F6: DABAKALA | G6: BKE-003 | H6: 46071 | I6: 46146 | J6: 126434 | K6: 4 | L6: Not available in 2026 source | M6: DELIVERED | N6: =SUMIFS('Truck Reception'!$AD$2:$AD$500,'Truck Reception'!$AJ$2:$AJ$500,A6) -> 126434 | O6: =COUNTIF('Truck Reception'!$AJ$2:$AJ$500,A6) -> 4 | P6: =COUNTIFS('Truck Reception'!$AJ$2:$AJ$500,A6,'Truck Reception'!$AO$2:$AO$500,"STOCKED") -> 3 | Q6: =J6-N6 -> 0 | R6: =N6-J6 -> 0 | S6: WAREHOUSE CHANGE | T6: Reconstructed from 2026 actual receipts; Delivery Plan did not exist as a structured legacy field.
A7: DP-BKE-2026-006 | B7: 2026 | C7: 46069 | D7: LBA-010-CAP | E7: CAPCD-SCOOPS | F7: BOUAKE | G7: BKE-002 | H7: 46071 | I7: 46145 | J7: 78715 | K7: 3 | L7: Not available in 2026 source | M7: DELIVERED | N7: =SUMIFS('Truck Reception'!$AD$2:$AD$500,'Truck Reception'!$AJ$2:$AJ$500,A7) -> 92606 | O7: =COUNTIF('Truck Reception'!$AJ$2:$AJ$500,A7) -> 3 | P7: =COUNTIFS('Truck Reception'!$AJ$2:$AJ$500,A7,'Truck Reception'!$AO$2:$AO$500,"STOCKED") -> 3 | Q7: =J7-N7 -> -13891 | R7: =N7-J7 -> 13891 | S7: PLAN EXCESS | T7: Reconstructed from 2026 actual receipts; Delivery Plan did not exist as a structured legacy field.
A8: DP-BKE-2026-007 | B8: 2026 | C8: 46068 | D8: LBA-003-HER | E8: SCOOPS HERE B | F8: NIAKARA | G8: BKE-001 | H8: 46070 | I8: 46144 | J8: 135594 | K8: 3 | L8: Not available in 2026 source | M8: CANCELLED | N8: =SUMIFS('Truck Reception'!$AD$2:$AD$500,'Truck Reception'!$AJ$2:$AJ$500,A8) -> 135594 | O8: =COUNTIF('Truck Reception'!$AJ$2:$AJ$500,A8) -> 3 | P8: =COUNTIFS('Truck Reception'!$AJ$2:$AJ$500,A8,'Truck Reception'!$AO$2:$AO$500,"STOCKED") -> 3 | Q8: =J8-N8 -> 0 | R8: =N8-J8 -> 0 | S8: CANCELLED PLAN ARRIVAL | T8: Reconstructed from 2026 actual receipts; Delivery Plan did not exist as a structured legacy field.
A9: DP-BKE-2026-008 | B9: 2026 | C9: 46068 | D9: LBA-015-OUM | E9: SCOOPS-OUMI/KONE SIDY | F9: BOUAKE | G9: BKE-001 | H9: 46070 | I9: 46146 | J9: 141898 | K9: 3 | L9: Not available in 2026 source | M9: DELIVERED | N9: =SUMIFS('Truck Reception'!$AD$2:$AD$500,'Truck Reception'!$AJ$2:$AJ$500,A9) -> 141898 | O9: =COUNTIF('Truck Reception'!$AJ$2:$AJ$500,A9) -> 3 | P9: =COUNTIFS('Truck Reception'!$AJ$2:$AJ$500,A9,'Truck Reception'!$AO$2:$AO$500,"STOCKED") -> 3 | Q9: =J9-N9 -> 0 | R9: =N9-J9 -> 0 | S9: MULTI-TRUCK NORMAL | T9: Reconstructed from 2026 actual receipts; Delivery Plan did not exist as a structured legacy field.
A10: DP-BKE-2026-009 | B10: 2026 | C10: 46072 | D10: LBA-016-NOU | E10: SCOOPS AH AL NOUR | F10: KATIOLA | G10: BKE-001 | H10: 46074 | I10: 46146 | J10: 128412 | K10: 3 | L10: Not available in 2026 source | M10: DELIVERED | N10: =SUMIFS('Truck Reception'!$AD$2:$AD$500,'Truck Reception'!$AJ$2:$AJ$500,A10) -> 128412 | O10: =COUNTIF('Truck Reception'!$AJ$2:$AJ$500,A10) -> 3 | P10: =COUNTIFS('Truck Reception'!$AJ$2:$AJ$500,A10,'Truck Reception'!$AO$2:$AO$500,"STOCKED") -> 3 | Q10: =J10-N10 -> 0 | R10: =N10-J10 -> 0 | S10: MULTI-TRUCK NORMAL | T10: Reconstructed from 2026 actual receipts; Delivery Plan did not exist as a structured legacy field.
A11: DP-BKE-2026-010 | B11: 2026 | C11: 46070 | D11: LBA-005-JAV | E11: COP JAVA SCOOPS | F11: VAVOUA | G11: BKE-003 | H11: 46072 | I11: 46144 | J11: 141583 | K11: 3 | L11: Not available in 2026 source | M11: DELIVERED | N11: =SUMIFS('Truck Reception'!$AD$2:$AD$500,'Truck Reception'!$AJ$2:$AJ$500,A11) -> 141583 | O11: =COUNTIF('Truck Reception'!$AJ$2:$AJ$500,A11) -> 3 | P11: =COUNTIFS('Truck Reception'!$AJ$2:$AJ$500,A11,'Truck Reception'!$AO$2:$AO$500,"STOCKED") -> 3 | Q11: =J11-N11 -> 0 | R11: =N11-J11 -> 0 | S11: MULTI-TRUCK NORMAL | T11: Reconstructed from 2026 actual receipts; Delivery Plan did not exist as a structured legacy field.

Sheet Truck Reception
A1: Receipt ID | B1: Arrival Date | C1: Offloading Date | D1: Payment Type | E1: Warehouse Location | F1: Warehouse Code | G1: Supplier Name | H1: Supplier Code | I1: Truck No | J1: Fiche Code | K1: Fiche No | L1: Origin | M1: Moisture (%) | N1: Nut Count | O1: KOR | P1: Final KOR | Q1: Quality Result | R1: Rejection Reason | S1: Gross Weight (kg) | T1: Tare Weight (kg) | U1: Net Weight (kg) | V1: Paid Weight (kg) | W1: Bags Count | X1: Good Bags | Y1: Humid Bags | Z1: Torn Bags | AA1: Refraction (kg) | AB1: Price (CFA/kg) | AC1: Amount (CFA) | AD1: GRN Quantity (kg) | AE1: Lot No | AF1: Bin No | AG1: Remarks | AH1: Week | AI1: Planned Delivery? | AJ1: Delivery Plan ID | AK1: Reception Type | AL1: Planning / Exception Flag | AM1: Exception Approval Status | AN1: Plan Link Status | AO1: Receipt Status
A2: REC-BKE-2026-0001 | B2: 46069 | C2: 46069 | D2: CREDIT | E2: BOUAKE | F2: BKE-002 | G2: SCOOP IMANE | H2: LBA-006-IMA | I2: 827KT01 | J2: 0401-0007 | K2: 72515 | L2: DIANRA | M2: 10.2 | N2: 172 | O2: 47.69 | P2: 48.4 | Q2: ACCEPTED | S2: 41300 | U2: 40822 | V2: =IF(OR(U2="",AA2=""),"",U2-AA2) -> 40762 | W2: 478 | X2: 463 | Y2: 0 | Z2: 15 | AA2: 60 | AB2: 470 | AC2: =IF(OR(V2="",AB2=""),"",V2*AB2) -> 19158140 | AD2: 40822 | AE2: LOT-BKE-2026-0001 | AH2: W-8 Feb | AI2: NO | AK2: UNPLANNED | AL2: UNPLANNED - known LBA, no pre-alert | AM2: APPROVED | AN2: NOT PLANNED | AO2: STOCKED
A3: REC-BKE-2026-0002 | B3: 46069 | C3: 46069 | D3: CREDIT | E3: BOUAKE | F3: BKE-002 | G3: CASP-S SCOOPS | H3: LBA-007-CAS | I3: 793LT03 | J3: 0429-0040 | K3: 72533 | L3: MANKONO | M3: 9 | N3: 165 | O3: 48.41 | P3: 48.22 | Q3: ACCEPTED | S3: 50880 | U3: 50252 | V3: =IF(OR(U3="",AA3=""),"",U3-AA3) -> 49976 | W3: 628 | X3: 559 | Y3: 0 | Z3: 69 | AA3: 276 | AB3: 490 | AC3: =IF(OR(V3="",AB3=""),"",V3*AB3) -> 24488240 | AD3: 50252 | AE3: LOT-BKE-2026-0002 | AH3: W-8 Feb | AI3: NO | AK3: UNPLANNED | AL3: UNPLANNED - known LBA, no pre-alert | AM3: APPROVED | AN3: NOT PLANNED | AO3: STOCKED
A4: REC-BKE-2026-0003 | B4: 46069 | D4: CREDIT | E4: BOUAKE | G4: CASP-S SCOOPS | H4: LBA-007-CAS | I4: 524LS01 | L4: MANKONO | M4: 8.7 | N4: 164 | O4: 44.35 | Q4: REJECTED | R4: REJECT | S4: 0 | U4: 0 | V4: 0 | W4: 0 | AB4: 0 | AC4: 0 | AG4: REJECT | AI4: NO | AK4: UNPLANNED | AL4: UNPLANNED / QUALITY REJECTED | AM4: N/A - REJECTED | AN4: NOT PLANNED | AO4: REJECTED
A5: REC-BKE-2026-0004 | B5: 46070 | C5: 46070 | D5: CREDIT | E5: BOUAKE | F5: BKE-002 | G5: SCOOPS HERE B | H5: LBA-003-HER | I5: 8287GH03 | J5: 0426-0187 | K5: 72615 | L5: NIAKARA | M5: 11.4 | N5: 162 | O5: 46.11 | Q5: ACCEPTED | S5: 45420 | U5: 44908 | V5: =IF(OR(U5="",AA5=""),"",U5-AA5) -> 44876 | W5: 512 | X5: 504 | Y5: 0 | Z5: 8 | AA5: 32 | AB5: 470 | AC5: =IF(OR(V5="",AB5=""),"",V5*AB5) -> 21091720 | AD5: 44908 | AE5: LOT-BKE-2026-0003 | AF5: BKE-002-BIN-004 / BKE-002-BIN-006 | AH5: W-8 Feb | AI5: YES | AJ5: DP-BKE-2026-007 | AK5: PLANNED WITH EXCEPTION | AL5: PLAN CANCELLED - ARRIVAL RECORDED; WAREHOUSE CHANGE | AM5: APPROVED | AN5: PLANNED FROM START | AO5: STOCKED
A6: REC-BKE-2026-0005 | B6: 46070 | C6: 46070 | D6: CREDIT | E6: BOUAKE | F6: BKE-003 | G6: SCOPPAS SCOOPS | H6: LBA-009-SCO | I6: 338KX01 | J6: 0426-0203 | K6: 72540 | L6: BOUAKE | M6: 9.5 | N6: 166 | O6: 48.57 | P6: 48.04 | Q6: ACCEPTED | S6: 35320 | U6: 34895 | V6: =IF(OR(U6="",AA6=""),"",U6-AA6) -> 34795 | W6: 425 | X6: 400 | Y6: 0 | Z6: 25 | AA6: 100 | AB6: 470 | AC6: =IF(OR(V6="",AB6=""),"",V6*AB6) -> 16353650 | AD6: 34895 | AE6: LOT-BKE-2026-0004 | AH6: W-8 Feb | AI6: NO | AK6: UNPLANNED | AL6: UNPLANNED - known LBA, no pre-alert | AM6: APPROVED | AN6: NOT PLANNED | AO6: STOCKED
A7: REC-BKE-2026-0006 | B7: 46070 | C7: 46070 | D7: CREDIT | E7: BOUAKE | F7: BKE-002 | G7: DAGNOGO KARIM | H7: LBA-013-DAG | I7: 3633LZ04 | J7: 0425-0068 | K7: 72569 | L7: NIAKARA | M7: 11.5 | N7: 161 | O7: 47.87 | Q7: ACCEPTED | S7: 50760 | U7: 50174 | V7: =IF(OR(U7="",AA7=""),"",U7-AA7) -> 49622 | W7: 586 | X7: 556 | Y7: 12 | Z7: 18 | AA7: 552 | AB7: 470 | AC7: =IF(OR(V7="",AB7=""),"",V7*AB7) -> 23322340 | AD7: 50174 | AE7: LOT-BKE-2026-0005 | AF7: BKE-002-BIN-003 | AH7: W-8 Feb | AI7: NO | AK7: UNPLANNED | AL7: UNPLANNED - known LBA, no pre-alert | AM7: APPROVED | AN7: NOT PLANNED | AO7: STOCKED
A8: REC-BKE-2026-0007 | B8: 46070 | C8: 46070 | D8: CREDIT | E8: BOUAKE | F8: BKE-002 | G8: SCOOPS BAY SCOOPS | H8: LBA-014-BAY | I8: 3509KJ01 | J8: 0426-0194 | K8: 72607 | L8: MANKONO | M8: 9.1 | N8: 163 | O8: 47.08 | P8: 47.16 | Q8: ACCEPTED | S8: 39460 | U8: 39018 | V8: =IF(OR(U8="",AA8=""),"",U8-AA8) -> 38998 | W8: 442 | X8: 437 | Y8: 0 | Z8: 5 | AA8: 20 | AB8: 470 | AC8: =IF(OR(V8="",AB8=""),"",V8*AB8) -> 18329060 | AD8: 39018 | AE8: LOT-BKE-2026-0006 | AH8: W-8 Feb | AI8: NO | AK8: UNPLANNED | AL8: UNPLANNED - known LBA, no pre-alert | AM8: APPROVED | AN8: NOT PLANNED | AO8: STOCKED
A9: REC-BKE-2026-0008 | B9: 46070 | C9: 46070 | D9: CREDIT | E9: BOUAKE | F9: BKE-002 | G9: SCOOPS-OUMI/KONE SIDY | H9: LBA-015-OUM | I9: 28JZ01 | J9: 0426-0347 | K9: 72564 | L9: BOUAKE | M9: 9.2 | N9: 172 | O9: 48.04 | P9: 48.4 | Q9: ACCEPTED | S9: 49020 | U9: 48450 | V9: =IF(OR(U9="",AA9=""),"",U9-AA9) -> 48390 | W9: 570 | X9: 555 | Y9: 0 | Z9: 15 | AA9: 60 | AB9: 470 | AC9: =IF(OR(V9="",AB9=""),"",V9*AB9) -> 22743300 | AD9: 48450 | AE9: LOT-BKE-2026-0007 | AH9: W-8 Feb | AI9: YES | AJ9: DP-BKE-2026-008 | AK9: PLANNED WITH EXCEPTION | AL9: WAREHOUSE CHANGE | AM9: APPROVED | AN9: PLANNED FROM START | AO9: STOCKED
A10: REC-BKE-2026-0009 | B10: 46070 | D10: CREDIT | E10: BOUAKE | G10: SCOOP ASER | H10: LBA-011-ASR | I10: AA398TS04 | L10: BOUAKE | M10: 9.3 | N10: 185 | O10: 45.4 | Q10: REJECTED | R10: REJECT | S10: 0 | U10: 0 | V10: 0 | W10: 0 | AB10: 0 | AC10: 0 | AG10: REJECT | AI10: YES | AJ10: DP-BKE-2026-002 | AK10: PLANNED WITH EXCEPTION | AL10: EARLY DELIVERY; ORIGIN MISMATCH | AM10: N/A - REJECTED | AN10: PLANNED FROM START | AO10: REJECTED
A11: REC-BKE-2026-0010 | B11: 46071 | C11: 46071 | D11: CREDIT | E11: BOUAKE | F11: BKE-003 | G11: SCAAMT COOP CA | H11: LBA-002-SCA | I11: AA864JL01 | J11: 0419-0180 | K11: 72517 | L11: VAVOUA | M11: 9.5 | N11: 178 | O11: 46.81 | P11: 47.16 | Q11: ACCEPTED | S11: 52060 | U11: 51446 | V11: =IF(OR(U11="",AA11=""),"",U11-AA11) -> 51302 | W11: 614 | X11: 578 | Y11: 0 | Z11: 36 | AA11: 144 | AB11: 470 | AC11: =IF(OR(V11="",AB11=""),"",V11*AB11) -> 24111940 | AD11: 51446 | AE11: LOT-BKE-2026-0008 | AH11: W-8 Feb | AI11: YES | AJ11: DP-BKE-2026-001 | AK11: PLANNED | AL11: ON PLAN | AM11: NOT REQUIRED | AN11: PLANNED FROM START | AO11: STOCKED
A12: REC-BKE-2026-0011 | B12: 46071 | C12: 46071 | D12: CREDIT | E12: BOUAKE | F12: BKE-003 | G12: SCOOPS WEBE | H12: LBA-004-WEB | I12: 5176LG04 | J12: 0425-0212 | K12: 72568 | L12: DABAKALA | M12: 9.6 | N12: 182 | O12: 48.22 | P12: 48.4 | Q12: ACCEPTED | S12: 41540 | U12: 41087 | V12: =IF(OR(U12="",AA12=""),"",U12-AA12) -> 40915 | W12: 453 | X12: 410 | Y12: 0 | Z12: 43 | AA12: 172 | AB12: 475 | AC12: =IF(OR(V12="",AB12=""),"",V12*AB12) -> 19434625 | AD12: 41087 | AE12: LOT-BKE-2026-0009 | AH12: W-8 Feb | AI12: YES | AJ12: DP-BKE-2026-005 | AK12: PLANNED | AL12: ON PLAN | AM12: NOT REQUIRED | AN12: PLANNED FROM START | AO12: STOCKED
A13: REC-BKE-2026-0012 | B13: 46071 | C13: 46071 | D13: CREDIT | E13: BOUAKE | F13: BKE-002 | G13: CAPCD-SCOOPS | H13: LBA-010-CAP | I13: AA562YL04 | J13: 0431-0277 | K13: 72523 | L13: DIANRA | M13: 11.2 | N13: 168 | O13: 48.04 | Q13: ACCEPTED | S13: 40560 | U13: 40097 | V13: =IF(OR(U13="",AA13=""),"",U13-AA13) -> 40057 | W13: 463 | X13: 453 | Y13: 0 | Z13: 10 | AA13: 40 | AB13: 475 | AC13: =IF(OR(V13="",AB13=""),"",V13*AB13) -> 19027075 | AD13: 40097 | AE13: LOT-BKE-2026-0010 | AH13: W-8 Feb | AI13: YES | AJ13: DP-BKE-2026-006 | AK13: PLANNED WITH EXCEPTION | AL13: ORIGIN MISMATCH | AM13: APPROVED | AN13: PLANNED FROM START | AO13: STOCKED
A14: REC-BKE-2026-0013 | B14: 46071 | C14: 46071 | D14: CREDIT | E14: BOUAKE | F14: BKE-003 | G14: SCOOP ASER | H14: LBA-011-ASR | I14: 2138HC01 | J14: 0426-0340 | K14: 72501 | L14: MANKONO | M14: 8.6 | N14: 171 | O14: 47.6 | P14: 47.87 | Q14: ACCEPTED | S14: 46680 | U14: 46118 | V14: =IF(OR(U14="",AA14=""),"",U14-AA14) -> 45966 | W14: 562 | X14: 524 | Y14: 0 | Z14: 38 | AA14: 152 | AB14: 470 | AC14: =IF(OR(V14="",AB14=""),"",V14*AB14) -> 21604020 | AD14: 46118 | AE14: LOT-BKE-2026-0011 | AH14: W-8 Feb | AI14: YES | AJ14: DP-BKE-2026-002 | AK14: PLANNED WITH EXCEPTION | AL14: WAREHOUSE CHANGE | AM14: APPROVED | AN14: PLANNED FROM START | AO14: STOCKED
A15: REC-BKE-2026-0014 | B15: 46071 | D15: CREDIT | E15: BOUAKE | G15: SCOOPS WEBE | H15: LBA-004-WEB | I15: AA533NN | L15: KORHOGO | M15: 8.1 | N15: 178 | O15: 44.35 | Q15: REJECTED | R15: REJECT | S15: 0 | V15: 0 | W15: 0 | AC15: 0 | AG15: REJECT | AI15: YES | AJ15: DP-BKE-2026-005 | AK15: PLANNED WITH EXCEPTION | AL15: ORIGIN MISMATCH | AM15: N/A - REJECTED | AN15: PLANNED FROM START | AO15: REJECTED
A16: REC-BKE-2026-0015 | B16: 46071 | D16: CREDIT | E16: BOUAKE | G16: SCOPPAS SCOOPS | H16: LBA-009-SCO | I16: 913HB04 | L16: KOUTO | M16: 7.5 | N16: 170 | O16: 44.7 | Q16: REJECTED | R16: REJECT | S16: 0 | V16: 0 | W16: 0 | AC16: 0 | AG16: REJECT | AI16: NO | AK16: UNPLANNED | AL16: UNPLANNED / QUALITY REJECTED | AM16: N/A - REJECTED | AN16: NOT PLANNED | AO16: REJECTED
A17: REC-BKE-2026-0016 | B17: 46072 | C17: 46072 | D17: CREDIT | E17: BOUAKE | F17: BKE-003 | G17: COP JAVA SCOOPS | H17: LBA-005-JAV | I17: 285LA01 | J17: 0429-0005 | K17: 72553 | L17: VAVOUA | M17: 8.2 | N17: 178 | O17: 47.52 | P17: 48.04 | Q17: ACCEPTED | S17: 44040 | U17: 43478 | V17: =IF(OR(U17="",AA17=""),"",U17-AA17) -> 43402 | W17: 562 | X17: 543 | Y17: 0 | Z17: 19 | AA17: 76 | AB17: 475 | AC17: =IF(OR(V17="",AB17=""),"",V17*AB17) -> 20615950 | AD17: 43478 | AE17: LOT-BKE-2026-0012 | AH17: W-8 Feb | AI17: YES | AJ17: DP-BKE-2026-010 | AK17: PLANNED | AL17: ON PLAN | AM17: NOT REQUIRED | AN17: PLANNED FROM START | AO17: STOCKED
A18: REC-BKE-2026-0017 | B18: 46072 | C18: 46072 | D18: CREDIT | E18: BOUAKE | F18: BKE-003 | G18: SCOOPS KPESSO | H18: LBA-012-KPE | I18: AA057ER03 | J18: 0426-0365 | K18: 72549 | L18: DIANRA | M18: 8.7 | N18: 178 | O18: 46.99 | P18: 47.34 | Q18: ACCEPTED | S18: 43860 | U18: 43350 | V18: =IF(OR(U18="",AA18=""),"",U18-AA18) -> 43302 | W18: 510 | X18: 498 | Y18: 0 | Z18: 12 | AA18: 48 | AB18: 470 | AC18: =IF(OR(V18="",AB18=""),"",V18*AB18) -> 20351940 | AD18: 43350 | AE18: LOT-BKE-2026-0013 | AH18: W-8 Feb | AI18: NO | AK18: UNPLANNED | AL18: UNPLANNED - known LBA, no pre-alert | AM18: APPROVED | AN18: NOT PLANNED | AO18: STOCKED
A19: REC-BKE-2026-0018 | B19: 46073 | C19: 46073 | D19: CREDIT | E19: BOUAKE | F19: BKE-002 | G19: SCOOP-CA/COBAN | H19: LBA-008-COB | I19: 2415CV03 | J19: 0420-0149 | K19: 72529 | L19: DIANRA | M19: 8.5 | N19: 167 | O19: 46.64 | P19: 46.72 | Q19: ACCEPTED | S19: 51300 | U19: 50693 | V19: =IF(OR(U19="",AA19=""),"",U19-AA19) -> 50441 | W19: 607 | X19: 544 | Z19: 63 | AA19: 252 | AB19: 480 | AC19: =IF(OR(V19="",AB19=""),"",V19*AB19) -> 24211680 | AD19: 50693 | AE19: LOT-BKE-2026-0014 | AH19: W-8 Feb | AI19: NO | AK19: UNPLANNED | AL19: UNPLANNED - approval required at arrival | AM19: APPROVED | AN19: TO BE LINKED / REGULARIZED | AO19: STOCKED
A20: REC-BKE-2026-0019 | B20: 46073 | D20: CREDIT | E20: BOUAKE | G20: SCOOP-CA/COBAN | H20: LBA-008-COB | I20: 9719FC01 | L20: DIANRA | M20: 9.3 | N20: 165 | O20: 45.23 | Q20: REJECTED | R20: REJECT | S20: 0 | V20: 0 | W20: 0 | AC20: 0 | AG20: REJECT | AI20: NO | AK20: UNPLANNED | AL20: UNPLANNED / QUALITY REJECTED | AM20: N/A - REJECTED | AN20: NOT PLANNED | AO20: REJECTED
A21: REC-BKE-2026-0020 | B21: 46074 | C21: 46074 | D21: CREDIT | E21: BOUAKE | F21: BKE-003 | G21: SCOOPS AH AL NOUR | H21: LBA-016-NOU | I21: 838LX01 | J21: 0425-0055 | K21: 72593 | L21: KATIOLA | M21: 9 | N21: 165 | O21: 48.92 | Q21: ACCEPTED | S21: 46380 | U21: 45843 | V21: =IF(OR(U21="",AA21=""),"",U21-AA21) -> 45759 | W21: 537 | X21: 516 | Y21: 0 | Z21: 21 | AA21: 84 | AB21: 475 | AC21: =IF(OR(V21="",AB21=""),"",V21*AB21) -> 21735525 | AD21: 45843 | AE21: LOT-BKE-2026-0015 | AH21: W-8 Feb | AI21: YES | AJ21: DP-BKE-2026-009 | AK21: PLANNED WITH EXCEPTION | AL21: WAREHOUSE CHANGE | AM21: APPROVED | AN21: PLANNED FROM START | AO21: STOCKED
A22: REC-BKE-2026-0021 | B22: 46074 | C22: 46074 | D22: CREDIT | E22: BOUAKE | F22: BKE-002 | G22: SCOOPS DPVICA | H22: LBA-017-DPV | I22: 32LA01 | J22: 0420-0251 | K22: 68145 | L22: DIANRA | M22: 9.3 | N22: 166 | O22: 46.11 | Q22: ACCEPTED | S22: 40740 | U22: 40220 | V22: =IF(OR(U22="",AA22=""),"",U22-AA22) -> 40112 | W22: 520 | X22: 493 | Y22: 0 | Z22: 27 | AA22: 108 | AB22: 475 | AC22: =IF(OR(V22="",AB22=""),"",V22*AB22) -> 19053200 | AD22: 40220 | AE22: LOT-BKE-2026-0016 | AH22: W-8 Feb | AI22: NO | AK22: UNPLANNED | AL22: UNPLANNED - known LBA, no pre-alert | AM22: APPROVED | AN22: NOT PLANNED | AO22: STOCKED
A23: REC-BKE-2026-0022 | B23: 46075 | D23: CREDIT | E23: BOUAKE | G23: SCOOPS HERE B | H23: LBA-003-HER | I23: 6103GZ03 | L23: DIKODOUGOU | M23: 9.6 | N23: 170 | O23: 45.4 | Q23: REJECTED | R23: REJECT | S23: 0 | V23: 0 | W23: 0 | AC23: 0 | AG23: REJECT | AI23: NO | AK23: UNPLANNED | AL23: UNPLANNED / QUALITY REJECTED | AM23: N/A - REJECTED | AN23: NOT PLANNED | AO23: REJECTED
A24: REC-BKE-2026-0023 | B24: 46076 | D24: CREDIT | E24: BOUAKE | G24: SCOOPS-OUMI/KONE SIDY | H24: LBA-015-OUM | I24: 28JZ01 | L24: MANKONO | M24: 8.2 | N24: 174 | O24: 45.05 | Q24: REJECTED | R24: REJECT | S24: 0 | V24: 0 | W24: 0 | AA24: 0 | AC24: 0 | AG24: REJECT | AI24: NO | AK24: UNPLANNED | AL24: UNPLANNED / QUALITY REJECTED | AM24: N/A - REJECTED | AN24: NOT PLANNED | AO24: REJECTED
A25: REC-BKE-2026-0024 | B25: 46077 | C25: 46077 | D25: CREDIT | E25: BOUAKE | F25: BKE-003 | G25: SCOOPS COOPRAKA | H25: LBA-018-COP | I25: 2766HC01 | J25: 0425-0001 | K25: 72620 | L25: KATIOLA | M25: 9.4 | N25: 174 | O25: 47.87 | Q25: ACCEPTED | S25: 39020 | U25: 38569 | V25: =IF(OR(U25="",AA25=""),"",U25-AA25) -> 38529 | W25: 451 | X25: 441 | Y25: 0 | Z25: 10 | AA25: 40 | AB25: 475 | AC25: =IF(OR(V25="",AB25=""),"",V25*AB25) -> 18301275 | AD25: 38569 | AE25: LOT-BKE-2026-0017 | AH25: W-9 Feb | AI25: YES | AJ25: DP-BKE-2026-003 | AK25: PLANNED | AL25: ON PLAN | AM25: NOT REQUIRED | AN25: PLANNED FROM START | AO25: STOCKED
A26: REC-BKE-2026-0025 | B26: 46077 | D26: CREDIT | E26: BOUAKE | G26: DAGNOGO KARIM | H26: LBA-013-DAG | I26: 9149EL04 | L26: NIAKARA | M26: 11.7 | N26: 161 | O26: 45.05 | Q26: REJECTED | R26: REJECT | S26: 0 | U26: 0 | V26: 0 | W26: 0 | AC26: 0 | AG26: REJECT | AI26: NO | AK26: UNPLANNED | AL26: UNPLANNED / QUALITY REJECTED | AM26: N/A - REJECTED | AN26: NOT PLANNED | AO26: REJECTED
A27: REC-BKE-2026-0026 | B27: 46077 | D27: CREDIT | E27: BOUAKE | G27: SCOOPS AH AL NOUR | H27: LBA-016-NOU | I27: AA518FY01 | L27: KATIOLA | M27: 10.9 | N27: 174 | O27: 44.88 | Q27: REJECTED | R27: REJECT | S27: 0 | U27: 0 | V27: 0 | W27: 0 | AC27: 0 | AG27: REJECT | AI27: NO | AK27: UNPLANNED | AL27: UNPLANNED / QUALITY REJECTED | AM27: N/A - REJECTED | AN27: NOT PLANNED | AO27: REJECTED
A28: REC-BKE-2026-0027 | B28: 46078 | C28: 46078 | D28: CREDIT | E28: BOUAKE | F28: BKE-003 | G28: CASP-S SCOOPS | H28: LBA-007-CAS | I28: 3619 EJ 03 | J28: 0429-0040 | K28: 68659 | L28: BOUNDIALI | M28: 8 | N28: 175 | O28: 46.11 | Q28: ACCEPTED | S28: 51380 | U28: 50744 | V28: =IF(OR(U28="",AA28=""),"",U28-AA28) -> 50624 | W28: 636 | X28: 606 | Y28: 0 | Z28: 30 | AA28: 120 | AB28: 490 | AC28: =IF(OR(V28="",AB28=""),"",V28*AB28) -> 24805760 | AD28: 50744 | AE28: LOT-BKE-2026-0018 | AH28: W-9 Feb | AI28: NO | AK28: UNPLANNED | AL28: UNPLANNED - known LBA, no pre-alert | AM28: APPROVED | AN28: NOT PLANNED | AO28: STOCKED
A29: REC-BKE-2026-0028 | B29: 46079 | D29: CREDIT | E29: BOUAKE | G29: SCOOP IMANE | H29: LBA-006-IMA | I29: 1148CV03 | L29: KANI | M29: 8.3 | N29: 180 | O29: 41 | Q29: REJECTED | R29: REJECT | S29: 0 | V29: 0 | AB29: 0 | AC29: 0 | AG29: REJECT | AI29: NO | AK29: UNPLANNED | AL29: UNPLANNED / QUALITY REJECTED | AM29: N/A - REJECTED | AN29: NOT PLANNED | AO29: REJECTED
A30: REC-BKE-2026-0029 | B30: 46081 | D30: CREDIT | E30: YAKRO FACTORY | G30: SCAAMT COOP CA | H30: LBA-002-SCA | I30: AV2744KK0R | L30: VAVOUA | M30: 7.9 | N30: 183 | O30: 45.23 | Q30: REJECTED | R30: REJECT | S30: 0 | V30: 0 | AC30: 0 | AG30: REJECT | AI30: YES | AJ30: DP-BKE-2026-001 | AK30: PLANNED | AL30: ON PLAN | AM30: N/A - REJECTED | AN30: PLANNED FROM START | AO30: REJECTED
A31: REC-BKE-2026-0030 | B31: 46085 | D31: CREDIT | E31: BOUAKE | G31: SCOOPS BAY SCOOPS | H31: LBA-014-BAY | I31: 2023 HF 01 | L31: BOTRO | M31: 10 | N31: 170 | O31: 44.26 | Q31: REJECTED | R31: REJECT | S31: 0 | V31: 0 | AC31: 0 | AG31: REJECT | AI31: NO | AK31: UNPLANNED | AL31: UNPLANNED / QUALITY REJECTED | AM31: N/A - REJECTED | AN31: NOT PLANNED | AO31: REJECTED
A32: REC-BKE-2026-0031 | B32: 46085 | D32: CREDIT | E32: BOUAKE | G32: CAPCD-SCOOPS | H32: LBA-010-CAP | I32: AA 465 KK 01 | L32: SEGUELA | M32: 7.9 | N32: 178 | O32: 42.06 | Q32: REJECTED | R32: REJECT | S32: 0 | V32: 0 | AC32: 0 | AG32: REJECT | AI32: NO | AK32: UNPLANNED | AL32: UNPLANNED / QUALITY REJECTED | AM32: N/A - REJECTED | AN32: NOT PLANNED | AO32: REJECTED
A33: REC-BKE-2026-0032 | B33: 46086 | C33: 46086 | D33: CREDIT | E33: BOUAKE | F33: BKE-003 | G33: DAGNOGO KARIM | H33: LBA-013-DAG | I33: 374LK01 | J33: 0425-0068 | K33: 77662 | L33: NIAKARA | M33: 9.7 | N33: 160 | O33: 46.02 | Q33: ACCEPTED | S33: 46760 | U33: 46256 | V33: =IF(OR(U33="",AA33=""),"",U33-AA33) -> 46216 | W33: 504 | X33: 494 | Y33: 0 | Z33: 10 | AA33: 40 | AB33: 485 | AC33: =IF(OR(V33="",AB33=""),"",V33*AB33) -> 22414760 | AD33: 46256 | AE33: LOT-BKE-2026-0019 | AH33: W-10 Mar | AI33: NO | AK33: UNPLANNED | AL33: UNPLANNED - known LBA, no pre-alert | AM33: APPROVED | AN33: NOT PLANNED | AO33: STOCKED
A34: REC-BKE-2026-0033 | B34: 46087 | D34: CREDIT | E34: BOUAKE | G34: SCOOPS COOPRAKA | H34: LBA-018-COP | I34: 2766 HC 01 | L34: KATIOLA | M34: 9.6 | N34: 168 | O34: 44.44 | Q34: REJECTED | R34: REJECT | S34: 0 | V34: 0 | AC34: 0 | AG34: REJECT | AI34: YES | AJ34: DP-BKE-2026-003 | AK34: PLANNED | AL34: ON PLAN | AM34: N/A - REJECTED | AN34: PLANNED FROM START | AO34: REJECTED
A35: REC-BKE-2026-0034 | B35: 46088 | C35: 46088 | D35: CREDIT | E35: BOUAKE | F35: BKE-001 | G35: SCOOPS HERE B | H35: LBA-003-HER | I35: 6085HR03 | J35: 0426-0187 | K35: 77633 | L35: NIAKARA | M35: 9.8 | N35: 168 | O35: 46.11 | Q35: ACCEPTED | S35: 46040 | U35: 45492 | V35: =IF(OR(U35="",AA35=""),"",U35-AA35) -> 45460 | W35: 548 | X35: 540 | Y35: 0 | Z35: 8 | AA35: 32 | AB35: 485 | AC35: =IF(OR(V35="",AB35=""),"",V35*AB35) -> 22048100 | AD35: 45492 | AE35: LOT-BKE-2026-0020 | AH35: W-10 Mar | AI35: YES | AJ35: DP-BKE-2026-007 | AK35: PLANNED WITH EXCEPTION | AL35: PLAN CANCELLED - ARRIVAL RECORDED | AM35: APPROVED | AN35: PLANNED FROM START | AO35: STOCKED
A36: REC-BKE-2026-0035 | B36: 46090 | D36: CREDIT | E36: BOUAKE | G36: SCOOPS KPESSO | H36: LBA-012-KPE | I36: AA653PE03 | L36: DIANRA | M36: 9.1 | N36: 170 | O36: 44.35 | Q36: REJECTED | R36: REJECT | S36: 0 | V36: 0 | AC36: 0 | AG36: REJECT | AI36: NO | AK36: UNPLANNED | AL36: UNPLANNED / QUALITY REJECTED | AM36: N/A - REJECTED | AN36: NOT PLANNED | AO36: REJECTED
A37: REC-BKE-2026-0036 | B37: 46092 | C37: 46092 | D37: CREDIT | E37: BOUAKE | F37: BKE-001 | G37: SCOPPAS SCOOPS | H37: LBA-009-SCO | I37: 6690GB01 | J37: 0426-0203 | K37: 75589 | L37: VAVOUA | M37: 9.9 | N37: 185 | O37: 45.23 | Q37: ACCEPTED | S37: 48580 | U37: 47967 | V37: =IF(OR(U37="",AA37=""),"",U37-AA37) -> 47935 | W37: 613 | X37: 605 | Y37: 0 | Z37: 8 | AA37: 32 | AB37: 485 | AC37: =IF(OR(V37="",AB37=""),"",V37*AB37) -> 23248475 | AD37: 47967 | AE37: LOT-BKE-2026-0021 | AH37: W-11 Mar | AI37: NO | AK37: UNPLANNED | AL37: UNPLANNED - known LBA, no pre-alert | AM37: APPROVED | AN37: NOT PLANNED | AO37: STOCKED
A38: REC-BKE-2026-0037 | B38: 46093 | C38: 46093 | D38: CREDIT | E38: BOUAKE | F38: BKE-001 | G38: SCOOP-CA/COBAN | H38: LBA-008-COB | I38: 8573GA01 | J38: 0420-0149 | K38: 72647 | L38: SEGUELA | M38: 7.5 | N38: 166 | O38: 45.4 | Q38: ACCEPTED | S38: 40300 | U38: 39784 | V38: =IF(OR(U38="",AA38=""),"",U38-AA38) -> 39744 | W38: 516 | X38: 506 | Y38: 0 | Z38: 10 | AA38: 40 | AB38: 485 | AC38: =IF(OR(V38="",AB38=""),"",V38*AB38) -> 19275840 | AD38: 39784 | AE38: LOT-BKE-2026-0022 | AH38: W-11 Mar | AI38: NO | AK38: UNPLANNED | AL38: UNPLANNED - known LBA, no pre-alert | AM38: APPROVED | AN38: NOT PLANNED | AO38: STOCKED
A39: REC-BKE-2026-0038 | B39: 46095 | C39: 46095 | D39: CREDIT | E39: BOUAKE | F39: BKE-002 | G39: SCOOPS WEBE | H39: LBA-004-WEB | I39: AA869FY01 | J39: 0425-0212 | K39: 82147 | L39: DABAKALA | M39: 8.6 | N39: 166 | O39: 47.26 | Q39: ACCEPTED | S39: 44880 | U39: 44340 | V39: =IF(OR(U39="",AA39=""),"",U39-AA39) -> 44308 | W39: 540 | X39: 532 | Y39: 0 | Z39: 8 | AA39: 32 | AB39: 495 | AC39: =IF(OR(V39="",AB39=""),"",V39*AB39) -> 21932460 | AD39: 44340 | AE39: LOT-BKE-2026-0023 | AH39: W-11 Mar | AI39: YES | AJ39: DP-BKE-2026-005 | AK39: PLANNED WITH EXCEPTION | AL39: WAREHOUSE CHANGE | AM39: APPROVED | AN39: PLANNED FROM START | AO39: STOCKED
A40: REC-BKE-2026-0039 | B40: 46096 | C40: 46097 | D40: CREDIT | E40: BOUAKE | F40: BKE-001 | G40: SCOOPS HERE B | H40: LBA-003-HER | I40: 8287GH03 | J40: 0426-0187 | K40: 82869 | L40: DABAKALA | M40: 12.2 | N40: 189 | O40: 45.15 | Q40: ACCEPTED | S40: 39880 | U40: 39405 | V40: =IF(OR(U40="",AA40=""),"",U40-AA40) -> 39325 | W40: 475 | X40: 455 | Y40: 0 | Z40: 20 | AA40: 80 | AB40: 485 | AC40: =IF(OR(V40="",AB40=""),"",V40*AB40) -> 19072625 | AD40: 39405 | AE40: LOT-BKE-2026-0024 | AF40: BKE-001-BIN-015 | AH40: W-12 Mar | AI40: NO | AK40: UNPLANNED | AL40: UNPLANNED - known LBA, no pre-alert | AM40: APPROVED | AN40: NOT PLANNED | AO40: STOCKED
...

Sheet Warehouse Receiving
A1: Row ID | B1: No | C1: Warehouse | D1: Unloading Bin | E1: After Drying Bin | F1: Lot No | G1: Scale Location | H1: Warehouse Receipt No | I1: Fiche CCA No | J1: Truck No | K1: Arrival Date | L1: Arrival Date (as written) | M1: Discharge Date | N1: Discharge Date (as written) | O1: Origin | P1: Supplier Name | Q1: Supplier Code | R1: Good Bags | S1: Humid Bags | T1: Torn Bags | U1: Recondition Bags | V1: Total Bags in Lot | W1: Export Bags | X1: Bio Bags | Y1: Brousse Bags | Z1: Total Bags Received | AA1: Gross Weight Received (kg) | AB1: Total Refraction (kg) | AC1: GRN Quantity (kg) | AD1: Paid Weight (kg) | AE1: Net Weight (kg) | AF1: GRN Fresh Quantity (kg) | AG1: GRN Dried Quantity (kg) | AH1: Sample – Rejection (g) | AI1: Sample – Void (g) | AJ1: Sample – Oil (g) | AK1: Sample – Total Defect (g) | AL1: Sample – Good Kernel (g) | AM1: Sample – Immature (g) | AN1: Sample – Spotted (g) | AO1: Sample – Total Kernels (g) | AP1: Sample – KOR | AQ1: Sample – Shot | AR1: Sample – FOT | AS1: Sample – Useful Kernels Yield (%) | AT1: Sample – Total Yield (%) | AU1: Sample – Moisture (%) | AV1: Sample – Nut Count | AW1: Sample – Shell (g) | AX1: Final – Rejection (g) | AY1: Final – Void (g) | AZ1: Final – Oil (g) | BA1: Final – Total Defect (g) | BB1: Final – Good Kernel (g) | BC1: Final – Immature (g) | BD1: Final – Spotted (g) | BE1: Final – Total Kernels (g) | BF1: Final – KOR | BG1: Final – Shot | BH1: Final – FOT | BI1: Final – Useful Kernels Yield (%) | BJ1: Final – Total Yield (%) | BK1: Final – Moisture (%) | BL1: Final – Nut Count | BM1: Final – Shell (g)
A2: RCV-BKE-2026-0001 | B2: 1 | C2: BKE-002 | F2: LOT-BKE-2026-0001 | G2: INSIDE | H2: 801 | I2: 72515 | J2: 827KT01 | K2: 46069 | L2: 16-Feb | M2: 46069 | N2: 16-Feb | O2: DIANRA | P2: SCOOP IMANE | Q2: LBA-006-IMA | R2: 463 | S2: 0 | T2: 15 | V2: 478 | Z2: =SUM(R2:U2) -> 478 | AA2: 41300 | AB2: 60 | AC2: 40822 | AD2: =IF(OR(AE2="",AB2=""),"",AE2-AB2) -> 40762 | AE2: 40822 | AF2: 40822 | AK2: =IF(COUNTA(AH2:AJ2)=0,"",SUM(AH2:AJ2)) | AO2: =IF(COUNTA(AL2:AN2)=0,"",SUM(AL2:AN2)) | AP2: =IF(COUNTA(AL2:AN2)<3,"",(AL2+0.5*(AM2+AN2))*0.17637) | AQ2: =IF(AO2="","",AO2*0.17637) | AR2: =IF(COUNTA(AJ2,AH2,AL2:AN2)=0,"",(AJ2+AH2+AL2+AM2+AN2)*0.17637) | AS2: =IF(AO2="","",AO2/1000) | AT2: =IF(COUNTA(AH2,AJ2,AL2:AN2)=0,"",SUM(AH2,AJ2,AL2:AN2)/1000) | AU2: 10.2 | AV2: 172 | BA2: =IF(COUNTA(AX2:AZ2)=0,"",SUM(AX2:AZ2)) | BE2: =IF(COUNTA(BB2:BD2)=0,"",SUM(BB2:BD2)) | BF2: =IF(COUNTA(BB2:BD2)<3,"",(BB2+0.5*(BC2+BD2))*0.17637) | BG2: =IF(BE2="","",BE2*0.17637) | BH2: =IF(COUNTA(AZ2,AX2,BB2:BD2)=0,"",(AZ2+AX2+BB2+BC2+BD2)*0.17637) | BI2: =IF(BE2="","",BE2/1000) | BJ2: =IF(COUNTA(AX2,AZ2,BB2:BD2)=0,"",SUM(AX2,AZ2,BB2:BD2)/1000) | BK2: 10.2 | BL2: 172
A3: RCV-BKE-2026-0002 | B3: 2 | C3: BKE-002 | F3: LOT-BKE-2026-0002 | G3: INSIDE | H3: 802 | I3: 72533 | J3: 793LT03 | K3: 46069 | L3: 16-Feb | M3: 46069 | N3: 16-Feb | O3: MANKONO | P3: CASP-S SCOOPS | Q3: LBA-007-CAS | R3: 559 | S3: 0 | T3: 69 | V3: 628 | Z3: =SUM(R3:U3) -> 628 | AA3: 50880 | AB3: 276 | AC3: 50252 | AD3: =IF(OR(AE3="",AB3=""),"",AE3-AB3) -> 49976 | AE3: 50252 | AF3: 50252 | AK3: =IF(COUNTA(AH3:AJ3)=0,"",SUM(AH3:AJ3)) | AO3: =IF(COUNTA(AL3:AN3)=0,"",SUM(AL3:AN3)) | AP3: =IF(COUNTA(AL3:AN3)<3,"",(AL3+0.5*(AM3+AN3))*0.17637) | AQ3: =IF(AO3="","",AO3*0.17637) | AR3: =IF(COUNTA(AJ3,AH3,AL3:AN3)=0,"",(AJ3+AH3+AL3+AM3+AN3)*0.17637) | AS3: =IF(AO3="","",AO3/1000) | AT3: =IF(COUNTA(AH3,AJ3,AL3:AN3)=0,"",SUM(AH3,AJ3,AL3:AN3)/1000) | AU3: 9 | AV3: 165 | BA3: =IF(COUNTA(AX3:AZ3)=0,"",SUM(AX3:AZ3)) | BE3: =IF(COUNTA(BB3:BD3)=0,"",SUM(BB3:BD3)) | BF3: =IF(COUNTA(BB3:BD3)<3,"",(BB3+0.5*(BC3+BD3))*0.17637) | BG3: =IF(BE3="","",BE3*0.17637) | BH3: =IF(COUNTA(AZ3,AX3,BB3:BD3)=0,"",(AZ3+AX3+BB3+BC3+BD3)*0.17637) | BI3: =IF(BE3="","",BE3/1000) | BJ3: =IF(COUNTA(AX3,AZ3,BB3:BD3)=0,"",SUM(AX3,AZ3,BB3:BD3)/1000) | BK3: 9 | BL3: 165
A4: RCV-BKE-2026-0003 | B4: 3 | C4: BKE-002 | D4: BKE-002-BIN-004 / BKE-002-BIN-006 | F4: LOT-BKE-2026-0003 | G4: INSIDE | H4: 809 | I4: 72615 | J4: 8287GH03 | K4: 46070 | L4: 17-Feb | M4: 46070 | N4: 17-Feb | O4: NIAKARA | P4: SCOOPS HERE B | Q4: LBA-003-HER | R4: 504 | S4: 0 | T4: 8 | V4: 512 | Z4: =SUM(R4:U4) -> 512 | AA4: 45420 | AB4: 32 | AC4: 44908 | AD4: =IF(OR(AE4="",AB4=""),"",AE4-AB4) -> 44876 | AE4: 44908 | AF4: 44908 | AK4: =IF(COUNTA(AH4:AJ4)=0,"",SUM(AH4:AJ4)) | AO4: =IF(COUNTA(AL4:AN4)=0,"",SUM(AL4:AN4)) | AP4: =IF(COUNTA(AL4:AN4)<3,"",(AL4+0.5*(AM4+AN4))*0.17637) | AQ4: =IF(AO4="","",AO4*0.17637) | AR4: =IF(COUNTA(AJ4,AH4,AL4:AN4)=0,"",(AJ4+AH4+AL4+AM4+AN4)*0.17637) | AS4: =IF(AO4="","",AO4/1000) | AT4: =IF(COUNTA(AH4,AJ4,AL4:AN4)=0,"",SUM(AH4,AJ4,AL4:AN4)/1000) | AU4: 11.4 | AV4: 162 | BA4: =IF(COUNTA(AX4:AZ4)=0,"",SUM(AX4:AZ4)) | BE4: =IF(COUNTA(BB4:BD4)=0,"",SUM(BB4:BD4)) | BF4: =IF(COUNTA(BB4:BD4)<3,"",(BB4+0.5*(BC4+BD4))*0.17637) | BG4: =IF(BE4="","",BE4*0.17637) | BH4: =IF(COUNTA(AZ4,AX4,BB4:BD4)=0,"",(AZ4+AX4+BB4+BC4+BD4)*0.17637) | BI4: =IF(BE4="","",BE4/1000) | BJ4: =IF(COUNTA(AX4,AZ4,BB4:BD4)=0,"",SUM(AX4,AZ4,BB4:BD4)/1000) | BK4: 11.4 | BL4: 162
A5: RCV-BKE-2026-0004 | B5: 4 | C5: BKE-003 | F5: LOT-BKE-2026-0004 | G5: INSIDE | H5: 811 | I5: 72540 | J5: 338KX01 | K5: 46070 | L5: 17-Feb | M5: 46070 | N5: 17-Feb | O5: BOUAKE | P5: SCOPPAS SCOOPS | Q5: LBA-009-SCO | R5: 400 | S5: 0 | T5: 25 | V5: 425 | Z5: =SUM(R5:U5) -> 425 | AA5: 35320 | AB5: 100 | AC5: 34895 | AD5: =IF(OR(AE5="",AB5=""),"",AE5-AB5) -> 34795 | AE5: 34895 | AF5: 34895 | AK5: =IF(COUNTA(AH5:AJ5)=0,"",SUM(AH5:AJ5)) | AO5: =IF(COUNTA(AL5:AN5)=0,"",SUM(AL5:AN5)) | AP5: =IF(COUNTA(AL5:AN5)<3,"",(AL5+0.5*(AM5+AN5))*0.17637) | AQ5: =IF(AO5="","",AO5*0.17637) | AR5: =IF(COUNTA(AJ5,AH5,AL5:AN5)=0,"",(AJ5+AH5+AL5+AM5+AN5)*0.17637) | AS5: =IF(AO5="","",AO5/1000) | AT5: =IF(COUNTA(AH5,AJ5,AL5:AN5)=0,"",SUM(AH5,AJ5,AL5:AN5)/1000) | AU5: 9.5 | AV5: 166 | BA5: =IF(COUNTA(AX5:AZ5)=0,"",SUM(AX5:AZ5)) | BE5: =IF(COUNTA(BB5:BD5)=0,"",SUM(BB5:BD5)) | BF5: =IF(COUNTA(BB5:BD5)<3,"",(BB5+0.5*(BC5+BD5))*0.17637) | BG5: =IF(BE5="","",BE5*0.17637) | BH5: =IF(COUNTA(AZ5,AX5,BB5:BD5)=0,"",(AZ5+AX5+BB5+BC5+BD5)*0.17637) | BI5: =IF(BE5="","",BE5/1000) | BJ5: =IF(COUNTA(AX5,AZ5,BB5:BD5)=0,"",SUM(AX5,AZ5,BB5:BD5)/1000) | BK5: 9.5 | BL5: 166
A6: RCV-BKE-2026-0005 | B6: 5 | C6: BKE-002 | D6: BKE-002-BIN-003 | F6: LOT-BKE-2026-0005 | G6: INSIDE | H6: 805 | I6: 72569 | J6: 3633LZ04 | K6: 46070 | L6: 17-Feb | M6: 46070 | N6: 17-Feb | O6: NIAKARA | P6: DAGNOGO KARIM | Q6: LBA-013-DAG | R6: 556 | S6: 12 | T6: 18 | V6: 586 | Z6: =SUM(R6:U6) -> 586 | AA6: 50760 | AB6: 552 | AC6: 50174 | AD6: =IF(OR(AE6="",AB6=""),"",AE6-AB6) -> 49622 | AE6: 50174 | AF6: 50174 | AK6: =IF(COUNTA(AH6:AJ6)=0,"",SUM(AH6:AJ6)) | AO6: =IF(COUNTA(AL6:AN6)=0,"",SUM(AL6:AN6)) | AP6: =IF(COUNTA(AL6:AN6)<3,"",(AL6+0.5*(AM6+AN6))*0.17637) | AQ6: =IF(AO6="","",AO6*0.17637) | AR6: =IF(COUNTA(AJ6,AH6,AL6:AN6)=0,"",(AJ6+AH6+AL6+AM6+AN6)*0.17637) | AS6: =IF(AO6="","",AO6/1000) | AT6: =IF(COUNTA(AH6,AJ6,AL6:AN6)=0,"",SUM(AH6,AJ6,AL6:AN6)/1000) | AU6: 11.5 | AV6: 161 | BA6: =IF(COUNTA(AX6:AZ6)=0,"",SUM(AX6:AZ6)) | BE6: =IF(COUNTA(BB6:BD6)=0,"",SUM(BB6:BD6)) | BF6: =IF(COUNTA(BB6:BD6)<3,"",(BB6+0.5*(BC6+BD6))*0.17637) | BG6: =IF(BE6="","",BE6*0.17637) | BH6: =IF(COUNTA(AZ6,AX6,BB6:BD6)=0,"",(AZ6+AX6+BB6+BC6+BD6)*0.17637) | BI6: =IF(BE6="","",BE6/1000) | BJ6: =IF(COUNTA(AX6,AZ6,BB6:BD6)=0,"",SUM(AX6,AZ6,BB6:BD6)/1000) | BK6: 11.5 | BL6: 161
A7: RCV-BKE-2026-0006 | B7: 6 | C7: BKE-002 | F7: LOT-BKE-2026-0006 | G7: INSIDE | H7: 804 | I7: 72607 | J7: 3509KJ01 | K7: 46070 | L7: 17-Feb | M7: 46070 | N7: 17-Feb | O7: MANKONO | P7: SCOOPS BAY SCOOPS | Q7: LBA-014-BAY | R7: 437 | S7: 0 | T7: 5 | V7: 442 | Z7: =SUM(R7:U7) -> 442 | AA7: 39460 | AB7: 20 | AC7: 39018 | AD7: =IF(OR(AE7="",AB7=""),"",AE7-AB7) -> 38998 | AE7: 39018 | AF7: 39018 | AK7: =IF(COUNTA(AH7:AJ7)=0,"",SUM(AH7:AJ7)) | AO7: =IF(COUNTA(AL7:AN7)=0,"",SUM(AL7:AN7)) | AP7: =IF(COUNTA(AL7:AN7)<3,"",(AL7+0.5*(AM7+AN7))*0.17637) | AQ7: =IF(AO7="","",AO7*0.17637) | AR7: =IF(COUNTA(AJ7,AH7,AL7:AN7)=0,"",(AJ7+AH7+AL7+AM7+AN7)*0.17637) | AS7: =IF(AO7="","",AO7/1000) | AT7: =IF(COUNTA(AH7,AJ7,AL7:AN7)=0,"",SUM(AH7,AJ7,AL7:AN7)/1000) | AU7: 9.1 | AV7: 163 | BA7: =IF(COUNTA(AX7:AZ7)=0,"",SUM(AX7:AZ7)) | BE7: =IF(COUNTA(BB7:BD7)=0,"",SUM(BB7:BD7)) | BF7: =IF(COUNTA(BB7:BD7)<3,"",(BB7+0.5*(BC7+BD7))*0.17637) | BG7: =IF(BE7="","",BE7*0.17637) | BH7: =IF(COUNTA(AZ7,AX7,BB7:BD7)=0,"",(AZ7+AX7+BB7+BC7+BD7)*0.17637) | BI7: =IF(BE7="","",BE7/1000) | BJ7: =IF(COUNTA(AX7,AZ7,BB7:BD7)=0,"",SUM(AX7,AZ7,BB7:BD7)/1000) | BK7: 9.1 | BL7: 163
A8: RCV-BKE-2026-0007 | B8: 7 | C8: BKE-002 | F8: LOT-BKE-2026-0007 | G8: INSIDE | H8: 808 | I8: 72564 | J8: 28JZ01 | K8: 46070 | L8: 17-Feb | M8: 46070 | N8: 17-Feb | O8: BOUAKE | P8: SCOOPS-OUMI/KONE SIDY | Q8: LBA-015-OUM | R8: 555 | S8: 0 | T8: 15 | V8: 570 | Z8: =SUM(R8:U8) -> 570 | AA8: 49020 | AB8: 60 | AC8: 48450 | AD8: =IF(OR(AE8="",AB8=""),"",AE8-AB8) -> 48390 | AE8: 48450 | AF8: 48450 | AK8: =IF(COUNTA(AH8:AJ8)=0,"",SUM(AH8:AJ8)) | AO8: =IF(COUNTA(AL8:AN8)=0,"",SUM(AL8:AN8)) | AP8: =IF(COUNTA(AL8:AN8)<3,"",(AL8+0.5*(AM8+AN8))*0.17637) | AQ8: =IF(AO8="","",AO8*0.17637) | AR8: =IF(COUNTA(AJ8,AH8,AL8:AN8)=0,"",(AJ8+AH8+AL8+AM8+AN8)*0.17637) | AS8: =IF(AO8="","",AO8/1000) | AT8: =IF(COUNTA(AH8,AJ8,AL8:AN8)=0,"",SUM(AH8,AJ8,AL8:AN8)/1000) | AU8: 9.2 | AV8: 172 | BA8: =IF(COUNTA(AX8:AZ8)=0,"",SUM(AX8:AZ8)) | BE8: =IF(COUNTA(BB8:BD8)=0,"",SUM(BB8:BD8)) | BF8: =IF(COUNTA(BB8:BD8)<3,"",(BB8+0.5*(BC8+BD8))*0.17637) | BG8: =IF(BE8="","",BE8*0.17637) | BH8: =IF(COUNTA(AZ8,AX8,BB8:BD8)=0,"",(AZ8+AX8+BB8+BC8+BD8)*0.17637) | BI8: =IF(BE8="","",BE8/1000) | BJ8: =IF(COUNTA(AX8,AZ8,BB8:BD8)=0,"",SUM(AX8,AZ8,BB8:BD8)/1000) | BK8: 9.2 | BL8: 172
A9: RCV-BKE-2026-0008 | B9: 8 | C9: BKE-003 | F9: LOT-BKE-2026-0008 | G9: INSIDE | H9: 815 | I9: 72517 | J9: AA864JL01 | K9: 46071 | L9: 18-Feb | M9: 46071 | N9: 18-Feb | O9: VAVOUA | P9: SCAAMT COOP CA | Q9: LBA-002-SCA | R9: 578 | S9: 0 | T9: 36 | V9: 614 | Z9: =SUM(R9:U9) -> 614 | AA9: 52060 | AB9: 144 | AC9: 51446 | AD9: =IF(OR(AE9="",AB9=""),"",AE9-AB9) -> 51302 | AE9: 51446 | AF9: 51446 | AK9: =IF(COUNTA(AH9:AJ9)=0,"",SUM(AH9:AJ9)) | AO9: =IF(COUNTA(AL9:AN9)=0,"",SUM(AL9:AN9)) | AP9: =IF(COUNTA(AL9:AN9)<3,"",(AL9+0.5*(AM9+AN9))*0.17637) | AQ9: =IF(AO9="","",AO9*0.17637) | AR9: =IF(COUNTA(AJ9,AH9,AL9:AN9)=0,"",(AJ9+AH9+AL9+AM9+AN9)*0.17637) | AS9: =IF(AO9="","",AO9/1000) | AT9: =IF(COUNTA(AH9,AJ9,AL9:AN9)=0,"",SUM(AH9,AJ9,AL9:AN9)/1000) | AU9: 9.5 | AV9: 178 | BA9: =IF(COUNTA(AX9:AZ9)=0,"",SUM(AX9:AZ9)) | BE9: =IF(COUNTA(BB9:BD9)=0,"",SUM(BB9:BD9)) | BF9: =IF(COUNTA(BB9:BD9)<3,"",(BB9+0.5*(BC9+BD9))*0.17637) | BG9: =IF(BE9="","",BE9*0.17637) | BH9: =IF(COUNTA(AZ9,AX9,BB9:BD9)=0,"",(AZ9+AX9+BB9+BC9+BD9)*0.17637) | BI9: =IF(BE9="","",BE9/1000) | BJ9: =IF(COUNTA(AX9,AZ9,BB9:BD9)=0,"",SUM(AX9,AZ9,BB9:BD9)/1000) | BK9: 9.5 | BL9: 178
A10: RCV-BKE-2026-0009 | B10: 9 | C10: BKE-003 | F10: LOT-BKE-2026-0009 | G10: INSIDE | H10: 817 | I10: 72568 | J10: 5176LG04 | K10: 46071 | L10: 18-Feb | M10: 46071 | N10: 18-Feb | O10: DABAKALA | P10: SCOOPS WEBE | Q10: LBA-004-WEB | R10: 410 | S10: 0 | T10: 43 | V10: 453 | Z10: =SUM(R10:U10) -> 453 | AA10: 41540 | AB10: 172 | AC10: 41087 | AD10: =IF(OR(AE10="",AB10=""),"",AE10-AB10) -> 40915 | AE10: 41087 | AF10: 41087 | AK10: =IF(COUNTA(AH10:AJ10)=0,"",SUM(AH10:AJ10)) | AO10: =IF(COUNTA(AL10:AN10)=0,"",SUM(AL10:AN10)) | AP10: =IF(COUNTA(AL10:AN10)<3,"",(AL10+0.5*(AM10+AN10))*0.17637) | AQ10: =IF(AO10="","",AO10*0.17637) | AR10: =IF(COUNTA(AJ10,AH10,AL10:AN10)=0,"",(AJ10+AH10+AL10+AM10+AN10)*0.17637) | AS10: =IF(AO10="","",AO10/1000) | AT10: =IF(COUNTA(AH10,AJ10,AL10:AN10)=0,"",SUM(AH10,AJ10,AL10:AN10)/1000) | AU10: 9.6 | AV10: 182 | BA10: =IF(COUNTA(AX10:AZ10)=0,"",SUM(AX10:AZ10)) | BE10: =IF(COUNTA(BB10:BD10)=0,"",SUM(BB10:BD10)) | BF10: =IF(COUNTA(BB10:BD10)<3,"",(BB10+0.5*(BC10+BD10))*0.17637) | BG10: =IF(BE10="","",BE10*0.17637) | BH10: =IF(COUNTA(AZ10,AX10,BB10:BD10)=0,"",(AZ10+AX10+BB10+BC10+BD10)*0.17637) | BI10: =IF(BE10="","",BE10/1000) | BJ10: =IF(COUNTA(AX10,AZ10,BB10:BD10)=0,"",SUM(AX10,AZ10,BB10:BD10)/1000) | BK10: 9.6 | BL10: 182
A11: RCV-BKE-2026-0010 | B11: 10 | C11: BKE-002 | F11: LOT-BKE-2026-0010 | G11: INSIDE | H11: 812 | I11: 72523 | J11: AA562YL04 | K11: 46071 | L11: 18-Feb | M11: 46071 | N11: 18-Feb | O11: DIANRA | P11: CAPCD-SCOOPS | Q11: LBA-010-CAP | R11: 453 | S11: 0 | T11: 10 | V11: 463 | Z11: =SUM(R11:U11) -> 463 | AA11: 40560 | AB11: 40 | AC11: 40097 | AD11: =IF(OR(AE11="",AB11=""),"",AE11-AB11) -> 40057 | AE11: 40097 | AF11: 40097 | AK11: =IF(COUNTA(AH11:AJ11)=0,"",SUM(AH11:AJ11)) | AO11: =IF(COUNTA(AL11:AN11)=0,"",SUM(AL11:AN11)) | AP11: =IF(COUNTA(AL11:AN11)<3,"",(AL11+0.5*(AM11+AN11))*0.17637) | AQ11: =IF(AO11="","",AO11*0.17637) | AR11: =IF(COUNTA(AJ11,AH11,AL11:AN11)=0,"",(AJ11+AH11+AL11+AM11+AN11)*0.17637) | AS11: =IF(AO11="","",AO11/1000) | AT11: =IF(COUNTA(AH11,AJ11,AL11:AN11)=0,"",SUM(AH11,AJ11,AL11:AN11)/1000) | AU11: 11.2 | AV11: 168 | BA11: =IF(COUNTA(AX11:AZ11)=0,"",SUM(AX11:AZ11)) | BE11: =IF(COUNTA(BB11:BD11)=0,"",SUM(BB11:BD11)) | BF11: =IF(COUNTA(BB11:BD11)<3,"",(BB11+0.5*(BC11+BD11))*0.17637) | BG11: =IF(BE11="","",BE11*0.17637) | BH11: =IF(COUNTA(AZ11,AX11,BB11:BD11)=0,"",(AZ11+AX11+BB11+BC11+BD11)*0.17637) | BI11: =IF(BE11="","",BE11/1000) | BJ11: =IF(COUNTA(AX11,AZ11,BB11:BD11)=0,"",SUM(AX11,AZ11,BB11:BD11)/1000) | BK11: 11.2 | BL11: 168
A12: RCV-BKE-2026-0011 | B12: 11 | C12: BKE-003 | F12: LOT-BKE-2026-0011 | G12: INSIDE | H12: 814 | I12: 72501 | J12: 2138HC01 | K12: 46071 | L12: 18-Feb | M12: 46071 | N12: 18-Feb | O12: MANKONO | P12: SCOOP ASER | Q12: LBA-011-ASR | R12: 524 | S12: 0 | T12: 38 | V12: 562 | Z12: =SUM(R12:U12) -> 562 | AA12: 46680 | AB12: 152 | AC12: 46118 | AD12: =IF(OR(AE12="",AB12=""),"",AE12-AB12) -> 45966 | AE12: 46118 | AF12: 46118 | AK12: =IF(COUNTA(AH12:AJ12)=0,"",SUM(AH12:AJ12)) | AO12: =IF(COUNTA(AL12:AN12)=0,"",SUM(AL12:AN12)) | AP12: =IF(COUNTA(AL12:AN12)<3,"",(AL12+0.5*(AM12+AN12))*0.17637) | AQ12: =IF(AO12="","",AO12*0.17637) | AR12: =IF(COUNTA(AJ12,AH12,AL12:AN12)=0,"",(AJ12+AH12+AL12+AM12+AN12)*0.17637) | AS12: =IF(AO12="","",AO12/1000) | AT12: =IF(COUNTA(AH12,AJ12,AL12:AN12)=0,"",SUM(AH12,AJ12,AL12:AN12)/1000) | AU12: 8.6 | AV12: 171 | BA12: =IF(COUNTA(AX12:AZ12)=0,"",SUM(AX12:AZ12)) | BE12: =IF(COUNTA(BB12:BD12)=0,"",SUM(BB12:BD12)) | BF12: =IF(COUNTA(BB12:BD12)<3,"",(BB12+0.5*(BC12+BD12))*0.17637) | BG12: =IF(BE12="","",BE12*0.17637) | BH12: =IF(COUNTA(AZ12,AX12,BB12:BD12)=0,"",(AZ12+AX12+BB12+BC12+BD12)*0.17637) | BI12: =IF(BE12="","",BE12/1000) | BJ12: =IF(COUNTA(AX12,AZ12,BB12:BD12)=0,"",SUM(AX12,AZ12,BB12:BD12)/1000) | BK12: 8.6 | BL12: 171
A13: RCV-BKE-2026-0012 | B13: 12 | C13: BKE-003 | F13: LOT-BKE-2026-0012 | G13: INSIDE | H13: 823 | I13: 72553 | J13: 285LA01 | K13: 46072 | L13: 19-Feb | M13: 46072 | N13: 19-Feb | O13: VAVOUA | P13: COP JAVA SCOOPS | Q13: LBA-005-JAV | R13: 543 | S13: 0 | T13: 19 | V13: 562 | Z13: =SUM(R13:U13) -> 562 | AA13: 44040 | AB13: 76 | AC13: 43478 | AD13: =IF(OR(AE13="",AB13=""),"",AE13-AB13) -> 43402 | AE13: 43478 | AF13: 43478 | AK13: =IF(COUNTA(AH13:AJ13)=0,"",SUM(AH13:AJ13)) | AO13: =IF(COUNTA(AL13:AN13)=0,"",SUM(AL13:AN13)) | AP13: =IF(COUNTA(AL13:AN13)<3,"",(AL13+0.5*(AM13+AN13))*0.17637) | AQ13: =IF(AO13="","",AO13*0.17637) | AR13: =IF(COUNTA(AJ13,AH13,AL13:AN13)=0,"",(AJ13+AH13+AL13+AM13+AN13)*0.17637) | AS13: =IF(AO13="","",AO13/1000) | AT13: =IF(COUNTA(AH13,AJ13,AL13:AN13)=0,"",SUM(AH13,AJ13,AL13:AN13)/1000) | AU13: 8.2 | AV13: 178 | BA13: =IF(COUNTA(AX13:AZ13)=0,"",SUM(AX13:AZ13)) | BE13: =IF(COUNTA(BB13:BD13)=0,"",SUM(BB13:BD13)) | BF13: =IF(COUNTA(BB13:BD13)<3,"",(BB13+0.5*(BC13+BD13))*0.17637) | BG13: =IF(BE13="","",BE13*0.17637) | BH13: =IF(COUNTA(AZ13,AX13,BB13:BD13)=0,"",(AZ13+AX13+BB13+BC13+BD13)*0.17637) | BI13: =IF(BE13="","",BE13/1000) | BJ13: =IF(COUNTA(AX13,AZ13,BB13:BD13)=0,"",SUM(AX13,AZ13,BB13:BD13)/1000) | BK13: 8.2 | BL13: 178
A14: RCV-BKE-2026-0013 | B14: 13 | C14: BKE-003 | F14: LOT-BKE-2026-0013 | G14: INSIDE | H14: 825 | I14: 72549 | J14: AA057ER03 | K14: 46072 | L14: 19-Feb | M14: 46072 | N14: 19-Feb | O14: DIANRA | P14: SCOOPS KPESSO | Q14: LBA-012-KPE | R14: 498 | S14: 0 | T14: 12 | V14: 510 | Z14: =SUM(R14:U14) -> 510 | AA14: 43860 | AB14: 48 | AC14: 43350 | AD14: =IF(OR(AE14="",AB14=""),"",AE14-AB14) -> 43302 | AE14: 43350 | AF14: 43350 | AK14: =IF(COUNTA(AH14:AJ14)=0,"",SUM(AH14:AJ14)) | AO14: =IF(COUNTA(AL14:AN14)=0,"",SUM(AL14:AN14)) | AP14: =IF(COUNTA(AL14:AN14)<3,"",(AL14+0.5*(AM14+AN14))*0.17637) | AQ14: =IF(AO14="","",AO14*0.17637) | AR14: =IF(COUNTA(AJ14,AH14,AL14:AN14)=0,"",(AJ14+AH14+AL14+AM14+AN14)*0.17637) | AS14: =IF(AO14="","",AO14/1000) | AT14: =IF(COUNTA(AH14,AJ14,AL14:AN14)=0,"",SUM(AH14,AJ14,AL14:AN14)/1000) | AU14: 8.7 | AV14: 178 | BA14: =IF(COUNTA(AX14:AZ14)=0,"",SUM(AX14:AZ14)) | BE14: =IF(COUNTA(BB14:BD14)=0,"",SUM(BB14:BD14)) | BF14: =IF(COUNTA(BB14:BD14)<3,"",(BB14+0.5*(BC14+BD14))*0.17637) | BG14: =IF(BE14="","",BE14*0.17637) | BH14: =IF(COUNTA(AZ14,AX14,BB14:BD14)=0,"",(AZ14+AX14+BB14+BC14+BD14)*0.17637) | BI14: =IF(BE14="","",BE14/1000) | BJ14: =IF(COUNTA(AX14,AZ14,BB14:BD14)=0,"",SUM(AX14,AZ14,BB14:BD14)/1000) | BK14: 8.7 | BL14: 178
A15: RCV-BKE-2026-0014 | B15: 14 | C15: BKE-002 | F15: LOT-BKE-2026-0014 | G15: INSIDE | H15: 836 | I15: 72529 | J15: 2415CV03 | K15: 46073 | L15: 20-Feb | M15: 46073 | N15: 20-Feb | O15: DIANRA | P15: SCOOP-CA/COBAN | Q15: LBA-008-COB | R15: 544 | T15: 63 | V15: 607 | Z15: =SUM(R15:U15) -> 607 | AA15: 51300 | AB15: 252 | AC15: 50693 | AD15: =IF(OR(AE15="",AB15=""),"",AE15-AB15) -> 50441 | AE15: 50693 | AF15: 50693 | AK15: =IF(COUNTA(AH15:AJ15)=0,"",SUM(AH15:AJ15)) | AO15: =IF(COUNTA(AL15:AN15)=0,"",SUM(AL15:AN15)) | AP15: =IF(COUNTA(AL15:AN15)<3,"",(AL15+0.5*(AM15+AN15))*0.17637) | AQ15: =IF(AO15="","",AO15*0.17637) | AR15: =IF(COUNTA(AJ15,AH15,AL15:AN15)=0,"",(AJ15+AH15+AL15+AM15+AN15)*0.17637) | AS15: =IF(AO15="","",AO15/1000) | AT15: =IF(COUNTA(AH15,AJ15,AL15:AN15)=0,"",SUM(AH15,AJ15,AL15:AN15)/1000) | AU15: 8.5 | AV15: 167 | BA15: =IF(COUNTA(AX15:AZ15)=0,"",SUM(AX15:AZ15)) | BE15: =IF(COUNTA(BB15:BD15)=0,"",SUM(BB15:BD15)) | BF15: =IF(COUNTA(BB15:BD15)<3,"",(BB15+0.5*(BC15+BD15))*0.17637) | BG15: =IF(BE15="","",BE15*0.17637) | BH15: =IF(COUNTA(AZ15,AX15,BB15:BD15)=0,"",(AZ15+AX15+BB15+BC15+BD15)*0.17637) | BI15: =IF(BE15="","",BE15/1000) | BJ15: =IF(COUNTA(AX15,AZ15,BB15:BD15)=0,"",SUM(AX15,AZ15,BB15:BD15)/1000) | BK15: 8.5 | BL15: 167
A16: RCV-BKE-2026-0015 | B16: 15 | C16: BKE-003 | F16: LOT-BKE-2026-0015 | G16: INSIDE | H16: 842 | I16: 72593 | J16: 838LX01 | K16: 46074 | L16: 21-Feb | M16: 46074 | N16: 21-Feb | O16: KATIOLA | P16: SCOOPS AH AL NOUR | Q16: LBA-016-NOU | R16: 516 | S16: 0 | T16: 21 | V16: 537 | Z16: =SUM(R16:U16) -> 537 | AA16: 46380 | AB16: 84 | AC16: 45843 | AD16: =IF(OR(AE16="",AB16=""),"",AE16-AB16) -> 45759 | AE16: 45843 | AF16: 45843 | AK16: =IF(COUNTA(AH16:AJ16)=0,"",SUM(AH16:AJ16)) | AO16: =IF(COUNTA(AL16:AN16)=0,"",SUM(AL16:AN16)) | AP16: =IF(COUNTA(AL16:AN16)<3,"",(AL16+0.5*(AM16+AN16))*0.17637) | AQ16: =IF(AO16="","",AO16*0.17637) | AR16: =IF(COUNTA(AJ16,AH16,AL16:AN16)=0,"",(AJ16+AH16+AL16+AM16+AN16)*0.17637) | AS16: =IF(AO16="","",AO16/1000) | AT16: =IF(COUNTA(AH16,AJ16,AL16:AN16)=0,"",SUM(AH16,AJ16,AL16:AN16)/1000) | AU16: 9 | AV16: 165 | BA16: =IF(COUNTA(AX16:AZ16)=0,"",SUM(AX16:AZ16)) | BE16: =IF(COUNTA(BB16:BD16)=0,"",SUM(BB16:BD16)) | BF16: =IF(COUNTA(BB16:BD16)<3,"",(BB16+0.5*(BC16+BD16))*0.17637) | BG16: =IF(BE16="","",BE16*0.17637) | BH16: =IF(COUNTA(AZ16,AX16,BB16:BD16)=0,"",(AZ16+AX16+BB16+BC16+BD16)*0.17637) | BI16: =IF(BE16="","",BE16/1000) | BJ16: =IF(COUNTA(AX16,AZ16,BB16:BD16)=0,"",SUM(AX16,AZ16,BB16:BD16)/1000) | BK16: 9 | BL16: 165
A17: RCV-BKE-2026-0016 | B17: 16 | C17: BKE-002 | F17: LOT-BKE-2026-0016 | G17: INSIDE | H17: 844 | I17: 68145 | J17: 32LA01 | K17: 46074 | L17: 21-Feb | M17: 46074 | N17: 21-Feb | O17: DIANRA | P17: SCOOPS DPVICA | Q17: LBA-017-DPV | R17: 493 | S17: 0 | T17: 27 | V17: 520 | Z17: =SUM(R17:U17) -> 520 | AA17: 40740 | AB17: 108 | AC17: 40220 | AD17: =IF(OR(AE17="",AB17=""),"",AE17-AB17) -> 40112 | AE17: 40220 | AF17: 40220 | AK17: =IF(COUNTA(AH17:AJ17)=0,"",SUM(AH17:AJ17)) | AO17: =IF(COUNTA(AL17:AN17)=0,"",SUM(AL17:AN17)) | AP17: =IF(COUNTA(AL17:AN17)<3,"",(AL17+0.5*(AM17+AN17))*0.17637) | AQ17: =IF(AO17="","",AO17*0.17637) | AR17: =IF(COUNTA(AJ17,AH17,AL17:AN17)=0,"",(AJ17+AH17+AL17+AM17+AN17)*0.17637) | AS17: =IF(AO17="","",AO17/1000) | AT17: =IF(COUNTA(AH17,AJ17,AL17:AN17)=0,"",SUM(AH17,AJ17,AL17:AN17)/1000) | AU17: 9.3 | AV17: 166 | BA17: =IF(COUNTA(AX17:AZ17)=0,"",SUM(AX17:AZ17)) | BE17: =IF(COUNTA(BB17:BD17)=0,"",SUM(BB17:BD17)) | BF17: =IF(COUNTA(BB17:BD17)<3,"",(BB17+0.5*(BC17+BD17))*0.17637) | BG17: =IF(BE17="","",BE17*0.17637) | BH17: =IF(COUNTA(AZ17,AX17,BB17:BD17)=0,"",(AZ17+AX17+BB17+BC17+BD17)*0.17637) | BI17: =IF(BE17="","",BE17/1000) | BJ17: =IF(COUNTA(AX17,AZ17,BB17:BD17)=0,"",SUM(AX17,AZ17,BB17:BD17)/1000) | BK17: 9.3 | BL17: 166
A18: RCV-BKE-2026-0017 | B18: 17 | C18: BKE-003 | F18: LOT-BKE-2026-0017 | G18: INSIDE | H18: 768 | I18: 72620 | J18: 2766HC01 | K18: 46077 | L18: 24-Feb | M18: 46077 | N18: 24-Feb | O18: KATIOLA | P18: SCOOPS COOPRAKA | Q18: LBA-018-COP | R18: 441 | S18: 0 | T18: 10 | V18: 451 | Z18: =SUM(R18:U18) -> 451 | AA18: 39020 | AB18: 40 | AC18: 38569 | AD18: =IF(OR(AE18="",AB18=""),"",AE18-AB18) -> 38529 | AE18: 38569 | AF18: 38569 | AK18: =IF(COUNTA(AH18:AJ18)=0,"",SUM(AH18:AJ18)) | AO18: =IF(COUNTA(AL18:AN18)=0,"",SUM(AL18:AN18)) | AP18: =IF(COUNTA(AL18:AN18)<3,"",(AL18+0.5*(AM18+AN18))*0.17637) | AQ18: =IF(AO18="","",AO18*0.17637) | AR18: =IF(COUNTA(AJ18,AH18,AL18:AN18)=0,"",(AJ18+AH18+AL18+AM18+AN18)*0.17637) | AS18: =IF(AO18="","",AO18/1000) | AT18: =IF(COUNTA(AH18,AJ18,AL18:AN18)=0,"",SUM(AH18,AJ18,AL18:AN18)/1000) | AU18: 9.4 | AV18: 174 | BA18: =IF(COUNTA(AX18:AZ18)=0,"",SUM(AX18:AZ18)) | BE18: =IF(COUNTA(BB18:BD18)=0,"",SUM(BB18:BD18)) | BF18: =IF(COUNTA(BB18:BD18)<3,"",(BB18+0.5*(BC18+BD18))*0.17637) | BG18: =IF(BE18="","",BE18*0.17637) | BH18: =IF(COUNTA(AZ18,AX18,BB18:BD18)=0,"",(AZ18+AX18+BB18+BC18+BD18)*0.17637) | BI18: =IF(BE18="","",BE18/1000) | BJ18: =IF(COUNTA(AX18,AZ18,BB18:BD18)=0,"",SUM(AX18,AZ18,BB18:BD18)/1000) | BK18: 9.4 | BL18: 174
A19: RCV-BKE-2026-0018 | B19: 18 | C19: BKE-003 | F19: LOT-BKE-2026-0018 | G19: INSIDE | H19: 778 | I19: 68659 | J19: 3619 EJ 03 | K19: 46078 | L19: 25-Feb | M19: 46078 | N19: 25-Feb | O19: BOUNDIALI | P19: CASP-S SCOOPS | Q19: LBA-007-CAS | R19: 606 | S19: 0 | T19: 30 | V19: 636 | Z19: =SUM(R19:U19) -> 636 | AA19: 51380 | AB19: 120 | AC19: 50744 | AD19: =IF(OR(AE19="",AB19=""),"",AE19-AB19) -> 50624 | AE19: 50744 | AF19: 50744 | AK19: =IF(COUNTA(AH19:AJ19)=0,"",SUM(AH19:AJ19)) | AO19: =IF(COUNTA(AL19:AN19)=0,"",SUM(AL19:AN19)) | AP19: =IF(COUNTA(AL19:AN19)<3,"",(AL19+0.5*(AM19+AN19))*0.17637) | AQ19: =IF(AO19="","",AO19*0.17637) | AR19: =IF(COUNTA(AJ19,AH19,AL19:AN19)=0,"",(AJ19+AH19+AL19+AM19+AN19)*0.17637) | AS19: =IF(AO19="","",AO19/1000) | AT19: =IF(COUNTA(AH19,AJ19,AL19:AN19)=0,"",SUM(AH19,AJ19,AL19:AN19)/1000) | AU19: 8 | AV19: 175 | BA19: =IF(COUNTA(AX19:AZ19)=0,"",SUM(AX19:AZ19)) | BE19: =IF(COUNTA(BB19:BD19)=0,"",SUM(BB19:BD19)) | BF19: =IF(COUNTA(BB19:BD19)<3,"",(BB19+0.5*(BC19+BD19))*0.17637) | BG19: =IF(BE19="","",BE19*0.17637) | BH19: =IF(COUNTA(AZ19,AX19,BB19:BD19)=0,"",(AZ19+AX19+BB19+BC19+BD19)*0.17637) | BI19: =IF(BE19="","",BE19/1000) | BJ19: =IF(COUNTA(AX19,AZ19,BB19:BD19)=0,"",SUM(AX19,AZ19,BB19:BD19)/1000) | BK19: 8 | BL19: 175
A20: RCV-BKE-2026-0019 | B20: 19 | C20: BKE-003 | F20: LOT-BKE-2026-0019 | G20: INSIDE | H20: 1238 | I20: 77662 | J20: 374LK01 | K20: 46086 | L20: 05-Mar | M20: 46086 | N20: 05-Mar | O20: NIAKARA | P20: DAGNOGO KARIM | Q20: LBA-013-DAG | R20: 494 | S20: 0 | T20: 10 | V20: 504 | Z20: =SUM(R20:U20) -> 504 | AA20: 46760 | AB20: 40 | AC20: 46256 | AD20: =IF(OR(AE20="",AB20=""),"",AE20-AB20) -> 46216 | AE20: 46256 | AF20: 46256 | AK20: =IF(COUNTA(AH20:AJ20)=0,"",SUM(AH20:AJ20)) | AO20: =IF(COUNTA(AL20:AN20)=0,"",SUM(AL20:AN20)) | AP20: =IF(COUNTA(AL20:AN20)<3,"",(AL20+0.5*(AM20+AN20))*0.17637) | AQ20: =IF(AO20="","",AO20*0.17637) | AR20: =IF(COUNTA(AJ20,AH20,AL20:AN20)=0,"",(AJ20+AH20+AL20+AM20+AN20)*0.17637) | AS20: =IF(AO20="","",AO20/1000) | AT20: =IF(COUNTA(AH20,AJ20,AL20:AN20)=0,"",SUM(AH20,AJ20,AL20:AN20)/1000) | AU20: 9.7 | AV20: 160 | BA20: =IF(COUNTA(AX20:AZ20)=0,"",SUM(AX20:AZ20)) | BE20: =IF(COUNTA(BB20:BD20)=0,"",SUM(BB20:BD20)) | BF20: =IF(COUNTA(BB20:BD20)<3,"",(BB20+0.5*(BC20+BD20))*0.17637) | BG20: =IF(BE20="","",BE20*0.17637) | BH20: =IF(COUNTA(AZ20,AX20,BB20:BD20)=0,"",(AZ20+AX20+BB20+BC20+BD20)*0.17637) | BI20: =IF(BE20="","",BE20/1000) | BJ20: =IF(COUNTA(AX20,AZ20,BB20:BD20)=0,"",SUM(AX20,AZ20,BB20:BD20)/1000) | BK20: 9.7 | BL20: 160
A21: RCV-BKE-2026-0020 | B21: 20 | C21: BKE-001 | F21: LOT-BKE-2026-0020 | G21: INSIDE | H21: 202 | I21: 77633 | J21: 6085HR03 | K21: 46088 | L21: 07-Mar | M21: 46088 | N21: 07-Mar | O21: NIAKARA | P21: SCOOPS HERE B | Q21: LBA-003-HER | R21: 540 | S21: 0 | T21: 8 | V21: 548 | Z21: =SUM(R21:U21) -> 548 | AA21: 46040 | AB21: 32 | AC21: 45492 | AD21: =IF(OR(AE21="",AB21=""),"",AE21-AB21) -> 45460 | AE21: 45492 | AF21: 45492 | AK21: =IF(COUNTA(AH21:AJ21)=0,"",SUM(AH21:AJ21)) | AO21: =IF(COUNTA(AL21:AN21)=0,"",SUM(AL21:AN21)) | AP21: =IF(COUNTA(AL21:AN21)<3,"",(AL21+0.5*(AM21+AN21))*0.17637) | AQ21: =IF(AO21="","",AO21*0.17637) | AR21: =IF(COUNTA(AJ21,AH21,AL21:AN21)=0,"",(AJ21+AH21+AL21+AM21+AN21)*0.17637) | AS21: =IF(AO21="","",AO21/1000) | AT21: =IF(COUNTA(AH21,AJ21,AL21:AN21)=0,"",SUM(AH21,AJ21,AL21:AN21)/1000) | AU21: 9.8 | AV21: 168 | BA21: =IF(COUNTA(AX21:AZ21)=0,"",SUM(AX21:AZ21)) | BE21: =IF(COUNTA(BB21:BD21)=0,"",SUM(BB21:BD21)) | BF21: =IF(COUNTA(BB21:BD21)<3,"",(BB21+0.5*(BC21+BD21))*0.17637) | BG21: =IF(BE21="","",BE21*0.17637) | BH21: =IF(COUNTA(AZ21,AX21,BB21:BD21)=0,"",(AZ21+AX21+BB21+BC21+BD21)*0.17637) | BI21: =IF(BE21="","",BE21/1000) | BJ21: =IF(COUNTA(AX21,AZ21,BB21:BD21)=0,"",SUM(AX21,AZ21,BB21:BD21)/1000) | BK21: 9.8 | BL21: 168
A22: RCV-BKE-2026-0021 | B22: 21 | C22: BKE-001 | F22: LOT-BKE-2026-0021 | G22: INSIDE | H22: 225 | I22: 75589 | J22: 6690GB01 | K22: 46092 | L22: 11-Mar | M22: 46092 | N22: 11-Mar | O22: VAVOUA | P22: SCOPPAS SCOOPS | Q22: LBA-009-SCO | R22: 605 | S22: 0 | T22: 8 | V22: 613 | Z22: =SUM(R22:U22) -> 613 | AA22: 48580 | AB22: 32 | AC22: 47967 | AD22: =IF(OR(AE22="",AB22=""),"",AE22-AB22) -> 47935 | AE22: 47967 | AF22: 47967 | AK22: =IF(COUNTA(AH22:AJ22)=0,"",SUM(AH22:AJ22)) | AO22: =IF(COUNTA(AL22:AN22)=0,"",SUM(AL22:AN22)) | AP22: =IF(COUNTA(AL22:AN22)<3,"",(AL22+0.5*(AM22+AN22))*0.17637) | AQ22: =IF(AO22="","",AO22*0.17637) | AR22: =IF(COUNTA(AJ22,AH22,AL22:AN22)=0,"",(AJ22+AH22+AL22+AM22+AN22)*0.17637) | AS22: =IF(AO22="","",AO22/1000) | AT22: =IF(COUNTA(AH22,AJ22,AL22:AN22)=0,"",SUM(AH22,AJ22,AL22:AN22)/1000) | AU22: 9.9 | AV22: 185 | BA22: =IF(COUNTA(AX22:AZ22)=0,"",SUM(AX22:AZ22)) | BE22: =IF(COUNTA(BB22:BD22)=0,"",SUM(BB22:BD22)) | BF22: =IF(COUNTA(BB22:BD22)<3,"",(BB22+0.5*(BC22+BD22))*0.17637) | BG22: =IF(BE22="","",BE22*0.17637) | BH22: =IF(COUNTA(AZ22,AX22,BB22:BD22)=0,"",(AZ22+AX22+BB22+BC22+BD22)*0.17637) | BI22: =IF(BE22="","",BE22/1000) | BJ22: =IF(COUNTA(AX22,AZ22,BB22:BD22)=0,"",SUM(AX22,AZ22,BB22:BD22)/1000) | BK22: 9.9 | BL22: 185
A23: RCV-BKE-2026-0022 | B23: 22 | C23: BKE-001 | F23: LOT-BKE-2026-0022 | G23: INSIDE | H23: 237 | I23: 72647 | J23: 8573GA01 | K23: 46093 | L23: 12-Mar | M23: 46093 | N23: 12-Mar | O23: SEGUELA | P23: SCOOP-CA/COBAN | Q23: LBA-008-COB | R23: 506 | S23: 0 | T23: 10 | V23: 516 | Z23: =SUM(R23:U23) -> 516 | AA23: 40300 | AB23: 40 | AC23: 39784 | AD23: =IF(OR(AE23="",AB23=""),"",AE23-AB23) -> 39744 | AE23: 39784 | AF23: 39784 | AK23: =IF(COUNTA(AH23:AJ23)=0,"",SUM(AH23:AJ23)) | AO23: =IF(COUNTA(AL23:AN23)=0,"",SUM(AL23:AN23)) | AP23: =IF(COUNTA(AL23:AN23)<3,"",(AL23+0.5*(AM23+AN23))*0.17637) | AQ23: =IF(AO23="","",AO23*0.17637) | AR23: =IF(COUNTA(AJ23,AH23,AL23:AN23)=0,"",(AJ23+AH23+AL23+AM23+AN23)*0.17637) | AS23: =IF(AO23="","",AO23/1000) | AT23: =IF(COUNTA(AH23,AJ23,AL23:AN23)=0,"",SUM(AH23,AJ23,AL23:AN23)/1000) | AU23: 7.5 | AV23: 166 | BA23: =IF(COUNTA(AX23:AZ23)=0,"",SUM(AX23:AZ23)) | BE23: =IF(COUNTA(BB23:BD23)=0,"",SUM(BB23:BD23)) | BF23: =IF(COUNTA(BB23:BD23)<3,"",(BB23+0.5*(BC23+BD23))*0.17637) | BG23: =IF(BE23="","",BE23*0.17637) | BH23: =IF(COUNTA(AZ23,AX23,BB23:BD23)=0,"",(AZ23+AX23+BB23+BC23+BD23)*0.17637) | BI23: =IF(BE23="","",BE23/1000) | BJ23: =IF(COUNTA(AX23,AZ23,BB23:BD23)=0,"",SUM(AX23,AZ23,BB23:BD23)/1000) | BK23: 7.5 | BL23: 166
A24: RCV-BKE-2026-0023 | B24: 23 | C24: BKE-002 | F24: LOT-BKE-2026-0023 | G24: INSIDE | H24: 246 | I24: 82147 | J24: AA869FY01 | K24: 46095 | L24: 14-Mar | M24: 46095 | N24: 14-Mar | O24: DABAKALA | P24: SCOOPS WEBE | Q24: LBA-004-WEB | R24: 532 | S24: 0 | T24: 8 | V24: 540 | Z24: =SUM(R24:U24) -> 540 | AA24: 44880 | AB24: 32 | AC24: 44340 | AD24: =IF(OR(AE24="",AB24=""),"",AE24-AB24) -> 44308 | AE24: 44340 | AF24: 44340 | AK24: =IF(COUNTA(AH24:AJ24)=0,"",SUM(AH24:AJ24)) | AO24: =IF(COUNTA(AL24:AN24)=0,"",SUM(AL24:AN24)) | AP24: =IF(COUNTA(AL24:AN24)<3,"",(AL24+0.5*(AM24+AN24))*0.17637) | AQ24: =IF(AO24="","",AO24*0.17637) | AR24: =IF(COUNTA(AJ24,AH24,AL24:AN24)=0,"",(AJ24+AH24+AL24+AM24+AN24)*0.17637) | AS24: =IF(AO24="","",AO24/1000) | AT24: =IF(COUNTA(AH24,AJ24,AL24:AN24)=0,"",SUM(AH24,AJ24,AL24:AN24)/1000) | AU24: 8.6 | AV24: 166 | BA24: =IF(COUNTA(AX24:AZ24)=0,"",SUM(AX24:AZ24)) | BE24: =IF(COUNTA(BB24:BD24)=0,"",SUM(BB24:BD24)) | BF24: =IF(COUNTA(BB24:BD24)<3,"",(BB24+0.5*(BC24+BD24))*0.17637) | BG24: =IF(BE24="","",BE24*0.17637) | BH24: =IF(COUNTA(AZ24,AX24,BB24:BD24)=0,"",(AZ24+AX24+BB24+BC24+BD24)*0.17637) | BI24: =IF(BE24="","",BE24/1000) | BJ24: =IF(COUNTA(AX24,AZ24,BB24:BD24)=0,"",SUM(AX24,AZ24,BB24:BD24)/1000) | BK24: 8.6 | BL24: 166
A25: RCV-BKE-2026-0024 | B25: 24 | C25: BKE-001 | D25: BKE-001-BIN-015 | F25: LOT-BKE-2026-0024 | G25: INSIDE | H25: 108 | I25: 82869 | J25: 8287GH03 | K25: 46096 | L25: 15-Mar | M25: 46097 | N25: 16-Mar | O25: DABAKALA | P25: SCOOPS HERE B | Q25: LBA-003-HER | R25: 455 | S25: 0 | T25: 20 | V25: 475 | Z25: =SUM(R25:U25) -> 475 | AA25: 39880 | AB25: 80 | AC25: 39405 | AD25: =IF(OR(AE25="",AB25=""),"",AE25-AB25) -> 39325 | AE25: 39405 | AF25: 39405 | AK25: =IF(COUNTA(AH25:AJ25)=0,"",SUM(AH25:AJ25)) | AO25: =IF(COUNTA(AL25:AN25)=0,"",SUM(AL25:AN25)) | AP25: =IF(COUNTA(AL25:AN25)<3,"",(AL25+0.5*(AM25+AN25))*0.17637) | AQ25: =IF(AO25="","",AO25*0.17637) | AR25: =IF(COUNTA(AJ25,AH25,AL25:AN25)=0,"",(AJ25+AH25+AL25+AM25+AN25)*0.17637) | AS25: =IF(AO25="","",AO25/1000) | AT25: =IF(COUNTA(AH25,AJ25,AL25:AN25)=0,"",SUM(AH25,AJ25,AL25:AN25)/1000) | AU25: 12.2 | AV25: 189 | BA25: =IF(COUNTA(AX25:AZ25)=0,"",SUM(AX25:AZ25)) | BE25: =IF(COUNTA(BB25:BD25)=0,"",SUM(BB25:BD25)) | BF25: =IF(COUNTA(BB25:BD25)<3,"",(BB25+0.5*(BC25+BD25))*0.17637) | BG25: =IF(BE25="","",BE25*0.17637) | BH25: =IF(COUNTA(AZ25,AX25,BB25:BD25)=0,"",(AZ25+AX25+BB25+BC25+BD25)*0.17637) | BI25: =IF(BE25="","",BE25/1000) | BJ25: =IF(COUNTA(AX25,AZ25,BB25:BD25)=0,"",SUM(AX25,AZ25,BB25:BD25)/1000) | BK25: 12.2 | BL25: 189
