Workbook
Name Prestataires: [1]Listes!$A$2:$A$20
Name Sites: [2]Listes!$B$2:$B$20
Name Sites: [1]Listes!$B$2:$B$20

Sheet FINAL DRY RCN-YAKRO-2026
M1: =SUBTOTAL(9,Table1[[#All],[Issued Wt to Drying GW RCN+BAGS]]) -> 4096678.4 | O1: =SUMIF(T2:T83,">0",O2:O83) -> 4044378.4 | P1: WIP | Q1: =SUMIF(Table1[[#All],[Received Wt from Drying (Net Wt)]],0,Table1[[#All],[Issued Wt To Drying (Net Wt)]]) -> 0 | T1: =SUBTOTAL(9,T3:T83) -> 3939483 | AI1: =SUBTOTAL(9,AI2:AI83) -> 104895.38 | AL1: =SUM(AL2:AL65) -> 41676
A2: S.No. | B2: DATE | C2: Warehouse | D2: BIN | E2: Lot No | F2: FICHE NO | G2: STATUS | H2: Dry Type | I2: Destintion | J2: Dry Bin No | K2: Issued for Drying GW RCN+BAGS+PALLETS | L2: Pallets WT | M2: Issued Wt to Drying GW RCN+BAGS | N2: Issued Bags for Drying | O2: Issued Wt To Drying (Net Wt) | P2: Received from Drying GW RCN+BAGS+PALLETS | Q2: Pallets Wt2 | R2: Received Wt from Drying GW RCN+BAGS | S2: Received Bags from Drying | T2: Received Wt from Drying (Net Wt) | U2: Input Moisture | V2: INPUT NUT COUNT | W2: INPUT KOR | X2: Output Moisture | Y2: OUTPUT NUT COUNT | Z2: OUTPUT KOR | AA2: Oil | AB2: Rejection | AC2: GK | AD2: Immature | AE2: Spoted | AF2: Shell | AG2: Void | AH2: MOIS Loss% | AI2: Drying Loss Kg's | AJ2: Drying LOSS % | AK2: INPUT BAGS FOR DRYING | AL2: OUTPUT BAGS AFTER DRING | AM2: DRYING/ PICKING | AN2: REMARKS | AO2: Issued To Production | AP2: Re Drying Date | AQ2: Moisture -1st Re- Dry | AR2: Moisture -2nd Dry | AS2: Issued to Production3 | AT2: Remarks4 | AW2: Row Labels | AX2: Sum of Issued Wt To Drying (Net Wt) | AY2: Sum of Received Wt from Drying (Net Wt)
A3: 1 | B3: 46099 | C3: ANAGROCI-01 | D3: BIN-002 | E3: 23 | F3: 77676 | G3: OK | H3: Supplier | I3: ANA-03-DRY | J3: ANA-03-DRY | K3: 49460 | L3: 0 | M3: =K3-L3 -> 49460 | N3: 596 | O3: =M3-N3 -> 48864 | P3: 47807 | Q3: 0 | R3: =P3-Q3 -> 47807 | S3: 592 | T3: =R3-S3 -> 47215 | U3: 11 | V3: 171 | W3: 45.23 | X3: 8.9 | Y3: 173 | Z3: 45.67 | AH3: =(U3-X3)/100 -> 0.021 | AI3: =O3-T3 -> 1649 | AJ3: =AI3/O3 -> 0.033746726 | AK3: 638 | AL3: 592 | AM3: Dryied | AN3: Scaled | AO3: BIN | AW3: BIN-001 | AX3: 554648 | AY3: 530547
A4: 2 | B4: 46106 | C4: ANAGROCI-01 | D4: BIN-002 | E4: 29 | F4: 82146 | G4: OK | H4: Supplier | I4: ANA-03-DRY | J4: ANA-03-DRY | K4: 39700 | L4: 0 | M4: =K4-L4 -> 39700 | N4: 467 | O4: =M4-N4 -> 39233 | P4: 38213.916 | Q4: 0 | R4: =P4-Q4 -> 38213.916 | S4: 502 | T4: =R4-S4 -> 37711.916 | U4: 12 | V4: 176 | W4: 45.05 | X4: 9.4 | Y4: 176 | Z4: 45.5 | AH4: =(U4-X4)/100 -> 0.026 | AI4: =O4-T4 -> 1521.084 | AJ4: =AI4/O4 -> 0.038770525 | AK4: 489 | AL4: 502 | AM4: Dryied | AN4: Scaled | AO4: BIN | AW4: BIN-002 | AX4: 131477 | AY4: 126201.92
A5: 3 | B5: 46108 | C5: ANAGROCI-01 | D5: BIN-008 | E5: 5 | F5: 72564 | G5: OK | H5: BOUAKE | I5: ANA-08-DRY | J5: ANA-08-DRY | K5: 51840 | L5: 0 | M5: =K5-L5 -> 51840 | N5: 608 | O5: =M5-N5 -> 51232 | P5: 49643.808 | Q5: 0 | R5: =P5-Q5 -> 49643.808 | S5: 699 | T5: =R5-S5 -> 48944.808 | U5: 12 | V5: 157 | W5: 45.32 | X5: 8.9 | Y5: 160 | Z5: 45.49 | AH5: =(U5-X5)/100 -> 0.031 | AI5: =O5-T5 -> 2287.192 | AJ5: =AI5/O5 -> 0.044643816 | AK5: 615 | AL5: 699 | AM5: Dryied | AN5: Scaled | AO5: BIN | AW5: BIN-003 | AX5: 41220 | AY5: 39785
A6: 4 | B6: 46109 | C6: ANAGROCI-01 | D6: BIN-09A | E6: 20 | F6: 72566 | G6: OK | H6: BOUAKE | I6: ANA-09-DRY | J6: ANA-09-DRY | K6: 38380 | L6: 0 | M6: =K6-L6 -> 38380 | N6: 537 | O6: =M6-N6 -> 37843 | P6: 36783.396 | Q6: 0 | R6: =P6-Q6 -> 36783.396 | S6: 530 | T6: =R6-S6 -> 36253.396 | U6: 11.7 | V6: 174 | W6: 43.82 | X6: 8.9 | Y6: 172 | Z6: 43.91 | AH6: =(U6-X6)/100 -> 0.028 | AI6: =O6-T6 -> 1589.604 | AJ6: =AI6/O6 -> 0.042005232 | AK6: 537 | AL6: 530 | AM6: Dryied | AN6: Scaled | AO6: BIN | AW6: BIN-004 | AX6: 122091 | AY6: 119602
A7: 5 | B7: 46109 | C7: ANAGROCI-01 | D7: BIN-001 | E7: 56 | F7: 82495 | G7: OK | H7: Supplier | I7: ANA-02-DRY | J7: ANA-02-DRY | K7: 46120 | L7: 0 | M7: =K7-L7 -> 46120 | N7: 530 | O7: =M7-N7 -> 45590 | P7: 43876 | Q7: 0 | R7: =P7-Q7 -> 43876 | S7: 601 | T7: =R7-S7 -> 43275 | U7: 11.2 | V7: 183 | W7: 44.35 | X7: 9.3 | Y7: 184 | Z7: 44.7 | AH7: =(U7-X7)/100 -> 0.019 | AI7: =O7-T7 -> 2315 | AJ7: =AI7/O7 -> 0.05077868 | AK7: 538 | AL7: 601 | AM7: Dryied | AN7: Scaled | AO7: BIN | AT7: PROCESSING | AW7: BIN-005 | AX7: 587959.6 | AY7: 580102.2
A8: 6 | B8: 46114 | C8: ANAGROCI-01 | D8: BIN-003 | E8: 61 | F8: 83411 | G8: OK | H8: Supplier | I8: ANA-05-DRY | J8: ANA-05-DRY | K8: 41780 | L8: 0 | M8: =K8-L8 -> 41780 | N8: 560 | O8: =M8-N8 -> 41220 | P8: 42642 | Q8: 2280 | R8: =P8-Q8 -> 40362 | S8: 577 | T8: =R8-S8 -> 39785 | U8: 10.1 | V8: 185 | W8: 46.2 | X8: 8.5 | Y8: 170 | Z8: 46.2 | AH8: =(U8-X8)/100 -> 0.016 | AI8: =O8-T8 -> 1435 | AJ8: =AI8/O8 -> 0.034813197 | AK8: 568 | AL8: 577 | AM8: Dryied | AN8: Scaled | AO8: BIN | AW8: BIN-007 | AX8: 320974.2 | AY8: 315527.7
A9: 7 | B9: 46115 | C9: ANAGROCI-01 | D9: BIN-002 | E9: 64 | F9: 82496 | G9: OK | H9: Supplier | I9: ANA-03-DRY | J9: ANA-03-DRY | K9: 43880 | L9: 0 | M9: =K9-L9 -> 43880 | N9: 500 | O9: =M9-N9 -> 43380 | P9: 44295 | Q9: 2470 | R9: =P9-Q9 -> 41825 | S9: 550 | T9: =R9-S9 -> 41275 | U9: 11.8 | V9: 177 | W9: 44.44 | X9: 9.2 | Y9: 176 | Z9: 45.2 | AH9: =(U9-X9)/100 -> 0.026 | AI9: =O9-T9 -> 2105 | AJ9: =AI9/O9 -> 0.048524666 | AK9: 509 | AL9: 550 | AM9: Dryied | AN9: Scaled | AO9: BIN | AW9: BIN-008 | AX9: 51232 | AY9: 48944.808
A10: 8 | B10: 46120 | C10: ANAGROCI-01 | D10: BIN-07A | E10: 67 | F10: 87134 | G10: OK | H10: Supplier | I10: ANA-07-DRY | J10: ANA-07-DRY | K10: 37160 | L10: 0 | M10: =K10-L10 -> 37160 | N10: 454 | O10: =M10-N10 -> 36706 | P10: 37911 | Q10: 2050 | R10: =P10-Q10 -> 35861 | S10: 477 | T10: =R10-S10 -> 35384 | U10: 11 | V10: 170 | W10: 45.15 | X10: 8.3 | Y10: 173 | Z10: 45.85 | AH10: =(U10-X10)/100 -> 0.027 | AI10: =O10-T10 -> 1322 | AJ10: =AI10/O10 -> 0.03601591 | AK10: 463 | AL10: 477 | AM10: Dryied | AN10: Scaled | AO10: BIN | AW10: BIN-013 | AX10: 667561 | AY10: 646363
A11: 9 | B11: 46123 | C11: ANAGROCI-01 | D11: BIN-001 | E11: 72 | F11: 87139 | G11: OK | H11: Supplier | I11: ANA-02-DRY | J11: ANA-02-DRY | K11: 54260 | L11: 0 | M11: =K11-L11 -> 54260 | N11: 706 | O11: =M11-N11 -> 53554 | P11: 55007 | Q11: 2945 | R11: =P11-Q11 -> 52062 | S11: 712 | T11: =R11-S11 -> 51350 | U11: 10.1 | V11: 183 | W11: 44.09 | X11: 8 | Y11: 181 | Z11: 44.26 | AH11: =(U11-X11)/100 -> 0.021 | AI11: =O11-T11 -> 2204 | AJ11: =AI11/O11 -> 0.041154722 | AK11: 721 | AL11: 712 | AM11: Dryied | AN11: Scaled | AO11: BIN | AT11: PROCESSING | AW11: BIN-015 | AX11: 55476 | AY11: 54448
A12: 10 | B12: 46124 | C12: ANAGROCI-01 | D12: BIN-001 | E12: 76 | F12: 78911 | G12: OK | H12: Supplier | I12: ANA-02-DRY | J12: ANA-02-DRY | K12: 47640 | L12: 0 | M12: =K12-L12 -> 47640 | N12: 658 | O12: =M12-N12 -> 46982 | P12: 48274 | Q12: 2660 | R12: =P12-Q12 -> 45614 | S12: 648 | T12: =R12-S12 -> 44966 | U12: 10.1 | V12: 185 | W12: 44.26 | X12: 8.3 | Y12: 179 | Z12: 44.53 | AH12: =(U12-X12)/100 -> 0.018 | AI12: =O12-T12 -> 2016 | AJ12: =AI12/O12 -> 0.042910051 | AK12: 658 | AL12: 648 | AM12: Dryied | AN12: Scaled | AO12: BIN | AT12: PROCESSING | AW12: BIN-016 | AX12: 37217 | AY12: 36341
A13: 11 | B13: 46125 | C13: ANAGROCI-01 | D13: BIN-001 | E13: 79 | F13: 37970 | G13: OK | H13: Supplier | I13: ANA-02-DRY | J13: ANA-02-DRY | K13: 42110 | L13: 0 | M13: =K13-L13 -> 42110 | N13: 488 | O13: =M13-N13 -> 41622 | P13: 42671 | Q13: 2280 | R13: =P13-Q13 -> 40391 | S13: 542 | T13: =R13-S13 -> 39849 | U13: 13.7 | V13: 160 | W13: 43.56 | X13: 9.7 | Y13: 163 | Z13: 44 | AH13: =(U13-X13)/100 -> 0.04 | AI13: =O13-T13 -> 1773 | AJ13: =AI13/O13 -> 0.042597665 | AK13: 488 | AL13: 542 | AM13: Dryied | AN13: Scaled | AO13: BIN | AT13: PROCESSING | AW13: BIN-03B | AX13: 1271107.6 | AY13: 1245576
A14: 12 | B14: 46128 | C14: ANAGROCI-01 | D14: BIN-001 | E14: 102 | F14: 78869 | G14: OK | H14: Supplier | I14: ANA-02-DRY | J14: ANA-02-DRY | K14: 49690 | L14: 0 | M14: =K14-L14 -> 49690 | N14: 684 | O14: =M14-N14 -> 49006 | P14: 50005 | Q14: 2575 | R14: =P14-Q14 -> 47430 | S14: 674 | T14: =R14-S14 -> 46756 | U14: 11.2 | V14: 181 | W14: 43.56 | X14: 9.4 | Y14: 182 | Z14: 44 | AH14: =(U14-X14)/100 -> 0.018 | AI14: =O14-T14 -> 2250 | AJ14: =AI14/O14 -> 0.045912745 | AK14: 691 | AL14: 674 | AM14: Dryied | AN14: Scaled | AO14: BIN | AT14: PROCESSING | AW14: BIN-06A | AX14: 128866 | AY14: 124407
A15: 13 | B15: 46129 | C15: ANAGROCI-01 | D15: BIN-013 | E15: 96 | F15: 89770 | G15: OK | H15: Supplier | I15: ANA-01-DRY | J15: ANA-01-DRY | K15: 50530 | L15: 0 | M15: =K15-L15 -> 50530 | N15: 598 | O15: =M15-N15 -> 49932 | P15: 51035 | Q15: 2660 | R15: =P15-Q15 -> 48375 | S15: 644 | T15: =R15-S15 -> 47731 | U15: 11.1 | V15: 168 | W15: 42.58 | X15: 8.9 | Y15: 172 | Z15: 43.12 | AH15: =(U15-X15)/100 -> 0.022 | AI15: =O15-T15 -> 2201 | AJ15: =AI15/O15 -> 0.044079949 | AK15: 612 | AL15: 644 | AM15: Dryied | AN15: Scaled | AO15: Issued to Production | AS15: Issued to Production | AT15: PROCESSED | AW15: BIN-07A | AX15: 36706 | AY15: 35384
A16: 14 | B16: 46130 | C16: ANAGROCI-01 | D16: BIN-013 | E16: 95 | F16: 89781 | G16: OK | H16: Supplier | I16: ANA-01-DRY | J16: ANA-01-DRY | K16: 50350 | L16: 0 | M16: =K16-L16 -> 50350 | N16: 604 | O16: =M16-N16 -> 49746 | P16: 51004 | Q16: 2660 | R16: =P16-Q16 -> 48344 | S16: 667 | T16: =R16-S16 -> 47677 | U16: 12.3 | V16: 169 | W16: 42.41 | X16: 9.8 | Y16: 170 | Z16: 42.85 | AH16: =(U16-X16)/100 -> 0.025 | AI16: =O16-T16 -> 2069 | AJ16: =AI16/O16 -> 0.041591284 | AK16: 629 | AL16: 667 | AM16: Dryied | AN16: Scaled | AO16: Issued to Production | AS16: Issued to Production | AT16: PROCESSED | AW16: BIN-09A | AX16: 37843 | AY16: 36253.396
A17: 15 | B17: 46131 | C17: ANAGROCI-01 | D17: BIN-001 | E17: 116 | F17: 31888 | G17: OK | H17: Supplier | I17: ANA-02-DRY | J17: ANA-02-DRY | K17: 40690 | L17: 0 | M17: =K17-L17 -> 40690 | N17: 489 | O17: =M17-N17 -> 40201 | P17: 40311 | Q17: 1386 | R17: =P17-Q17 -> 38925 | S17: 524 | T17: =R17-S17 -> 38401 | U17: 14.2 | V17: 158 | W17: 44.18 | X17: 10.1 | Y17: 160 | Z17: 44.26 | AH17: =(U17-X17)/100 -> 0.041 | AI17: =O17-T17 -> 1800 | AJ17: =AI17/O17 -> 0.044775006 | AK17: 489 | AL17: 524 | AM17: Dryied | AN17: Scaled | AO17: BIN | AT17: PROCESSING | AW17: Grand Total | AX17: 4044378.4 | AY17: 3939483
A18: 16 | B18: 46133 | C18: ANAGROCI-01 | D18: BIN-013 | E18: 122 | F18: 29107 | G18: OK | H18: Supplier | I18: ANA-01-DRY | J18: ANA-01-DRY | K18: 45980 | L18: 0 | M18: =K18-L18 -> 45980 | N18: 604 | O18: =M18-N18 -> 45376 | P18: 46755 | Q18: 2375 | R18: =P18-Q18 -> 44380 | S18: 600 | T18: =R18-S18 -> 43780 | U18: 10.3 | V18: 183 | W18: 41.79 | X18: 8.6 | Y18: 180 | Z18: 43.38 | AH18: =(U18-X18)/100 -> 0.017 | AI18: =O18-T18 -> 1596 | AJ18: =AI18/O18 -> 0.035172779 | AK18: 609 | AL18: 600 | AM18: Dryied | AN18: Scaled | AO18: Issued to Production | AS18: Issued to Production | AT18: PROCESSED
A19: 17 | B19: 46133 | C19: ANAGROCI-01 | D19: BIN-013 | E19: 125 | F19: 37582 | G19: OK | H19: Supplier | I19: ANA-01-DRY | J19: ANA-01-DRY | K19: 45520 | L19: 0 | M19: =K19-L19 -> 45520 | N19: 444 | O19: =M19-N19 -> 45076 | P19: 46698 | Q19: 2660 | R19: =P19-Q19 -> 44038 | S19: 585 | T19: =R19-S19 -> 43453 | U19: 11.4 | V19: 162 | W19: 43.12 | X19: 9.5 | Y19: 161 | Z19: 43.38 | AH19: =(U19-X19)/100 -> 0.019 | AI19: =O19-T19 -> 1623 | AJ19: =AI19/O19 -> 0.036005857 | AK19: 475 | AL19: 585 | AM19: Dryied | AN19: Scaled | AO19: Issued to Production | AS19: Issued to Production | AT19: PROCESSED
A20: 18 | B20: 46134 | C20: ANAGROCI-01 | D20: BIN-06A | E20: 135 | F20: 87109 | G20: OK | H20: Supplier | I20: ANA-06-DRY | J20: ANA-06-DRY | K20: 47060 | L20: 0 | M20: =K20-L20 -> 47060 | N20: 587 | O20: =M20-N20 -> 46473 | P20: 47318 | Q20: 2125 | R20: =P20-Q20 -> 45193 | S20: 606 | T20: =R20-S20 -> 44587 | U20: 10.7 | V20: 182 | W20: 42.15 | X20: 9.1 | Y20: 176 | Z20: 44.7 | AH20: =(U20-X20)/100 -> 0.016 | AI20: =O20-T20 -> 1886 | AJ20: =AI20/O20 -> 0.040582704 | AK20: 594 | AL20: 606 | AM20: Dryied | AN20: Scaled | AO20: BIN
A21: 19 | B21: 46134 | C21: ANAGROCI-01 | D21: BIN-013 | E21: 139 | F21: 35967 | G21: OK | H21: Supplier | I21: ANA-01-DRY | J21: ANA-01-DRY | K21: 42400 | L21: 0 | M21: =K21-L21 -> 42400 | N21: 523 | O21: =M21-N21 -> 41877 | P21: 43491 | Q21: 2125 | R21: =P21-Q21 -> 41366 | S21: 564 | T21: =R21-S21 -> 40802 | U21: 11.4 | V21: 178 | W21: 41.97 | X21: 9.3 | Y21: 179 | Z21: 42.68 | AH21: =(U21-X21)/100 -> 0.021 | AI21: =O21-T21 -> 1075 | AJ21: =AI21/O21 -> 0.025670416 | AK21: 542 | AL21: 564 | AM21: Dryied | AN21: Scaled | AO21: Issued to Production | AS21: Issued to Production | AT21: PROCESSED
A22: 20 | B22: 46135 | C22: ANAGROCI-01 | D22: BIN-013 | E22: 113 | F22: 87146 | G22: OK | H22: Supplier | I22: ANA-01-DRY | J22: ANA-01-DRY | K22: 34010 | L22: 0 | M22: =K22-L22 -> 34010 | N22: 430 | O22: =M22-N22 -> 33580 | P22: 34791 | Q22: 1785 | R22: =P22-Q22 -> 33006 | S22: 457 | T22: =R22-S22 -> 32549 | U22: 9.8 | V22: 172 | W22: 42.59 | X22: 8.8 | Y22: 171 | Z22: 43.65 | AH22: =(U22-X22)/100 -> 0.01 | AI22: =O22-T22 -> 1031 | AJ22: =AI22/O22 -> 0.030702799 | AK22: 449 | AL22: 457 | AM22: Dryied | AN22: Scaled | AO22: Issued to Production | AS22: Issued to Production | AT22: PROCESSED
A23: 21 | B23: 46136 | C23: ANAGROCI-01 | D23: BIN-013 | E23: 107 | F23: 37581 | G23: OK | H23: Supplier | I23: ANA-01-DRY | J23: ANA-01-DRY | K23: 45490 | L23: 0 | M23: =K23-L23 -> 45490 | N23: 531 | O23: =M23-N23 -> 44959 | P23: 47169 | Q23: 2295 | R23: =P23-Q23 -> 44874 | S23: 603 | T23: =R23-S23 -> 44271 | U23: 10.1 | V23: 159 | W23: 42.15 | X23: 8.7 | Y23: 164 | Z23: 42.59 | AH23: =(U23-X23)/100 -> 0.014 | AI23: =O23-T23 -> 688 | AJ23: =AI23/O23 -> 0.015302831 | AK23: 558 | AL23: 603 | AM23: Dryied | AN23: Scaled | AO23: Issued to Production | AS23: Issued to Production | AT23: PROCESSED
A24: 22 | B24: 46136 | C24: ANAGROCI-01 | D24: BIN-001 | E24: 110 | F24: 3198 | G24: OK | H24: Supplier | I24: ANA-02-DRY | J24: ANA-02-DRY | K24: 37970 | L24: 0 | M24: =K24-L24 -> 37970 | N24: 426 | O24: =M24-N24 -> 37544 | P24: 38637 | Q24: 1700 | R24: =P24-Q24 -> 36937 | S24: 506 | T24: =R24-S24 -> 36431 | U24: 12.9 | V24: 158 | W24: 43.21 | X24: 9.8 | Y24: 166 | Z24: 44.26 | AH24: =(U24-X24)/100 -> 0.031 | AI24: =O24-T24 -> 1113 | AJ24: =AI24/O24 -> 0.029645216 | AK24: 450 | AL24: 506 | AM24: Dryied | AN24: Scaled | AO24: BIN | AT24: PROCESSING
A25: 23 | B25: 46137 | C25: ANAGROCI-01 | D25: BIN-06A | E25: 162 | F25: 89784 | G25: OK | H25: Supplier | I25: ANA-06-DRY | J25: ANA-06-DRY | K25: 39460 | L25: 0 | M25: =K25-L25 -> 39460 | N25: 477 | O25: =M25-N25 -> 38983 | P25: 40251 | Q25: 1870 | R25: =P25-Q25 -> 38381 | S25: 518 | T25: =R25-S25 -> 37863 | U25: 12.8 | V25: 170 | W25: 44.09 | X25: 10.1 | Y25: 169 | Z25: 44.97 | AH25: =(U25-X25)/100 -> 0.027 | AI25: =O25-T25 -> 1120 | AJ25: =AI25/O25 -> 0.028730472 | AK25: 486 | AL25: 518 | AM25: Dryied | AN25: Scaled | AO25: BIN
A26: 24 | B26: 46137 | C26: ANAGROCI-01 | D26: BIN-06A | E26: 160 | F26: 65511 | G26: OK | H26: Supplier | I26: ANA-06-DRY | J26: ANA-06-DRY | K26: 43950 | L26: 0 | M26: =K26-L26 -> 43950 | N26: 540 | O26: =M26-N26 -> 43410 | P26: 44482 | Q26: 1955 | R26: =P26-Q26 -> 42527 | S26: 570 | T26: =R26-S26 -> 41957 | U26: 14.3 | V26: 165 | W26: 43.73 | X26: 10.9 | Y26: 169 | Z26: 45.06 | AH26: =(U26-X26)/100 -> 0.034 | AI26: =O26-T26 -> 1453 | AJ26: =AI26/O26 -> 0.03347155 | AK26: 566 | AL26: 570 | AM26: Dryied | AN26: Scaled | AO26: BIN
A27: 25 | B27: 46138 | C27: ANAGROCI-01 | D27: BIN-001 | E27: 173 | F27: 32358 | G27: OK | H27: Supplier | I27: ANA-02-DRY | J27: ANA-02-DRY | K27: 46090 | L27: 0 | M27: =K27-L27 -> 46090 | N27: 533 | O27: =M27-N27 -> 45557 | P27: 46658 | Q27: 2210 | R27: =P27-Q27 -> 44448 | S27: 594 | T27: =R27-S27 -> 43854 | U27: 13.6 | V27: 172 | W27: 44.2 | X27: 9.8 | Y27: 169 | Z27: 44.53 | AH27: =(U27-X27)/100 -> 0.038 | AI27: =O27-T27 -> 1703 | AJ27: =AI27/O27 -> 0.037381742 | AK27: 533 | AL27: 594 | AM27: Dryied | AN27: Scaled | AO27: BIN | AT27: PROCESSING
A28: 26 | B28: 46138 | C28: ANAGROCI-01 | D28: BIN-013 | E28: 172 | F28: 87093 | G28: OK | H28: Supplier | I28: ANA-01-DRY | J28: ANA-01-DRY | K28: 40130 | L28: 0 | M28: =K28-L28 -> 40130 | N28: 496 | O28: =M28-N28 -> 39634 | P28: 40789 | Q28: 1870 | R28: =P28-Q28 -> 38919 | S28: 528 | T28: =R28-S28 -> 38391 | U28: 11.1 | V28: 183 | W28: 41.97 | X28: 10.5 | Y28: 176 | Z28: 42.68 | AH28: =(U28-X28)/100 -> 0.006 | AI28: =O28-T28 -> 1243 | AJ28: =AI28/O28 -> 0.031361962 | AK28: 496 | AL28: 528 | AM28: Dryied | AN28: Scaled | AO28: Issued to Production | AS28: Issued to Production | AT28: PROCESSED
A29: 27 | B29: 46139 | C29: ANAGROCI-01 | D29: BIN-001 | E29: 139 | F29: 68652 | G29: OK | H29: BOUAKE | I29: ANA-02-DRY | J29: ANA-02-DRY | K29: 51380 | L29: 0 | M29: =K29-L29 -> 51380 | N29: 656 | O29: =M29-N29 -> 50724 | P29: 51652 | Q29: 2295 | R29: =P29-Q29 -> 49357 | S29: 660 | T29: =R29-S29 -> 48697 | U29: 10.8 | V29: 174 | W29: 42.06 | X29: 8.4 | Y29: 180 | Z29: 43.73 | AH29: =(U29-X29)/100 -> 0.024 | AI29: =O29-T29 -> 2027 | AJ29: =AI29/O29 -> 0.03996136 | AK29: 673 | AL29: 660 | AM29: Dryied | AN29: Scaled | AO29: BIN | AT29: PROCESSING
A30: 28 | B30: 46140 | C30: ANAGROCI-01 | D30: BIN-013 | E30: 184 | F30: 35051 | G30: OK | H30: Supplier | I30: ANA-01-DRY | J30: ANA-01-DRY | K30: 48740 | L30: 0 | M30: =K30-L30 -> 48740 | N30: 564 | O30: =M30-N30 -> 48176 | P30: 50339 | Q30: 2380 | R30: =P30-Q30 -> 47959 | S30: 643 | T30: =R30-S30 -> 47316 | U30: 11.2 | V30: 189 | W30: 42.32 | X30: 9.7 | Y30: 199 | Z30: 42.32 | AH30: =(U30-X30)/100 -> 0.015 | AI30: =O30-T30 -> 860 | AJ30: =AI30/O30 -> 0.017851212 | AK30: 567 | AL30: 643 | AM30: Dryied | AN30: Scaled | AO30: Empilage in Production Area | AS30: Issued to Production | AT30: PROCESSED
A31: 29 | B31: 46142 | C31: ANAGROCI-01 | D31: BIN-013 | E31: 193 | F31: 773 | G31: OK | H31: Supplier | I31: ANA-01-DRY | J31: ANA-01-DRY | K31: 43680 | L31: 0 | M31: =K31-L31 -> 43680 | N31: 531 | O31: =M31-N31 -> 43149 | P31: 44299 | Q31: 1955 | R31: =P31-Q31 -> 42344 | S31: 572 | T31: =R31-S31 -> 41772 | U31: 11.8 | V31: 185 | W31: 43.03 | X31: 9.6 | Y31: 183 | Z31: 43.32 | AA31: 0 | AB31: 49 | AC31: 227 | AD31: 10 | AE31: 16 | AF31: 675 | AG31: 17 | AH31: =(U31-X31)/100 -> 0.022 | AI31: =O31-T31 -> 1377 | AJ31: =AI31/O31 -> 0.031912675 | AK31: 540 | AL31: 572 | AM31: Dryied | AN31: Scaled | AO31: Empilage in Production Area | AS31: Issued to Production | AT31: PROCESSED
A32: 30 | B32: 46142 | C32: ANAGROCI-01 | D32: BIN-013 | E32: 197 | F32: 14643 | G32: Direct offload for dry | H32: Supplier | I32: ANA-01-DRY | J32: ANA-01-DRY | K32: 40480 | L32: 0 | M32: =K32-L32 -> 40480 | N32: 453 | O32: =M32-N32 -> 40027 | P32: 40602 | Q32: 1650 | R32: =P32-Q32 -> 38952 | S32: 536 | T32: =R32-S32 -> 38416 | U32: 11.8 | V32: 160 | W32: 43.12 | X32: 10.4 | Y32: 164 | Z32: 43.21 | AA32: 4 | AB32: 20 | AC32: 230 | AD32: 12 | AE32: 18 | AF32: 675 | AG32: 36 | AH32: =(U32-X32)/100 -> 0.014 | AI32: =O32-T32 -> 1611 | AJ32: =AI32/O32 -> 0.040247833 | AK32: 465 | AL32: 536 | AM32: Dryied | AN32: Scaled | AO32: Empilage in Production Area | AS32: Issued to Production | AT32: PROCESSED
A33: 31 | B33: 46145 | C33: ANAGROCI-01 | D33: BIN-013 | E33: 178 | F33: 82154 | H33: BOUAKE | I33: ANA-01-DRY | J33: ANA-01-DRY | K33: 46700 | L33: 0 | M33: =K33-L33 -> 46700 | N33: 576 | O33: =M33-N33 -> 46124 | P33: 46125 | Q33: 1680 | R33: =P33-Q33 -> 44445 | S33: 584 | T33: =R33-S33 -> 43861 | U33: 12.1 | V33: 171 | W33: 42.32 | X33: 8.9 | Y33: 174 | Z33: 42.5 | AH33: =(U33-X33)/100 -> 0.032 | AI33: =O33-T33 -> 2263 | AJ33: =AI33/O33 -> 0.049063394 | AK33: 530 | AL33: 584 | AM33: Dryied | AN33: Scaled | AO33: Issued to Production | AP33: 46239 | AQ33: 10.1 | AR33: 8.9 | AS33: Issued to Production | AT33: PROCESSED
A34: 32 | B34: 46145 | C34: ANAGROCI-01 | D34: BIN-001 | E34: 160 | F34: 82124 | G34: OK | H34: BOUAKE | I34: ANA-02-DRY | J34: ANA-02-DRY | K34: 54180 | L34: 0 | M34: =K34-L34 -> 54180 | N34: 646 | O34: =M34-N34 -> 53534 | P34: 55082 | Q34: 2044 | R34: =P34-Q34 -> 53038 | S34: 701 | T34: =R34-S34 -> 52337 | U34: 15.4 | V34: 158 | W34: 43.56 | X34: 10.5 | Y34: 170 | Z34: 44.26 | AA34: 0 | AB34: 27 | AC34: 244 | AD34: 10 | AE34: 4 | AF34: 674 | AG34: 37 | AH34: =(U34-X34)/100 -> 0.049 | AI34: =O34-T34 -> 1197 | AJ34: =AI34/O34 -> 0.022359622 | AK34: 631 | AL34: 701 | AM34: Dryied | AN34: Scaled | AO34: BIN | AT34: PROCESSING
A35: 33 | B35: 46145 | C35: ANAGROCI-01 | D35: BIN-001 | E35: 177 | F35: 82914 | G35: OK | H35: BOUAKE | I35: ANA-02-DRY | J35: ANA-02-DRY | K35: 40980 | L35: 0 | M35: =K35-L35 -> 40980 | N35: 507 | O35: =M35-N35 -> 40473 | P35: 39521 | Q35: 1470 | R35: =P35-Q35 -> 38051 | S35: 491 | T35: =R35-S35 -> 37560 | U35: 13.9 | V35: 166 | W35: 42.41 | X35: 10.6 | Y35: 176 | Z35: 44.35 | AH35: =(U35-X35)/100 -> 0.033 | AI35: =O35-T35 -> 2913 | AJ35: =AI35/O35 -> 0.071973909 | AK35: 521 | AL35: 491 | AM35: Dryied | AN35: Scaled | AO35: BIN | AP35: 46300 | AQ35: 10.6 | AR35: 9 | AS35: Need re drying -Calibrator rejected to accept the caro due to high moisture | AT35: PROCESSING
A36: 34 | B36: 46146 | C36: ANAGROCI-01 | D36: BIN-013 | E36: 179 | F36: 66919 | H36: BOUAKE | I36: ANA-01-DRY | J36: ANA-01-DRY | K36: 42480 | L36: 0 | M36: =K36-L36 -> 42480 | N36: 577 | O36: =M36-N36 -> 41903 | P36: 42599 | Q36: 1633 | R36: =P36-Q36 -> 40966 | S36: 547 | T36: =R36-S36 -> 40419 | U36: 10.5 | V36: 184 | W36: 42.41 | X36: 8.5 | Y36: 188 | Z36: 43.03 | AA36: 2 | AB36: 22 | AC36: 234 | AD36: 12 | AE36: 10 | AF36: 681 | AG36: 34 | AH36: =(U36-X36)/100 -> 0.02 | AI36: =O36-T36 -> 1484 | AJ36: =AI36/O36 -> 0.035415125 | AK36: 599 | AL36: 547 | AM36: Dryied | AN36: Scaled | AO36: Empilage in Production Area | AS36: Issued to Production | AT36: PROCESSED
A37: 35 | B37: 46147 | C37: ANAGROCI-01 | D37: BIN-001 | E37: 222 | F37: 36093 | G37: OK | H37: Supplier | I37: ANA-02-DRY | J37: ANA-02-DRY | K37: 50440 | L37: 0 | M37: =K37-L37 -> 50440 | N37: 579 | O37: =M37-N37 -> 49861 | P37: 49632 | Q37: 1950 | R37: =P37-Q37 -> 47682 | S37: 611 | T37: =R37-S37 -> 47071 | U37: 14.7 | V37: 173 | W37: 43.65 | X37: 9.6 | Y37: 167 | Z37: 44.44 | AH37: =(U37-X37)/100 -> 0.051 | AI37: =O37-T37 -> 2790 | AJ37: =AI37/O37 -> 0.055955556 | AK37: 597 | AL37: 611 | AM37: Dryied | AN37: Scaled | AO37: BIN | AT37: PROCESSING
A38: 36 | B38: 46154 | C38: ANAGROCI-01 | D38: BIN-03B | E38: BIN-03B | F38: 82484 | G38: OK | H38: BIN-03B | I38: ANA-01-DRY | J38: ANA-01-DRY | K38: 48780 | L38: 1460 | M38: =K38-L38 -> 47320 | N38: 597 | O38: =M38-N38 -> 46723 | P38: 47936 | Q38: 1800 | R38: =P38-Q38 -> 46136 | S38: 605 | T38: =R38-S38 -> 45531 | U38: 11 | X38: 9 | Y38: 168 | Z38: 42.76 | AH38: =(U38-X38)/100 -> 0.02 | AI38: =O38-T38 -> 1192 | AJ38: =AI38/O38 -> 0.02551206 | AK38: 597 | AL38: 605 | AM38: Dryied | AN38: Scaled | AO38: Issued to Production | AS38: Issued to Production | AT38: PROCESSED
A39: 37 | B39: 46155 | C39: ANAGROCI-01 | D39: BIN-03B | E39: BIN-03B | F39: 64970 | G39: OK | H39: BIN-03B | I39: ANA-01-DRY | J39: ANA-01-DRY | K39: 46287 | L39: 1391 | M39: =K39-L39 -> 44896 | N39: 572 | O39: =M39-N39 -> 44324 | P39: 45644 | Q39: 1771 | R39: =P39-Q39 -> 43873 | S39: 575 | T39: =R39-S39 -> 43298 | U39: 11 | X39: 9 | Y39: 168 | Z39: 42.76 | AH39: =(U39-X39)/100 -> 0.02 | AI39: =O39-T39 -> 1026 | AJ39: =AI39/O39 -> 0.02314773 | AK39: 572 | AL39: 575 | AM39: Dryied | AN39: Scaled | AO39: Issued to Production | AS39: Issued to Production | AT39: PROCESSED
A40: 38 | B40: 46157 | C40: ANAGROCI-01 | D40: BIN-03B | E40: BIN-03B | F40: 77650 | G40: OK | H40: BIN-03B | I40: ANA-01-DRY | J40: ANA-01-DRY | K40: 51884 | L40: 1584 | M40: =K40-L40 -> 50300 | N40: 660 | O40: =M40-N40 -> 49640 | P40: 50879 | Q40: 1971 | R40: =P40-Q40 -> 48908 | S40: 638 | T40: =R40-S40 -> 48270 | U40: 12 | X40: 8.5 | Y40: 172 | Z40: 42.15 | AH40: =(U40-X40)/100 -> 0.035 | AI40: =O40-T40 -> 1370 | AJ40: =AI40/O40 -> 0.027598711 | AK40: 660 | AL40: 638 | AM40: Dryied | AN40: Scaled | AO40: Issued to Production | AS40: Issued to Production | AT40: PROCESSED
...

Sheet No Dryied Issued RCN
L1: =SUBTOTAL(9,L3:L12)/1000 -> 1158.1538 | O1: =SUBTOTAL(9,O3:O76)/1000 -> 8759.6946
A2: S.No. | B2: DATE | C2: BIN | D2: Lot No | E2: STATUS | F2: Dry Type | G2: Destintion | H2: Dry Bin No | I2: Issued Wt (Pallet + Jute Bag +Cashew) | J2: Pallet Wt | K2: Issued Gwt -Bag +Cashew | L2: Net Wt-WH | M2: No of Bag Issued | N2: Bag Wt | O2: Nwt Issued
A3: 1 | B3: 17-06-2026 | C3: BIN-05 | D3: BIN-05 | E3: Issued Direct from BIN | F3: BIN-Low Moisture | G3: ANA-05-DRY | H3: ANA-05-DRY | K3: 112235 | L3: =K3-M3 -> 110750 | M3: 1485 | N3: =M3*0.65 -> 965.25 | O3: =K3-N3 -> 111269.75
A4: 2 | B4: 18-06-2026 | C4: BIN-05 | D4: BIN-05 | E4: Issued Direct from BIN | F4: BIN-Low Moisture | G4: ANA-05-DRY | H4: ANA-05-DRY | K4: 155376 | L4: =K4-M4 -> 153337 | M4: 2039 | N4: =M4*0.65 -> 1325.35 | O4: =K4-N4 -> 154050.65
A5: 3 | B5: 23-06-2026 | C5: BIN-02A | D5: BIN-02A | E5: Issued Direct from BIN | F5: BIN-Low Moisture | G5: ANA-02A-DRY | H5: ANA-02A-DRY | K5: 109097.8 | L5: =K5-M5 -> 107657.8 | M5: =1440 -> 1440 | N5: =M5*0.65 -> 936 | O5: =K5-N5 -> 108161.8
A6: 4 | B6: 25-06-2026 | C6: BIN-02A | D6: BIN-02A | E6: Issued Direct from BIN | F6: BIN-Low Moisture | G6: ANA-02A-DRY | H6: ANA-02A-DRY | K6: 99598 | L6: =K6-M6 -> 98277 | M6: 1321 | N6: =M6*0.65 -> 858.65 | O6: =K6-N6 -> 98739.35
A7: 5 | B7: 26-06-2026 | C7: BIN-02A | D7: BIN-02A | E7: Issued Direct from BIN | F7: BIN-Low Moisture | G7: ANA-02A-DRY | H7: ANA-02A-DRY | K7: =116651.4 -> 116651.4 | L7: =K7-M7 -> 115151.4 | M7: 1500 | N7: =M7*0.65 -> 975 | O7: =K7-N7 -> 115676.4
A8: 6 | B8: 27-06-2026 | C8: BIN-02A | D8: BIN-02A | E8: Issued Direct from BIN | F8: BIN-Low Moisture | G8: ANA-02A-DRY | H8: ANA-02A-DRY | K8: 110815.8 | L8: =K8-M8 -> 109313.8 | M8: =751+751 -> 1502 | N8: =M8*0.65 -> 976.3 | O8: =K8-N8 -> 109839.5
A9: 7 | B9: 28-06-2026 | C9: BIN-02A | D9: BIN-02A | E9: Issued Direct from BIN | F9: BIN-Low Moisture | G9: ANA-02A-DRY | H9: ANA-02A-DRY | K9: =87594.5-2913.2 -> 84681.3 | L9: =K9-M9 -> 83511.3 | M9: 1170 | N9: =M9*0.65 -> 760.5 | O9: =K9-N9 -> 83920.8
A10: 8 | B10: 29-06-2026 | C10: BIN-02A | D10: BIN-02A | E10: Issued Direct from BIN | F10: BIN-Low Moisture | G10: ANA-02A-DRY | H10: ANA-02A-DRY | I10: =107540.1 -> 107540.1 | J10: 3615.7 | K10: =I10-J10 -> 103924.4 | L10: =K10-M10 -> 102420.4 | M10: =1504 -> 1504 | N10: =M10*0.65 -> 977.6 | O10: =K10-N10 -> 102946.8
A11: 9 | B11: 30-06-2026 | C11: BIN-02A | D11: BIN-02A | E11: Issued Direct from BIN | F11: BIN-Low Moisture | G11: ANA-02A-DRY | H11: ANA-02A-DRY | I11: =230579.4 -> 230579.4 | J11: =7052.3 -> 7052.3 | K11: =I11-J11 -> 223527.1 | L11: =K11-M11 -> 220520.1 | M11: =3007 -> 3007 | N11: =M11*0.65 -> 1954.55 | O11: =K11-N11 -> 221572.55
A12: 10 | B12: 46029 | C12: BIN-02A | D12: BIN-02A | E12: Issued Direct from BIN | F12: BIN-Low Moisture | G12: ANA-02A-DRY | H12: ANA-02A-DRY | I12: =59664+100 -> 59764 | J12: 1798 | K12: =I12-J12 -> 57966 | L12: =K12-M12 -> 57215 | M12: 751 | N12: =M12*0.65 -> 488.15 | O12: =K12-N12 -> 57477.85
A13: 11 | B13: 46060 | C13: BIN-02A | D13: BIN-02A | E13: Issued Direct from BIN | F13: BIN-Low Moisture | G13: ANA-02A-DRY | H13: ANA-02A-DRY | I13: =56632.6+13181.3+59078.6+56226.1-347.6 -> 184771 | J13: =260.5+216.9+223.9+215.3+245.6+753.3+1207.3+204.1+211.4+430.1+205.9+191+233.1+360+749.3+201 -> 5908.7 | K13: =I13-J13 -> 178862.3 | L13: =K13-M13 -> 176455.3 | M13: =734+180+748+750-5 -> 2407 | N13: =M13*0.65 -> 1564.55 | O13: =K13-N13 -> 177297.75
A14: 12 | B14: 46119 | C14: BIN-02B | D14: BIN-02B | E14: Issued Direct from BIN | F14: BIN-Low Moisture | G14: ANA-02B-DRY | H14: ANA-02B-DRY | I14: =226161.9 -> 226161.9 | J14: 7388.4 | K14: =I14-J14 -> 218773.5 | L14: =K14-M14 -> 215766.5 | M14: 3007 | N14: =M14*0.65 -> 1954.55 | O14: =K14-N14 -> 216818.95
A15: 13 | B15: 46210 | C15: BIN-02B | D15: BIN-02B | E15: Issued Direct from BIN | F15: BIN-Low Moisture | G15: ANA-02B-DRY | H15: ANA-02B-DRY | I15: 160177.5 | J15: 5170.5 | K15: =I15-J15 -> 155007 | L15: =K15-M15 -> 152882 | M15: =2125 -> 2125 | N15: =M15*0.65 -> 1381.25 | O15: =K15-N15 -> 153625.75
A16: 14 | B16: 46302 | C16: BIN-02B | D16: BIN-02B | E16: Issued Direct from BIN | F16: BIN-Low Moisture | G16: ANA-02B-DRY | H16: ANA-02B-DRY | I16: =224785.1 -> 224785.1 | J16: =7410 -> 7410 | K16: =I16-J16 -> 217375.1 | L16: =K16-M16 -> 214380.1 | M16: 2995 | N16: =M16*0.65 -> 1946.75 | O16: =K16-N16 -> 215428.35
A17: 15 | B17: 46333 | C17: BIN-02B | D17: BIN-02B | E17: Issued Direct from BIN | F17: BIN-Low Moisture | G17: ANA-02B-DRY | H17: ANA-02B-DRY | I17: 111500.7 | J17: 3710.7 | K17: =I17-J17 -> 107790 | L17: =K17-M17 -> 106261 | M17: 1529 | N17: =M17*0.65 -> 993.85 | O17: =K17-N17 -> 106796.15
A18: 16 | B18: 46363 | C18: BIN-02B | D18: BIN-02B | E18: Issued Direct from BIN | F18: BIN-Low Moisture | G18: ANA-02B-DRY | H18: ANA-02B-DRY | I18: =41877.5+54336.6 -> 96214.1 | J18: =3158.3 -> 3158.3 | K18: =I18-J18 -> 93055.8 | L18: =K18-M18 -> 91741.8 | M18: =574+740 -> 1314 | N18: =M18*0.65 -> 854.1 | O18: =K18-N18 -> 92201.7
A19: 17 | B19: 13/07/2026 | C19: BIN-02B | D19: BIN-02B | E19: Issued Direct from BIN | F19: BIN-Low Moisture | G19: ANA-02B-DRY | H19: ANA-02B-DRY | I19: 93027.9 | J19: 3101.3 | K19: =I19-J19 -> 89926.6 | L19: =K19-M19 -> 88642.6 | M19: =750+534 -> 1284 | N19: =M19*0.65 -> 834.6 | O19: =K19-N19 -> 89092
A20: 18 | B20: 14/07/2026 | C20: BIN-08A | D20: BIN-08A | E20: Issued Direct from BIN | F20: BIN-Low Moisture | G20: BIN-08A | H20: ANA-08A-DRY | I20: =100356.6 -> 100356.6 | J20: =3180.2 -> 3180.2 | K20: =I20-J20 -> 97176.4 | L20: =K20-M20 -> 95887.4 | M20: =718+571 -> 1289 | N20: =M20*0.65 -> 837.85 | O20: =K20-N20 -> 96338.55
A21: 19 | B21: 15/07/2026 | C21: BIN-08A | D21: BIN-08A | E21: Issued Direct from BIN | F21: BIN-Low Moisture | G21: BIN-08A | H21: ANA-08A-DRY | I21: 102254.3 | J21: 3340.3 | K21: =I21-J21 -> 98914 | L21: =K21-M21 -> 97581 | M21: =752+581 -> 1333 | N21: =M21*0.65 -> 866.45 | O21: =K21-N21 -> 98047.55
A22: 20 | B22: 16/07/2026 | C22: BIN-08A | D22: BIN-08A | E22: Issued Direct from BIN | F22: BIN-Low Moisture | G22: BIN-08A | H22: ANA-08A-DRY | I22: =185021.6 -> 185021.6 | J22: 5904.3 | K22: =I22-J22 -> 179117.3 | L22: =K22-M22 -> 176672.3 | M22: 2445 | N22: =M22*0.65 -> 1589.25 | O22: =K22-N22 -> 177528.05
A23: 21 | B23: 17/07/2026 | C23: BIN-08A | D23: BIN-08A | E23: Issued Direct from BIN | F23: BIN-Low Moisture | G23: BIN-08A | H23: ANA-08A-DRY | I23: =55817.5 -> 55817.5 | J23: 1859.9 | K23: =I23-J23 -> 53957.6 | L23: =K23-M23 -> 53222.6 | M23: 735 | N23: =M23*0.65 -> 477.75 | O23: =K23-N23 -> 53479.85
A24: 22 | B24: 18/07/2026 | C24: BIN-03B | D24: BIN-03B | E24: Issued Direct from BIN | F24: BIN-Low Moisture | G24: BIN-03B | H24: ANA-03B-DRY | I24: 93913.7 | J24: 3010.8 | K24: =I24-J24 -> 90902.9 | L24: =K24-M24 -> 89701.9 | M24: 1201 | N24: =M24*0.65 -> 780.65 | O24: =K24-N24 -> 90122.25
A25: 23 | B25: 20/07/2026 | C25: BIN-03B | D25: BIN-03B | E25: Issued Direct from BIN | F25: BIN-Low Moisture | G25: BIN-03B | H25: ANA-03B-DRY | I25: 86128.9 | J25: 2641.2 | K25: =I25-J25 -> 83487.7 | L25: =K25-M25 -> 82405.7 | M25: 1082 | N25: =M25*0.65 -> 703.3 | O25: =K25-N25 -> 82784.4
A26: 24 | B26: 21/07/2026 | C26: BIN-03B | D26: BIN-03B | E26: Issued Direct from BIN | F26: BIN-Low Moisture | G26: BIN-03B | H26: ANA-03B-DRY | I26: 174333.3 | J26: 5305.6 | K26: =I26-J26 -> 169027.7 | L26: =K26-M26 -> 166808.7 | M26: 2219 | N26: =M26*0.65 -> 1442.35 | O26: =K26-N26 -> 167585.35
A27: 25 | B27: 22/07/2026 | C27: BIN-03B | D27: BIN-03B | E27: Issued Direct from BIN | F27: BIN-Low Moisture | G27: BIN-03B | H27: ANA-03B-DRY | I27: 186066.7 | J27: 5928.4 | K27: =I27-J27 -> 180138.3 | L27: =K27-M27 -> 177749.3 | M27: 2389 | N27: =M27*0.65 -> 1552.85 | O27: =K27-N27 -> 178585.45
A28: 26 | B28: 23/07/2026 | C28: BIN-03B | D28: BIN-03B | E28: Issued Direct from BIN | F28: BIN-Low Moisture | G28: BIN-03B | H28: ANA-03B-DRY | I28: 233839.9 | J28: 7357.4 | K28: =I28-J28 -> 226482.5 | L28: =K28-M28 -> 223477.5 | M28: 3005 | N28: =M28*0.65 -> 1953.25 | O28: =K28-N28 -> 224529.25
A29: 27 | B29: 24/07/2026 | C29: BIN-03B | D29: BIN-03B | E29: Issued Direct from BIN | F29: BIN-Low Moisture | G29: BIN-03B | H29: ANA-03B-DRY | I29: 214697.1 | J29: 6634 | K29: =I29-J29 -> 208063.1 | L29: =K29-M29 -> 205349.1 | M29: 2714 | N29: =M29*0.65 -> 1764.1 | O29: =K29-N29 -> 206299
A30: 28 | B30: 25/07/2026 | C30: BIN-03B | D30: BIN-03B | E30: Issued Direct from BIN | F30: BIN-Low Moisture | G30: BIN-03B | H30: ANA-03B-DRY | I30: 143519.6 | J30: 4494.9 | K30: =I30-J30 -> 139024.7 | L30: =K30-M30 -> 137189.7 | M30: 1835 | N30: =M30*0.65 -> 1192.75 | O30: =K30-N30 -> 137831.95
A31: 29 | B31: 27/07/2026 | C31: BIN-03B | D31: BIN-03B | E31: Issued Direct from BIN | F31: BIN-Low Moisture | G31: BIN-03B | H31: ANA-03B-DRY | I31: 127712.3 | J31: 3990.6 | K31: =I31-J31 -> 123721.7 | L31: =K31-M31 -> 122068.7 | M31: 1653 | N31: =M31*0.65 -> 1074.45 | O31: =K31-N31 -> 122647.25
A32: 30 | B32: 28/07/2026 | C32: BIN-03B | D32: BIN-03B | E32: Issued Direct from BIN | F32: BIN-Low Moisture | G32: BIN-03B | H32: ANA-03B-DRY | I32: 140595.8 | J32: 4345.1 | K32: =I32-J32 -> 136250.7 | L32: =K32-M32 -> 134455.7 | M32: 1795 | N32: =M32*0.65 -> 1166.75 | O32: =K32-N32 -> 135083.95
A33: 31 | B33: 29/07/2026 | C33: BIN-03B | D33: BIN-03B | E33: Issued Direct from BIN | F33: BIN-Low Moisture | G33: BIN-03B | H33: ANA-03B-DRY | I33: 141338.6 | J33: 4300.9 | K33: =I33-J33 -> 137037.7 | L33: =K33-M33 -> 135226.7 | M33: 1811 | N33: =M33*0.65 -> 1177.15 | O33: =K33-N33 -> 135860.55
A34: 32 | B34: 30/07/2026 | C34: BIN-03B | D34: BIN-03B | E34: Issued Direct from BIN | F34: BIN-Low Moisture | G34: BIN-03B | H34: ANA-03B-DRY | I34: 140767.3 | J34: 4317.5 | K34: =I34-J34 -> 136449.8 | L34: =K34-M34 -> 134652.8 | M34: 1797 | N34: =M34*0.65 -> 1168.05 | O34: =K34-N34 -> 135281.75
A35: 33 | B35: 31/07/2026 | C35: BIN-03B | D35: BIN-03B | E35: Issued Direct from BIN | F35: BIN-Low Moisture | G35: BIN-03B | H35: ANA-03B-DRY | I35: 133980.2 | J35: 4120 | K35: =I35-J35 -> 129860.2 | L35: =K35-M35 -> 128144.2 | M35: 1716 | N35: =M35*0.65 -> 1115.4 | O35: =K35-N35 -> 128744.8
A36: 34 | B36: 46061 | C36: BIN-03B | D36: BIN-03B | E36: Issued Direct from BIN | F36: BIN-Low Moisture | G36: BIN-03B | H36: ANA-03B-DRY | I36: 122379.2 | J36: =3904.9 -> 3904.9 | K36: =I36-J36 -> 118474.3 | L36: =K36-M36 -> 116891.3 | M36: 1583 | N36: =M36*0.65 -> 1028.95 | O36: =K36-N36 -> 117445.35
A37: 35 | B37: 46089 | C37: BIN-03B | D37: BIN-03B | E37: Issued Direct from BIN | F37: BIN-Low Moisture | G37: BIN-03B | H37: ANA-03B-DRY | I37: 117259.4 | J37: 3627.3 | K37: =I37-J37 -> 113632.1 | L37: =K37-M37 -> 112126.1 | M37: 1506 | N37: =M37*0.65 -> 978.9 | O37: =K37-N37 -> 112653.2
A38: 36 | B38: 46089 | C38: BIN-016 | D38: BIN-016 | E38: Issued Direct from BIN | F38: BIN-Low Moisture | G38: BIN-016 | H38: ANA-016-DRY | I38: 22122.2 | J38: 716 | K38: =I38-J38 -> 21406.2 | L38: =K38-M38 -> 21106.2 | M38: 300 | N38: =M38*0.65 -> 195 | O38: =K38-N38 -> 21211.2
A39: 37 | B39: 46120 | C39: BIN-03B | D39: BIN-03B | E39: Issued Direct from BIN | F39: BIN-Low Moisture | G39: BIN-03B | H39: ANA-03B-DRY | I39: 129133.5 | J39: 4013.1 | K39: =I39-J39 -> 125120.4 | L39: =K39-M39 -> 123464.4 | M39: 1656 | N39: =M39*0.65 -> 1076.4 | O39: =K39-N39 -> 124044
A40: 38 | B40: 46120 | C40: BIN-016 | D40: BIN-016 | E40: Issued Direct from BIN | F40: BIN-Low Moisture | G40: BIN-016 | H40: ANA-016-DRY | I40: 33387.7 | J40: 1153 | K40: =I40-J40 -> 32234.7 | L40: =K40-M40 -> 31784.7 | M40: 450 | N40: =M40*0.65 -> 292.5 | O40: =K40-N40 -> 31942.2
...

Sheet Bouake Dring RCN
A3: 36 | B3: 46331 | F3: 207 | G3: 82770 | J3: BOUAKE | P3: 49741 | Q3: 49355 | R3: =P3-Q3 -> 386 | S3: 8.9 | T3: 176 | U3: 42.76 | V3: 8.9 | W3: 176 | X3: 42.76 | AF3: =(S3-V3)/100 -> 0 | AG3: =P3-Q3 -> 386 | AH3: =IFERROR(AG3/P3,"0") -> 0.0077601978 | AI3: 639 | AJ3: 666 | AK3: 666 | AL3: Dryied | AM3: Scaled | AN3: Empilage in Production Area | AO3: Issued to Production | AT3: Issued to Production | AU3: Dried from Bouake Issued to Calibrator

Sheet Issued to Production Section
B4: DRY RCN GIVEN TO PRODUCTION SECTION
A5: SI NO | B5: Date | C5: RCN | D5: Source Bin | E5: DRY BIN | F5: Bin Status | G5: BTM | H5: KOR-Issued | I5: Nut Count | J5: GK | K5: Moisture | L5: Immature | M5: Spottd | N5: Rejection | O5: OIL (Gram) | P5: Void (Gram) | Q5: Shell (Gram) | R5: Fiche No | S5: Bag inStock afetr Dry | T5: No of Bag(Issued to Production) | U5: Avg Bag Wt (Empty Bag) | V5: Bag Wt(Empty Bag) | W5: No of Pallet | X5: Avg Pallet Wt | Y5: Pallet Weight (Kg) | Z5: Gross Wt (Before Dry) | AA5: Gross Wt (After Drying Wt with Jute Bag) | AB5: Net Wt (Without Jute Bag) | AC5: Date of Issue to Calibration | AD5: Received By Production(Net Wt) | AE5: Issued from | AF5: Diff in Issue | AG5: Remarks | AH5: Check | AK5: Row Labels | AL5: Sum of Net Wt (Without Jute Bag)
A6: 1 | B6: 46134 | C6: Dry Rcn | D6: BIN-013 | E6: ANA-01 | F6: Running | G6: 1001 | H6: 43.12 | I6: 172 | J6: 230 | K6: 8.9 | L6: 16 | M6: 13 | N6: 20 | O6: 0 | P6: 25 | Q6: 690 | R6: ='FINAL DRY RCN-YAKRO-2026'!F15 -> 89770 | S6: 644 | T6: ='FINAL DRY RCN-YAKRO-2026'!AL15 -> 644 | U6: =0.69 -> 0.69 | V6: =0.69*T6 -> 444.36 | W6: 25 | X6: 71.32 | Y6: =71.32*25 -> 1783 | AA6: =48375 -> 48375 | AB6: =AA6-V6 -> 47930.64 | AC6: 46135 | AD6: =97398 -> 97398 | AE6: BIN | AF6: =AD6-AB6-AB7 -> 1583.59 | AH6: =AF6+AB6+AB7 -> 97398 | AK6: 0 | AL6: 0
A7: 2 | B7: 46134 | C7: Dry Rcn | D7: BIN-013 | E7: ANA-01 | F7: Running | G7: 1001 | H7: 42.85 | I7: 170 | J7: 230 | K7: 9.8 | L7: 10 | M7: 16 | N7: 28 | O7: 8 | P7: 30 | Q7: 689 | R7: ='FINAL DRY RCN-YAKRO-2026'!F16 -> 89781 | S7: 667 | T7: ='FINAL DRY RCN-YAKRO-2026'!AL16 -> 667 | U7: =0.69 -> 0.69 | V7: =0.69*T7 -> 460.23 | W7: 31 | X7: =71.32 -> 71.32 | Y7: =71.32*31 -> 2210.92 | AA7: 48344 | AB7: =AA7-V7 -> 47883.77 | AC7: 46135 | AE7: BIN | AK7: BIN-001 | AL7: 539147.95
A8: 3 | B8: 46135 | C8: Dry Rcn | D8: BIN-013 | E8: ANA-01 | F8: Running | G8: 1004 | H8: 43.38 | I8: 180 | J8: 228 | K8: 8.6 | L8: 10 | M8: 11 | N8: 31 | O8: 0 | P8: 20 | Q8: 693 | R8: 29107 | S8: 600 | T8: 614 | U8: =0.617 -> 0.617 | V8: =T8*U8 -> 378.838 | W8: 26 | X8: =Y8/W8 -> 74.230769 | Y8: 1930 | AA8: 44380 | AB8: =AA8-V8 -> 44001.162 | AC8: 46137 | AD8: =44066 -> 44066 | AF8: =AD8-AB8 -> 64.838 | AH8: =AF8+AB8 -> 44066 | AK8: BIN-008A | AL8: 425394
A9: 4 | B9: 46137 | C9: Dry Rcn | D9: BIN-013 | E9: ANA-01 | F9: Running | G9: 1004 | H9: 43.65 | I9: 171 | J9: 238 | K9: 8.8 | L9: 11 | M9: 8 | N9: 30 | O9: 2 | P9: 20 | Q9: 685 | R9: 87146 | S9: 457 | T9: 458 | U9: =289/458 -> 0.63100437 | V9: =T9*U9 -> 289 | W9: 21 | X9: =Y9/W9 -> 74.747619 | Y9: 1569.7 | AA9: 33006 | AB9: =AA9-V9 -> 32717 | AC9: 46137 | AD9: =32913.9 -> 32913.9 | AF9: =AD9-AB9 -> 196.9 | AH9: =AF9+AB9 -> 32913.9 | AK9: BIN-010 | AL9: 878238.9
A10: 5 | B10: 46137 | C10: Dry Rcn | D10: BIN-013 | E10: ANA-01 | F10: Running | G10: 1002 | H10: 42.68 | I10: 176 | J10: 226 | K10: 10.5 | L10: 19 | M10: 13 | N10: 33 | O10: 2 | P10: 17 | Q10: 687 | R10: 87093 | S10: 528 | T10: 527 | U10: =289/458 -> 0.63100437 | V10: =T10*U10 -> 332.5393 | W10: 23 | X10: =Y10/W10 -> 76.847826 | Y10: =1767.5 -> 1767.5 | AA10: 38919 | AB10: =AA10-V10 -> 38586.461 | AC10: 46140 | AD10: 38461.6 | AF10: =AB10-AD10 -> 124.8607 | AH10: =AF10+AD10 -> 38586.461 | AK10: BIN-013 | AL10: 595207.81
A11: 6 | B11: 46140 | C11: Dry Rcn | D11: BIN-013 | E11: ANA-01 | F11: Running | G11: 1005 | H11: 42.59 | I11: 164 | J11: 227 | K11: 8.7 | L11: 19 | M11: 10 | N11: 16 | O11: 5 | P11: 21 | Q11: 696 | R11: 37581 | S11: 603 | T11: 609 | U11: =439.1/609 -> 0.72101806 | V11: =439.1 -> 439.1 | W11: 26 | X11: =Y11/W11 -> 75.542308 | Y11: 1964.1 | AA11: 44874 | AB11: =AA11-V11 -> 44434.9 | AC11: 46140 | AD11: =44720 -> 44720 | AF11: =AD11-AB11 -> 285.1 | AH11: =AF11+AB11 -> 44720 | AK11: BIN-016 | AL11: 272967.55
A12: 7 | B12: 46142 | C12: Dry Rcn | D12: BIN-013 | E12: ANA-01 | F12: Running | G12: 1010 | H12: 42.68 | I12: 179 | J12: 232 | K12: 9.3 | L12: 12 | M12: 8 | N12: 28 | O12: 0 | P12: 21 | Q12: 692 | R12: 35967 | S12: 564 | T12: 559 | U12: =289/458 -> 0.63100437 | V12: 352.17 | W12: 20 | X12: =Y12/W12 -> 70.425 | Y12: =1408.5 -> 1408.5 | AA12: 41366 | AB12: =AA12-V12 -> 41013.83 | AC12: 46142 | AD12: =42450.8-Y12-V12 -> 40690.13 | AF12: =AB12-AD12 -> 323.7 | AH12: =AF12+AD12 -> 41013.83 | AK12: BIN-02A | AL12: 1075633
A13: 8 | B13: 46142 | C13: Dry Rcn | D13: BIN-013 | E13: ANA-01 | F13: Running | G13: 1013 | H13: 43.38 | I13: 161 | J13: 232 | K13: 9.5 | L13: 10 | M13: 18 | N13: 28 | O13: 2 | P13: 18 | Q13: 687 | R13: 37582 | S13: 585 | T13: 618 | U13: =289/458 -> 0.63100437 | V13: 401.7 | W13: 27 | X13: =Y13/W13 -> 73.69 | Y13: =27*73.69 -> 1989.63 | AA13: 44038 | AB13: =AA13-V13 -> 43636.3 | AC13: 46142 | AD13: =44024.5 -> 44024.5 | AF13: =AD13-AB13 -> 388.2 | AH13: =AF13+AB13 -> 44024.5 | AK13: BIN-02B | AL13: 873962.9
A14: 9 | B14: 46147 | C14: Dry Rcn | D14: BIN-013 | E14: ANA-01 | F14: Running | G14: 1006 | H14: 43.03 | I14: 188 | J14: 227 | K14: 8.5 | L14: 17 | M14: 17 | N14: 28 | O14: 0 | P14: 21 | Q14: 684 | R14: 66919 | S14: 547 | T14: 547 | U14: =0.65 -> 0.65 | V14: =T14*U14 -> 355.55 | W14: 22 | X14: =Y14/W14 -> 72.940909 | Y14: 1604.7 | AA14: 40966 | AB14: =AA14-V14 -> 40610.45 | AC14: 46147 | AD14: =42570.3-1604.7-355.55 -> 40610.05 | AF14: =AB14-AD14 -> 0.4 | AH14: =AF14+AD14 -> 40610.45 | AK14: BIN-03B | AL14: 2687555.6
A15: 10 | B15: 46147 | C15: Dry Rcn | D15: BIN-013 | E15: ANA-01 | F15: Running | G15: 1007 | H15: 42.32 | I15: 199 | J15: 228 | K15: 9.7 | L15: 12 | M15: 12 | N15: 46 | O15: 4 | P15: 26 | Q15: 667 | R15: 35051 | S15: 643 | T15: 644 | U15: 0.65 | V15: =T15*U15 -> 418.6 | W15: 28 | X15: =Y15/W15 -> 75.421429 | Y15: =2111.8 -> 2111.8 | AA15: 47959 | AB15: =AA15-V15 -> 47540.4 | AC15: 46147 | AD15: =47464 -> 47464 | AF15: =AB15-AD15 -> 76.4 | AH15: =AF15+AD15 -> 47540.4 | AK15: BIN-05 | AL15: 847581.45
A16: 11 | B16: 46148 | C16: Dry Rcn | D16: BIN-013 | E16: ANA-01 | F16: Running | G16: 1008 | H16: 43.21 | I16: 164 | J16: 230 | K16: 10.4 | L16: 12 | M16: 18 | N16: 20 | O16: 4 | P16: 36 | Q16: 675 | R16: 14643 | S16: 537 | T16: 537 | U16: 0.65 | V16: =T16*U16 -> 349.05 | W16: 22 | X16: =Y16/W16 -> 71.640909 | Y16: 1576.1 | AA16: 38952 | AB16: =AA16-V16 -> 38602.95 | AC16: 46148 | AD16: =40137.1-Y16-V16 -> 38211.95 | AF16: =AB16-AD16 -> 391 | AH16: =AF16+AD16 -> 38602.95 | AK16: BKE-001-DRY | AL16: 49307.45
A17: 12 | B17: 46148 | C17: Dry Rcn | D17: BIN-013 | E17: ANA-01 | F17: Running | G17: 1009 | H17: 42.32 | I17: 183 | J17: 227 | K17: 9.6 | L17: 10 | M17: 16 | N17: 49 | O17: 0 | P17: 17 | Q17: 675 | R17: 773 | S17: 572 | T17: 572 | U17: 0.65 | V17: =T17*U17 -> 371.8 | W17: 23 | X17: =Y17/W17 -> 73.095652 | Y17: 1681.2 | AA17: 42344 | AB17: =AA17-V17 -> 41972.2 | AC17: 46148 | AD17: =41541 -> 41541 | AF17: =AB17-AD17 -> 431.2 | AH17: =AF17+AD17 -> 41972.2 | AK17: Grand Total | AL17: 8244996.6
A18: 13 | B18: 46151 | C18: Dry Rcn | D18: BIN-013 | E18: ANA-01 | F18: Running | G18: 1011 | H18: 42.5 | I18: 174 | J18: 225 | K18: 8.9 | L18: 14 | M18: 18 | N18: 41 | O18: 0 | P18: 13 | Q18: 684 | R18: 82154 | S18: 584 | T18: 585 | U18: 0.65 | V18: =0.65*T18 -> 380.25 | W18: 25 | X18: =Y18/W18 -> 67.2 | Y18: 1680 | AA18: =44445 -> 44445 | AB18: =AA18-V18 -> 44064.75 | AC18: 46151 | AD18: =43454 -> 43454 | AF18: =AB18-AD18 -> 610.75 | AH18: =AF18+AD18 -> 44064.75
A19: 14 | B19: 46153 | C19: Dry Rcn | D19: BKE-001-DRY | E19: ANA-01 | F19: Closed | G19: 1012 | H19: 42.76 | I19: 176 | J19: 228 | K19: 8.9 | L19: 16 | M19: 13 | N19: 22 | O19: 2 | P19: 30 | Q19: 684 | R19: 82770 | S19: 667 | T19: 667 | U19: 0.65 | V19: =0.65*667 -> 433.55 | W19: 25 | X19: =Y19/W19 -> 71.316 | Y19: 1782.9 | AA19: =49741 -> 49741 | AB19: =49741-V19 -> 49307.45 | AC19: 46153 | AD19: =49355 -> 49355 | AF19: =AD19-AB19 -> 47.55 | AH19: =AF19+AB19 -> 49355
A20: 15 | B20: 46154 | C20: Dry Rcn | D20: BIN-03B | E20: ANA-01 | F20: Running | G20: 1015 | H20: 43.47 | I20: 172 | J20: 230 | K20: 8.7 | L20: 12 | M20: 21 | N20: 32 | O20: 4 | P20: 9 | Q20: 688 | R20: BIN-03B | S20: 605 | T20: 605 | U20: 0.65 | V20: =U20*S20 -> 393.25 | W20: 25 | X20: =Y20/W20 -> 72 | Y20: 1800 | AA20: 46136 | AB20: =46136-V20 -> 45742.75 | AC20: 46154 | AD20: =45333 -> 45333 | AF20: =AB20-AD20 -> 409.75 | AH20: =AF20+AD20 -> 45742.75
A21: 16 | B21: 46155 | C21: Dry Rcn | D21: BIN-03B | E21: ANA-01 | F21: Running | G21: 1014 | H21: 42.15 | I21: 177 | J21: 223 | K21: 8.5 | L21: 11 | M21: 21 | N21: 40 | O21: 0 | P21: 30 | Q21: 671 | R21: BIN-03B | S21: 575 | T21: 575 | U21: 0.65 | V21: =U21*S21 -> 373.75 | W21: 24 | X21: =Y21/W21 -> 73.791667 | Y21: 1771 | AA21: 43873 | AB21: =AA21-V21 -> 43499.25 | AC21: 46157 | AD21: 43110 | AF21: =AB21-AD21 -> 389.25 | AH21: =AF21+AD21 -> 43499.25
A22: 17 | B22: 46157 | C22: Dry Rcn | D22: BIN-03B | E22: ANA-01 | F22: Running | G22: 1016 | H22: 43.47 | I22: 172 | J22: 230 | K22: 8.7 | L22: 12 | M22: 21 | N22: 32 | O22: 4 | P22: 9 | Q22: 688 | R22: BIN-03B | S22: 638 | T22: 638 | U22: 0.65 | V22: =U22*S22 -> 414.7 | W22: 27 | X22: =Y22/W22 -> 73 | Y22: 1971 | AA22: 48908 | AB22: =AA22-V22 -> 48493.3 | AC22: 46160 | AD22: 48024 | AF22: =AB22-AD22 -> 469.3 | AH22: =AF22+AD22 -> 48493.3
A23: 18 | B23: 46160 | C23: Dry Rcn | D23: BIN-013 | E23: ANA-01 | F23: Running | G23: 1018 | H23: 43.47 | I23: 173 | J23: 233 | K23: 8.5 | L23: 16 | M23: 11 | N23: 35 | O23: 0 | P23: 22 | Q23: 678 | R23: 31510 | S23: 566 | T23: 566 | U23: =V23/T23 -> 0.65017668 | V23: 368 | W23: 24 | X23: =Y23/W23 -> 72 | Y23: 1728 | AA23: 42581 | AB23: =AA23-V23 -> 42213 | AC23: 46162 | AD23: 41773 | AF23: =AB23-AD23 -> 440 | AH23: =AF23+AD23 -> 42213
A24: 19 | B24: 46161 | C24: Dry Rcn | D24: BIN-03B | E24: ANA-01 | F24: Running | G24: 1019 | H24: 42.06 | I24: 172 | J24: 225 | K24: 8.5 | L24: 14 | M24: 13 | N24: 41 | O24: 0 | P24: 26 | Q24: 676 | R24: BIN-03B | S24: 1322 | T24: 1323 | U24: =V24/T24 -> 0.65003779 | V24: 860 | W24: 55 | X24: =Y24/W24 -> 72.454545 | Y24: 3985 | AA24: 99494 | AB24: =AA24-V24 -> 98634 | AC24: 46164 | AD24: =97586 -> 97586 | AF24: =AB24-AD24 -> 1048 | AH24: =AF24+AD24 -> 98634
A25: 20 | B25: 46168 | C25: Dry Rcn | D25: BIN-03B | E25: ANA-01 | F25: Running | G25: 1020 | H25: 42.76 | I25: 172 | J25: 230 | K25: 8.8 | L25: 11 | M25: 14 | N25: 40 | O25: 0 | P25: 13 | Q25: 687 | R25: BIN-03B | S25: 535 | T25: 535 | U25: 0.65 | V25: =U25*S25 -> 347.75 | W25: 22 | X25: =Y25/W25 -> 72.272727 | Y25: 1590 | AA25: 39919 | AB25: =AA25-V25 -> 39571.25 | AC25: 46168 | AD25: =39269 -> 39269 | AF25: =AB25-AD25 -> 302.25 | AH25: =AF25+AD25 -> 39571.25
A26: 21 | B26: 46170 | C26: Dry Rcn | D26: BIN-03B | E26: ANA-01 | F26: Running | G26: 1022 | H26: 42.5 | I26: 175 | J26: 223 | K26: 8.7 | L26: 17 | M26: 19 | N26: 36 | O26: 0 | P26: 41 | Q26: 659 | R26: BIN-03B | S26: 414 | T26: 414 | U26: =0.65 -> 0.65 | V26: =U26*S26 -> 269.1 | W26: 19 | X26: =Y26/W26 -> 73.368421 | Y26: 1394 | AA26: 30903 | AB26: =AA26-V26 -> 30633.9 | AC26: 46170 | AD26: 30377 | AF26: =AB26-AD26 -> 256.9 | AH26: =AF26+AD26 -> 30633.9
A27: 22 | B27: 46170 | C27: Dry Rcn | D27: BIN-03B | E27: ANA-01 | F27: Running | G27: 1021 | H27: 42.59 | I27: 171 | J27: 227 | K27: 8.8 | L27: 19 | M27: 10 | N27: 30 | O27: 0 | P27: 36 | Q27: 670 | R27: BIN-03B | S27: 998 | T27: 1001 | U27: 0.65 | V27: =U27*S27 -> 648.7 | W27: 40 | X27: =2902/40 -> 72.55 | Y27: 2902 | AA27: 74281 | AB27: =AA27-V27 -> 73632.3 | AC27: 46170 | AD27: =73630 -> 73630 | AF27: =AB27-AD27 -> 2.3 | AH27: =AF27+AD27 -> 73632.3
A28: 23 | B28: 46171 | C28: Dry Rcn | D28: BIN-03B | E28: ANA-01 | F28: Running | G28: 1023 | H28: 42.41 | I28: 174 | J28: 226 | K28: 8.8 | L28: 14 | M28: 15 | N28: 37 | O28: 0 | P28: 32 | Q28: 671 | R28: BIN-03B | S28: 645 | T28: 649 | U28: 0.65 | V28: =U28*T28 -> 421.85 | W28: 27 | X28: =Y28/W28 -> 72.814815 | Y28: 1966 | AA28: 47982 | AB28: =AA28-V28 -> 47560.15 | AC28: 46171 | AD28: 47061.6 | AF28: =AB28-AD28 -> 498.55 | AH28: =AF28+AD28 -> 47560.15
A29: 24 | B29: 46175 | C29: Dry Rcn | D29: BIN-03B | E29: ANA-01 | F29: Running | G29: 1026 | H29: 42.53 | I29: 177 | J29: 217 | K29: 8.3 | L29: 17 | M29: 20 | N29: 40 | O29: 2 | P29: 35 | Q29: 665 | R29: BIN-03B | S29: 890 | T29: 890 | U29: 0.65 | V29: =T29*U29 -> 578.5 | W29: 37 | X29: =Y29/W29 -> 72.054054 | Y29: 2666 | AA29: 66342 | AB29: =AA29-V29 -> 65763.5 | AC29: 46175 | AD29: 65116 | AF29: =AB29-AD29 -> 647.5 | AH29: =AF29+AD29 -> 65763.5
A30: 0 | B30: 46175 | C30: Dry Rcn | D30: 0 | G30: 1024 | H30: 41.09 | I30: 183 | J30: 220 | K30: 8.9 | L30: 12 | M30: 14 | N30: 49 | O30: 0 | P30: 17 | Q30: 682 | R30: 87036 | S30: 0 | T30: 0 | U30: 0.65 | V30: =T30*U30 -> 0 | W30: 31 | X30: =Y30/W30 -> 71.451613 | Y30: 2215 | AA30: 0 | AB30: 0 | AC30: 46175 | AD30: 0 | AF30: 0 | AG30: Lot returned due to start higer KOR calibration/Staked in Calibration Area/Date of retur of CARGO-3/06/2026. (54.663)
A31: 25 | B31: 46178 | C31: Dry Rcn | D31: BIN-001 | E31: ANA-02-DRY | F31: Closed | G31: 1027 | H31: 44.09 | I31: 176 | J31: 232 | K31: 8.8 | L31: 16 | M31: 20 | N31: 21 | O31: 0 | P31: 20 | Q31: 684 | R31: ANA-02-DRY | S31: 810 | T31: 805 | U31: 0.65 | V31: 526 | W31: 27 | X31: =Y31/W31 -> 70.111111 | Y31: 1893 | AA31: 60031 | AB31: =AA31-V31 -> 59505 | AC31: 46178 | AD31: 58913.9 | AF31: =AB31-AD31 -> 591.1 | AH31: =AF31+AD31 -> 59505
A32: 26 | B32: 46179 | C32: Dry Rcn | D32: BIN-001 | E32: ANA-02-DRY | F32: Closed | G32: 1028 | H32: 45.41 | I32: 187 | J32: 240 | K32: 7.6 | L32: 18 | M32: 17 | N32: 15 | O32: 3 | P32: 32 | Q32: 669 | R32: ANA-02-DRY | S32: 1201 | T32: 1201 | U32: =780/1201 -> 0.64945878 | V32: 780 | W32: 40 | X32: =Y32/40 -> 69.275 | Y32: 2771 | AA32: 89375 | AB32: =AA32-V32 -> 88595 | AC32: 46179 | AD32: 88081 | AF32: =AB32-AD32 -> 514 | AH32: =AF32+AD32 -> 88595
A33: 27 | B33: 46179 | C33: Dry Rcn | D33: BIN-001 | E33: ANA-02-DRY | F33: Closed | G33: 1029 | H33: 45.41 | I33: 187 | J33: 241 | K33: 8.8 | L33: 13 | M33: 20 | N33: 23 | O33: 0 | P33: 11 | Q33: 685 | R33: ANA-02-DRY | S33: 746 | T33: 745 | U33: =V33/T33 -> 0.64966443 | V33: 484 | W33: 25 | X33: =Y33/25 -> 72.64 | Y33: 1816 | AA33: 55159 | AB33: =AA33-V33 -> 54675 | AC33: 46179 | AD33: 54456 | AF33: =AB33-AD33 -> 219 | AH33: =AF33+AD33 -> 54675
A34: 28 | B34: 46180 | C34: Dry Rcn | D34: BIN-001 | E34: ANA-02-DRY | F34: Closed | G34: 1030 | H34: 43.82 | I34: 184 | J34: 231 | K34: 91 | L34: 15 | M34: 20 | N34: 27 | O34: 0 | P34: 33 | Q34: 675 | R34: ANA-02-DRY | S34: 1230 | T34: 1234 | U34: 0.65 | V34: 800 | W34: 41 | X34: =Y34/W34 -> 70.487805 | Y34: 2890 | AA34: 89158.5 | AB34: 88358.5 | AC34: 46180 | AD34: 87867.85 | AF34: =AB34-AD34 -> 490.65 | AH34: =AF34+AD34 -> 88358.5
A35: 29 | B35: 46182 | C35: Dry Rcn | D35: BIN-001 | E35: ANA-02-DRY | F35: Closed | G35: 1031 | H35: 44.44 | I35: 188 | J35: 241 | K35: 8.5 | L35: 13 | M35: 9 | N35: 28 | O35: 2 | P35: 23 | Q35: 677 | R35: ANA-02-DRY | S35: 1318 | T35: 1318 | U35: 0.65 | V35: =T35*U35 -> 856.7 | W35: 44 | X35: =Y35/44 -> 71.613636 | Y35: 3151 | AA35: 94315 | AB35: =AA35-V35 -> 93458.3 | AC35: 46182 | AD35: 92903 | AF35: =AB35-AD35 -> 555.3 | AH35: =AF35+AD35 -> 93458.3
A36: 30 | B36: 46182 | C36: Dry Rcn | D36: BIN-001 | E36: ANA-02-DRY | F36: Closed | G36: 1032 | H36: 43.65 | I36: 184 | J36: 235 | K36: 8.1 | L36: 10 | M36: 15 | N36: 27 | O36: 0 | P36: 27 | Q36: 679 | R36: ANA-02-DRY | S36: 1104 | T36: =721+360 -> 1081 | U36: 0.65 | V36: =T36*U36 -> 702.65 | W36: 36 | X36: =Y36/W36 -> 71.472222 | Y36: 2573 | AA36: 77198 | AB36: =AA36-V36 -> 76495.35 | AC36: 46182 | AD36: 75770.1 | AF36: =AB36-AD36 -> 725.25 | AH36: =AF36+AD36 -> 76495.35
A37: 31 | B37: 46183 | C37: Dry Rcn | D37: BIN-001 | E37: ANA-02-DRY | F37: Closed | G37: 1033 | H37: 45.06 | I37: 186 | J37: 238 | K37: 8.1 | L37: 20 | M37: 15 | N37: 18 | O37: 1 | P37: 28 | Q37: 675 | R37: ANA-02-DRY | S37: 1108 | T37: 1108 | U37: 0.65 | V37: =T37*0.65 -> 720.2 | W37: 37 | X37: =Y37/37 -> 72.264865 | Y37: 2673.8 | AA37: 78781 | AB37: =AA37-V37 -> 78060.8 | AC37: 46183 | AD37: =78060 -> 78060 | AG37: Net wt yet pending from Calibrataion | AH37: =AF37+AD37 -> 78060
A38: 32 | B38: 46184 | C38: Dry Rcn | D38: BIN-05 | E38: ANA-05A-DRY | F38: Closed | G38: 1034 | H38: 48.41 | I38: 185 | J38: 258 | K38: 7.4 | L38: 22 | M38: 11 | N38: 14 | O38: 0 | P38: 6 | Q38: 679 | R38: ANA-05A-DRY | S38: 591 | T38: 591 | U38: 0.65 | V38: =T38*U38 -> 384.15 | W38: 24 | X38: =Y38/W38 -> 73.666667 | Y38: 1768 | AA38: 43436 | AB38: =AA38-V38 -> 43051.85 | AC38: 46184 | AD38: 42945.65 | AF38: =AB38-AD38 -> 106.2 | AH38: =AF38+AD38 -> 43051.85
A39: 33 | B39: 46184 | C39: Dry Rcn | D39: BIN-05 | E39: ANA-05A-DRY | F39: Closed | G39: 1035 | H39: 45.06 | I39: 188 | J39: 240 | K39: 7.1 | L39: 23 | M39: 16 | N39: 21 | O39: 4 | P39: 15 | Q39: 665 | R39: ANA-05A-DRY | S39: 867 | T39: 867 | U39: =0.65 -> 0.65 | V39: =U39*T39 -> 563.55 | W39: 36 | X39: =Y39/W39 -> 72.927778 | Y39: 2625.4 | AA39: 61930 | AB39: 61366.55 | AC39: 46184 | AD39: 61179 | AF39: =AB39-AD39 -> 187.55 | AH39: =AF39+AD39 -> 61366.55
A40: 34 | B40: 46185 | C40: Dry Rcn | D40: BIN-05 | E40: ANA-05A-DRY | F40: Closed | G40: 1036 | H40: 44.88 | I40: 185 | J40: 236 | K40: 7.5 | L40: 18 | M40: 19 | N40: 27 | O40: 0 | P40: 16 | Q40: 671 | R40: ANA-05A-DRY | S40: 884 | T40: 884 | U40: 0.65 | V40: =T40*U40 -> 574.6 | W40: 38 | X40: =Y40/38 -> 69.692105 | Y40: 2648.3 | AA40: 65368 | AB40: =AA40-V40 -> 64793.4 | AC40: 46185 | AD40: =64571.4 -> 64571.4 | AF40: =AB40-AD40 -> 222 | AH40: =AF40+AD40 -> 64793.4
A41: 35 | B41: 46186 | C41: Dry Rcn | D41: BIN-05 | E41: ANA-05A-DRY | F41: Closed | G41: 1037 | H41: 44.62 | I41: 184 | J41: 234 | K41: 7.3 | L41: 18 | M41: 20 | N41: 23 | O41: 0 | P41: 33 | Q41: 663 | R41: ANA-05A-DRY | S41: 966 | T41: 966 | U41: 0.65 | V41: =T41*U41 -> 627.9 | Y41: 2853 | AA41: 70726 | AB41: =AA41-V41 -> 70098.1 | AC41: 46186 | AD41: 70098.1 | AG41: Net wt yet pending from Calibrataion | AH41: =AF41+AD41 -> 70098.1
A42: 36 | B42: 46188 | C42: Dry Rcn | D42: BIN-05 | E42: ANA-05A-DRY | F42: Closed | G42: 1038 | H42: 44 | I42: 186 | J42: 233 | K42: 7.6 | L42: 17 | M42: 16 | N42: 28 | O42: 2 | P42: 22 | Q42: 676 | R42: ANA-05A-DRY | S42: 1325 | T42: 1325 | U42: 0.65 | V42: =T42*U42 -> 861.25 | AA42: 97807 | AB42: =AA42-V42 -> 96945.75 | AC42: 46188 | AD42: 96945.75 | AH42: =AF42+AD42 -> 96945.75
A43: 37 | B43: 46189 | C43: Dry Rcn | D43: BIN-05 | E43: ANA-05A-DRY | F43: Closed | G43: 1039 | H43: 44.7 | I43: 186 | J43: 240 | K43: 7.1 | L43: 15 | M43: 12 | N43: 25 | O43: 3 | P43: 22 | Q43: 672 | R43: ANA-05A-DRY | S43: 1428 | T43: 1428 | U43: 0.65 | V43: =T43*U43 -> 928.2 | W43: 60 | Y43: 4281.8 | AA43: 101669 | AB43: =AA43-V43 -> 100740.8 | AC43: 46189 | AD43: =AB43 -> 100740.8 | AH43: =AF43+AD43 -> 100740.8
...
