Workbook

Sheet LBA-2026
A2: SI NO | B2: Supplier Name (LBA) | C2: Supplier Code LBA)
A3: 1 | B3: RCN ADAM IVOIRE | C3: DIS-031-ADA
A4: 2 | B4: RCN AGRICAS IVOIRE | C4: LBA-023-AGR
A5: 3 | B5: RCN ALFCOUL GROUP | C5: DIS-028-ALF
A6: 4 | B6: RCN BROUMA SARL | C6: DIS-041-BRO
A7: 5 | B7: RCN CADEPO COOP CA | C7: DIS-024-CAD
A8: 6 | B8: RCN CAPCD- SCOOPS | C8: LBA-010-CAP
A9: 7 | B9: RCN CASP-S SCOOPS | C9: LBA-007-CAS
A10: 8 | B10: RCN COOPCA TOE SEYDOU | C10: DIS-036-SEY
A11: 9 | B11: RCN COPJAVA SCOOP | C11: LBA -005-JAV
A12: 10 | B12: RCN CPAS SCOOPS | C12: DIS-029-CPA
A13: 11 | B13: RCN DAGNOGO KARIM | C13: LBA-013-DAG
A14: 12 | B14: RCN DECARRE DAVID & DJOUMAN | C14: DIS-019-DEC
... A60: 58 | B60: RCN SOVA SCOOPS | C60: DIS-005-SOV

Sheet RCN INWARD FACTORY YAKRO 2026
B1: Daily Report 2026 | G1: 2500 | H1: 32133 | S1: +Q:BC | AA1: =S2/1000 | AC1: =+SUBTOTAL(9,AC5:AC4274) -> 136077 | AD1: =+SUBTOTAL(9,AD5:AD4274) -> 2373 | AH1: =+SUBTOTAL(9,AH5:AH4274) -> 140243 | AI1: =+SUBTOTAL(9,AI5:AI4274) -> 0 | AJ1: =+SUBTOTAL(9,AJ5:AJ4274) -> 0 | AK1: =+SUBTOTAL(9,AK5:AK4274) -> 139741 | AL1: =+SUBTOTAL(9,AL5:AL4274) -> 140454 | AM1: =+SUBTOTAL(9,AM5:AM4274) -> 11390255 | AN1: =+SUBTOTAL(9,AN5:AN4274) -> 175409 | AO1: =+SUBTOTAL(9,AO5:AO4274) -> 11249945 | ... AR1: =+SUBTOTAL(9,AR5:AR4274) -> 35984 | AT1: 2500 | AV1: Qualit Report - View-1 | BM1: Qualit Report - View-2 | CC1: SUMPRODUCT(AR5:AR5076,$Y5:$Y5076/$Y$2)
W2: =SUM(W5:W92) -> 47143 | X2: =SUM(X5:X92) -> 3537 | Y2: =SUM(Y5:Y318) -> 140052 | Z2: =SUM(Z5:Z92) -> 4239 | AA2: =SUM(AA5:AA92) -> 51318 | AB2: =SUM(AB5:AB92) -> 4239 | AC2: =+SUBTOTAL(9,AC5:AC4275) -> 136077 | AD2: =+SUBTOTAL(9,AD5:AD4275) -> 2373 | AF2: =SUM(AF5:AF259) -> 8894 | AG2: =+SUBTOTAL(9,AG5:AG4275) -> 0 | AH2: =+SUBTOTAL(9,AH5:AH4275) -> 140243 | AI2: =+SUBTOTAL(9,AI5:AI4275) -> 0 | AJ2: =+SUBTOTAL(9,AJ5:AJ4275) -> 0 | AK2: =+SUBTOTAL(9,AK5:AK4275) -> 139741 | AL2: =+SUBTOTAL(9,AL5:AL4275) -> 140454 | AM2: =+SUBTOTAL(9,AM5:AM4275) -> 11390255 | AN2: =+SUBTOTAL(9,AN5:AN4275) -> 175409 | ... AP2: =+SUBTOTAL(9,AP5:AP4275) -> 11213323 | AQ2: =+SUBTOTAL(9,AQ5:AQ1187) -> 11212919 | AR2: =+SUBTOTAL(9,AR5:AR4275) -> 35984 | AS2: =+SUBTOTAL(9,AS5:AS4275) -> 11250203 | AV2: {=SUMPRODUCT(AV5:AV4284,$AO5:$AO4284/$AO$2)} -> 27.195206 | AW2: {=SUMPRODUCT(AW5:AW4284,$AO5:$AO4284/$AO$2)} -> 18.203954 | AX2: {=SUMPRODUCT(AX5:AX4284,$AO5:$AO4284/$AO$2)} -> 1.9633749 | AY2: {=SUMPRODUCT(AY5:AY4284,$AO5:$AO4284/$AO$2)} -> 47.362535 | AZ2: {=SUMPRODUCT(AZ5:AZ4284,$AO5:$AO4284/$AO$2)} -> 232.26518 | BA2: {=SUMPRODUCT(BA5:BA4284,$AO5:$AO4284/$AO$2)} -> 14.40345 | BB2: {=SUMPRODUCT(BB5:BB4284,$AO5:$AO4284/$AO$2)} -> 11.343039 | BC2: {=SUMPRODUCT(BC5:BC4259,$AO5:$AO4284/$AO$2)} -> #VALUE! | BD2: =+#REF!/AO2 -> #REF! | BF2: {=SUMPRODUCT(BF5:BF4259,$AO5:$AO4284/$AO$2)} -> #VALUE! | BG2: {=SUMPRODUCT(BG5:BG4284,$AO5:$AO4284/$AO$2)} -> 50.648216 | BJ2: {=SUMPRODUCT(BJ5:BJ4284,$AO5:$AO4284/$AO$2)} -> 10.598221 | BK2: {=SUMPRODUCT(BK5:BK4284,$AO5:$AO4284/$AO$2)} -> 179.5523 | BM2: {=SUMPRODUCT(BM5:BM4284,$AO5:$AO4284/$AO$2)} -> 28.460926 | BO2: {=SUMPRODUCT(BO5:BO4284,$AO5:$AO4284/$AO$2)} -> 19.165693 | BP2: {=SUMPRODUCT(BP5:BP4284,$AO5:$AO4284/$AO$2)} -> 2.0021016 | BQ2: {=SUMPRODUCT(BQ5:BQ4284,$AO5:$AO4284/$AO$2)} -> 49.628721 | BR2: {=SUMPRODUCT(BR5:BR4284,$AO5:$AO4284/$AO$2)} -> 235.90639 | BS2: {=SUMPRODUCT(BS5:BS4284,$AO5:$AO4284/$AO$2)} -> 15.199113 | BT2: {=SUMPRODUCT(BT5:BT4284,$AO5:$AO4284/$AO$2)} -> 11.713195 | BU2: {=SUMPRODUCT(BU5:BU4284,$AO5:$AO4284/$AO$2)} -> 262.81869 | BV2: =+#REF!/BD2 -> #REF! | BY2: {=SUMPRODUCT(BY5:BY4284,$AO5:$AO4284/$AO$2)} -> 46.353333 | BZ2: {=SUMPRODUCT(BZ5:BZ4284,$AO5:$AO4284/$AO$2)} -> 51.726097 | CC2: {=SUMPRODUCT(CC5:CC4284,$AO5:$AO4284/$AO$2)} -> 10.60898 | CD2: {=SUMPRODUCT(CD5:CD4284,$AO5:$AO4284/$AO$2)} -> 178.27604
A3: Delivery Information | V3: Bags Information | W3: Physical RCN Bag Stock | AC3: BAGS INFORMATION | AL3: OFFLLOADING | AV3: Detailed Quality Information/ (Sampling Report) | BM3: Detailed Quality Information/ (Final Offloading Report)
A4: S. No. | B4: Warehouse / Site | C4: Warehouse | D4: Lot No | E4: Lot Dry | F4: Bordereau De Livraison) | G4: W/H Receipt No. (F.De DISCHARGMENT) | H4: FITCH DATE | I4: Date | J4: ACTIVITY | K4: CCAK VALIDATED | L4: Storage Area | M4: No. Fiche CCA | N4: BIN NO. | O4: Truck No. | P4: Arrival Date | Q4: Discharge Date | R4: Origin | S4: Supplier Name | T4: Linked | U4: CCA NO | V4: Supplier's Code | W4: Good Bag Offloaded | X4: Damaged Bag Offloladed | Y4: Total Bag Discharged (Truck) | Z4: Recondition Bag | AA4: Total Bag Stock (WH) | AB4: New Bag (Used in Recondition) | AC4: Bon Sacs | AD4: Humid Sacs | AE4: Sacs déchirés | AF4: Recondition | AG4: Recon Sacs | AH4: Total Sacs/lot | AI4: sacs exports | AJ4: sacs bio | AK4: sacs brousses | AL4: Total Recd | AM4: GROSS WT | AN4: Total Refraction (On Gross Wt) | AO4: GRN qt(kg) | AP4: Weight Paid | AQ4: Net Weight | AR4: Diff | AS4: NET WT AS PER BOOK | AT4: GRN FRESH qty(kg) | AU4: GRN dried qty(kg) | AV4: BROWNS/Rejection (gm) | AW4: VOIDS (gm) | AX4: OIL (gm) | AY4: TOT DEFECT | AZ4: Good Kernel (gm) | BA4: Immature (gm) | BB4: Spotted (gm) | BC4: TOT KERNELS gm | BD4: KOR | BE4: Murli | BF4: SHOT | BG4: FOT | BH4: Useful Kernels Yield % | BI4: Total Yield % | BJ4: Moisture | BK4: NC | BL4: Shell (gm) | BM4: BROWNS/Rejection (gm) (NUT) | BN4: MURLI(TOTAL %) | BO4: VOIDS (GM ) | BP4: OIL (g m) | BQ4: TOTAL DEFECT | BR4: Good Kernel (G M) | BS4: Immature (g m) | BT4: Spotted (g m) | BU4: TOT KERNELS (g m) | BV4: KOR- | BW4: Murli- | BX4: After Dry -KOR | BY4: SHOT- | BZ4: FOT- | CA4: Useful Kernels Yield %2 | CB4: Total Yield %- | CC4: Moisture- | CD4: NC- | CE4: Shell (gm)- | CF4: Remarks | CG4: Column3 | CH4: Aging
A5: 1 | B5: YAMOUSSOUKRO | C5: ANAGROCI-01 | D5: 1 | F5: 851 | H5: 25/02/2026 | K5: OK | L5: B3 | M5: 68687 | N5: BIN-03A | O5: 4379LL 02 | P5: 46079 | Q5: 46079 | R5: VAVOUA | S5: SCAAMT COOP CA | V5: LBA-002-SCA | W5: 621 | X5: 63 | Y5: =W5+X5 -> 684 | Z5: 75 | AA5: =W5+Z5 -> 696 | AB5: =Z5 -> 75 | AC5: 574 | AD5: 0 | AE5: 87 | AF5: 95 | AH5: =+AC5+AD5+AE5+AG5 -> 661 | AI5: 0 | AJ5: 0 | AK5: 696 | AL5: =+AI5+AJ5+AK5 -> 696 | AM5: 53380 | AN5: =(AD5*8)+(AE5*4)+(AG5*0)+(AH5*1) -> 1009 | AO5: =Table22[[#This Row],[GROSS WT]]-Table22[[#This Row],[Total Bag Stock (WH)]] -> 52684 | AP5: =Table22[[#This Row],[GRN qt(kg)]]-100 -> 52584 | AQ5: =+AO5-AE5*4 -> 52336 | AR5: =(AD5*40)+(AE5*4)+(AG5*0) -> 348 | AS5: =Table22[[#This Row],[GROSS WT]]-Table22[[#This Row],[Total Bag Discharged (Truck)]] -> 52696 | AT5: =+AO5 -> 52684 | AV5: 11.6 | AY5: =+AV5+AW5+AX5 -> 11.6 | AZ5: 257 | BB5: 11 | BC5: =+AZ5+BA5+BB5 -> 268 | BD5: =SUM(Table22[[#This Row],[Good Kernel (gm)]]+(Table22[[#This Row],[Immature (gm)]]+Table22[[#This Row],[Spotted (gm)]])/2)*0.176 -> 46.2 | BF5: =(AZ5+BA5+BB5)*0.17637 -> 47.26716 | BG5: =+((AX5+AV5+AZ5+BA5+BB5))*0.17637 -> 49.313052 | BH5: =SUM(Table22[[#This Row],[Good Kernel (gm)]:[Spotted (gm)]])/1000*100 -> 26.8 | BI5: =SUM(AV5,AX5,AZ5:BB5)/1000*100 -> 27.96 | BJ5: 8 | BK5: 187 | BM5: 18 | BN5: 0.066 | BO5: 5 | BP5: 13 | BQ5: =+BM5+BO5+BP5 -> 36 | BR5: 253 | BS5: 16 | BT5: 10 | BU5: 279 | BV5: =SUM(Table22[[#This Row],[Good Kernel (G M)]]+(Table22[[#This Row],[Immature (g m)]]+Table22[[#This Row],[Spotted (g m)]])/2)*0.176 -> 46.816 | BW5: 46.81 | BY5: =(BR5+BS5+BT5)*0.17637 -> 49.20723 | BZ5: =+((BP5+BM5+BR5+BS5+BT5))*0.17637 -> 54.6747 | CA5: =SUM(Table22[[#This Row],[Good Kernel (G M)]:[Spotted (g m)]])/1000*100 -> 27.9 | CB5: =(Table22[[#This Row],[BROWNS/Rejection (gm) (NUT)]]+Table22[[#This Row],[OIL (g m)]]+Table22[[#This Row],[Good Kernel (G M)]]+Table22[[#This Row],[Immature (g m)]]+Table22[[#This Row],[Spotted (g m)]])/1000*100 -> 31 | CC5: 7.9 | CD5: 187 | CE5: 596 | CH5: =TODAY()-Table22[[#This Row],[Discharge Date]] -> 176
A6: 2 | B6: YAMOUSSOUKRO | C6: ANAGROCI-01 | D6: 2 | F6: 852 | H6: 25/02/2026 | K6: OK | L6: B3 | M6: 68684 | N6: BIN-001A | O6: 1367 LH 01 | P6: 46079 | Q6: 46079 | R6: VAVOUA | S6: SCAAMT COOP CA | V6: LBA-002-SCA | W6: 574 | X6: 87 | Y6: =W6+X6 -> 661 | Z6: 95 | AA6: =W6+Z6 -> 669 | AB6: =Z6 -> 95 | AC6: 621 | AD6: 0 | AE6: 63 | AF6: 75 | AH6: =+AC6+AD6+AE6+AG6 -> 684 | AI6: 0 | AJ6: 0 | AK6: 669 | AL6: =+AI6+AJ6+AK6 -> 669 | AM6: 49700 | AN6: =(AD6*40)+(AE6*4)+(AG6*0)+(AH6*1) -> 936 | AO6: =Table22[[#This Row],[GROSS WT]]-Table22[[#This Row],[Total Bag Stock (WH)]] -> 49031 | AP6: =Table22[[#This Row],[GRN qt(kg)]]-100 -> 48931 | AQ6: =+AO6-AE6*4 -> 48779 | AR6: =(AD6*40)+(AE6*4)+(AG6*0) -> 252 | AS6: =Table22[[#This Row],[GROSS WT]]-Table22[[#This Row],[Total Bag Discharged (Truck)]] -> 49039 | AT6: =+AO6 -> 49031 | AV6: 9.8 | AY6: =+AV6+AW6+AX6 -> 9.8 | AZ6: 274 | BB6: 3 | BC6: =+AZ6+BA6+BB6 -> 277 | BD6: =SUM(Table22[[#This Row],[Good Kernel (gm)]]+(Table22[[#This Row],[Immature (gm)]]+Table22[[#This Row],[Spotted (gm)]])/2)*0.176 -> 48.488 | BF6: =(AZ6+BA6+BB6)*0.17637 -> 48.85449 | BG6: =+((AX6+AV6+AZ6+BA6+BB6))*0.17637 -> 50.582916 | BH6: =SUM(Table22[[#This Row],[Good Kernel (gm)]:[Spotted (gm)]])/1000*100 -> 27.7 | BI6: =SUM(AV6,AX6,AZ6:BB6)/1000*100 -> 28.68 | BJ6: 7.9 | BK6: 197 | BM6: 18 | BN6: 0.094 | BO6: 5 | BP6: 13 | BQ6: =+BM6+BO6+BP6 -> 36 | BR6: 263 | BS6: 16 | BT6: 10 | BU6: =+BR6+BS6+BT6 -> 289 | BV6: =SUM(Table22[[#This Row],[Good Kernel (G M)]]+(Table22[[#This Row],[Immature (g m)]]+Table22[[#This Row],[Spotted (g m)]])/2)*0.176 -> 48.576 | BW6: 48.04 | BY6: =(BR6+BS6+BT6)*0.17637 -> 50.97093 | BZ6: =+((BP6+BM6+BR6+BS6+BT6))*0.17637 -> 56.4384 | CA6: =SUM(Table22[[#This Row],[Good Kernel (G M)]:[Spotted (g m)]])/1000*100 -> 28.9 | CB6: =(Table22[[#This Row],[BROWNS/Rejection (gm) (NUT)]]+Table22[[#This Row],[OIL (g m)]]+Table22[[#This Row],[Good Kernel (G M)]]+Table22[[#This Row],[Immature (g m)]]+Table22[[#This Row],[Spotted (g m)]])/1000*100 -> 32 | CC6: 7.8 | CD6: 193 | CE6: 631 | CH6: =TODAY()-Table22[[#This Row],[Discharge Date]] -> 176
A7: 3 | B7: YAMOUSSOUKRO | C7: ANAGROCI-01 | D7: 3 | F7: 853 | H7: 25/02/2026 | L7: B3 | M7: 77593 | N7: BIN-001A | O7: 2744 KK 02 | P7: 46080 | Q7: 46080 | R7: VAVOUA | S7: SCAAMT COOP CA | V7: LBA-002-SCA | W7: 480 | X7: 11 | Y7: =W7+X7 -> 491 | Z7: 19 | AA7: =W7+Z7 -> 499 | AB7: =Z7 -> 19 | AC7: 489 | AD7: 0 | AE7: 11 | AF7: 19 | AH7: =+AC7+AD7+AE7+AG7 -> 500 | AI7: 0 | AJ7: 0 | AK7: 499 | AL7: =+AI7+AJ7+AK7 -> 499 | AM7: 39180 | AN7: =(AD7*40)+(AE7*4)+(AG7*0)+(AH7*1) -> 544 | AO7: =Table22[[#This Row],[GROSS WT]]-Table22[[#This Row],[Total Bag Stock (WH)]] -> 38681 | AP7: =Table22[[#This Row],[GRN qt(kg)]]-40 -> 38641 | AQ7: =+AO7-AE7*4 -> 38637 | AR7: =(AD7*40)+(AE7*4)+(AG7*0) -> 44 | AS7: =Table22[[#This Row],[GROSS WT]]-Table22[[#This Row],[Total Bag Discharged (Truck)]] -> 38689 | AT7: =+AO7 -> 38681 | AV7: 6.2 | AW7: 2 | AY7: =+AV7+AW7+AX7 -> 8.2 | AZ7: 270 | BB7: 16 | BC7: =+AZ7+BA7+BB7 -> 286 | BD7: =SUM(Table22[[#This Row],[Good Kernel (gm)]]+(Table22[[#This Row],[Immature (gm)]]+Table22[[#This Row],[Spotted (gm)]])/2)*0.176 -> 48.928 | BE7: =48.92 -> 48.92 | BF7: =(AZ7+BA7+BB7)*0.17637 -> 50.44182 | BG7: =+((AX7+AV7+AZ7+BA7+BB7))*0.17637 -> 51.535314 | BH7: =SUM(Table22[[#This Row],[Good Kernel (gm)]:[Spotted (gm)]])/1000*100 -> 28.6 | BI7: =SUM(AV7,AX7,AZ7:BB7)/1000*100 -> 29.22 | BJ7: 8.5 | BK7: 188 | BL7: 626 | BM7: 18 | BN7: 0.07 | BO7: 5 | BP7: 8 | BQ7: =+BM7+BO7+BP7 -> 31 | BR7: 259 | BS7: 18 | BT7: 12 | BU7: =+BR7+BS7+BT7 -> 289 | BV7: =SUM(Table22[[#This Row],[Good Kernel (G M)]]+(Table22[[#This Row],[Immature (g m)]]+Table22[[#This Row],[Spotted (g m)]])/2)*0.176 -> 48.224 | BW7: 48.22 | BY7: =(BR7+BS7+BT7)*0.17637 -> 50.97093 | BZ7: =+((BP7+BM7+BR7+BS7+BT7))*0.17637 -> 55.55655 | CA7: =SUM(Table22[[#This Row],[Good Kernel (G M)]:[Spotted (g m)]])/1000*100 -> 28.9 | CB7: =(Table22[[#This Row],[BROWNS/Rejection (gm) (NUT)]]+Table22[[#This Row],[OIL (g m)]]+Table22[[#This Row],[Good Kernel (G M)]]+Table22[[#This Row],[Immature (g m)]]+Table22[[#This Row],[Spotted (g m)]])/1000*100 -> 31.5 | CC7: 7.8 | CD7: 187 | CE7: 622 | CH7: =TODAY()-Table22[[#This Row],[Discharge Date]] -> 175
A8: 4 | B8: YAMOUSSOUKRO | C8: ANAGROCI-01 | D8: 4 | F8: 854 | H8: 26/02/2026 | K8: OK | L8: B3 | M8: 77584 | N8: BIN-03A | O8: AA 335 NH 01 | P8: 46080 | Q8: 46080 | R8: VAVOUA | S8: COP JAVA SCOOP | V8: LBA-005-JAV | W8: 584 | X8: 35 | Y8: =W8+X8 -> 619 | Z8: 40 | AA8: =W8+Z8 -> 624 | AB8: =Z8 -> 40 | AC8: 604 | AD8: 0 | AE8: 20 | AF8: 40 | AH8: =+AC8+AD8+AE8+AG8 -> 624 | AI8: 0 | AJ8: 0 | AK8: 624 | AL8: =+AI8+AJ8+AK8 -> 624 | AM8: 46440 | AN8: =(AD8*40)+(AE8*4)+(AG8*0)+(AH8*1) -> 704 | AO8: =AM8-AH8 -> 45816 | AP8: =AM8-AN8 -> 45736 | AQ8: =+AO8-AE8*4 -> 45736 | AR8: =(AD8*40)+(AE8*4)+(AG8*0) -> 80 | AS8: =Table22[[#This Row],[GROSS WT]]-Table22[[#This Row],[Total Bag Discharged (Truck)]] -> 45821 | AT8: =+AO8 -> 45816 | AV8: 10.5 | AW8: 7 | AX8: 11 | AY8: =+AV8+AW8+AX8 -> 28.5 | AZ8: 257 | BA8: 8 | BB8: 10 | BC8: =+AZ8+BA8+BB8 -> 275 | BD8: =SUM(Table22[[#This Row],[Good Kernel (gm)]]+(Table22[[#This Row],[Immature (gm)]]+Table22[[#This Row],[Spotted (gm)]])/2)*0.176 -> 46.816 | BE8: 46.81 | BF8: =(AZ8+BA8+BB8)*0.17637 -> 48.50175 | BG8: =+((AX8+AV8+AZ8+BA8+BB8))*0.17637 -> 52.293705 | BH8: =SUM(Table22[[#This Row],[Good Kernel (gm)]:[Spotted (gm)]])/1000*100 -> 27.5 | BI8: =SUM(AV8,AX8,AZ8:BB8)/1000*100 -> 29.65 | BJ8: 9.2 | BK8: 191 | BL8: 596 | BM8: 13 | BN8: 0.069 | BO8: 21 | BP8: 20 | BQ8: =+BM8+BO8+BP8 -> 54 | BR8: 250 | BS8: 30 | BT8: 6 | BU8: =+BR8+BS8+BT8 -> 286 | BV8: =SUM(Table22[[#This Row],[Good Kernel (G M)]]+(Table22[[#This Row],[Immature (g m)]]+Table22[[#This Row],[Spotted (g m)]])/2)*0.176 -> 47.168 | BW8: 47.16 | BY8: =(BR8+BS8+BT8)*0.17637 -> 50.44182 | BZ8: =+((BP8+BM8+BR8+BS8+BT8))*0.17637 -> 56.26203 | CA8: =SUM(Table22[[#This Row],[Good Kernel (G M)]:[Spotted (g m)]])/1000*100 -> 28.6 | CB8: =(Table22[[#This Row],[BROWNS/Rejection (gm) (NUT)]]+Table22[[#This Row],[OIL (g m)]]+Table22[[#This Row],[Good Kernel (G M)]]+Table22[[#This Row],[Immature (g m)]]+Table22[[#This Row],[Spotted (g m)]])/1000*100 -> 31.9 | CC8: 8.6 | CD8: 187 | CE8: 598 | CH8: =TODAY()-Table22[[#This Row],[Discharge Date]] -> 175
A9: 5 | B9: YAMOUSSOUKRO | C9: ANAGROCI-01 | D9: 5 | F9: 855 | H9: 26/02/2026 | K9: OK | L9: B3 | M9: 77585 | N9: BIN-03A | O9: AA 114 NQ 02 | P9: 46080 | Q9: 46080 | R9: VAVOUA | S9: SOVA SCOOP | V9: DIS-005-SOV | W9: 617 | X9: 25 | Y9: =W9+X9 -> 642 | Z9: 41 | AA9: =W9+Z9 -> 658 | AB9: =Z9 -> 41 | AC9: 638 | AD9: 0 | AE9: 20 | AF9: 41 | AH9: =+AC9+AD9+AE9+AG9 -> 658 | AI9: 0 | AJ9: 0 | AK9: 658 | AL9: =+AI9+AJ9+AK9 -> 658 | AM9: 48800 | AN9: =(AD9*40)+(AE9*4)+(AG9*0)+(AH9*1) -> 738 | AO9: =AM9-AH9 -> 48142 | AP9: =AM9-AN9 -> 48062 | AQ9: =+AO9-AE9*4 -> 48062 | AR9: =(AD9*40)+(AE9*4)+(AG9*0) -> 80 | AS9: =Table22[[#This Row],[GROSS WT]]-Table22[[#This Row],[Total Bag Discharged (Truck)]] -> 48158 | AT9: =+AO9 -> 48142 | AV9: 7.8 | AW9: 4 | AX9: 16 | AY9: =+AV9+AW9+AX9 -> 27.8 | AZ9: 263 | BA9: 10 | BB9: 8 | BC9: =+AZ9+BA9+BB9 -> 281 | BD9: =SUM(Table22[[#This Row],[Good Kernel (gm)]]+(Table22[[#This Row],[Immature (gm)]]+Table22[[#This Row],[Spotted (gm)]])/2)*0.176 -> 47.872 | BE9: 47.87 | BF9: =(AZ9+BA9+BB9)*0.17637 -> 49.55997 | BG9: =+((AX9+AV9+AZ9+BA9+BB9))*0.17637 -> 53.757576 | BH9: =SUM(Table22[[#This Row],[Good Kernel (gm)]:[Spotted (gm)]])/1000*100 -> 28.1 | BI9: =SUM(AV9,AX9,AZ9:BB9)/1000*100 -> 30.48 | BJ9: 8 | BK9: 185 | BL9: 616 | BM9: 31 | BN9: 0.108 | BO9: 0 | BP9: 19 | BQ9: =+BM9+BO9+BP9 -> 50 | BR9: 253 | BS9: 26 | BT9: 6 | BU9: =+BR9+BS9+BT9 -> 285 | BV9: =SUM(Table22[[#This Row],[Good Kernel (G M)]]+(Table22[[#This Row],[Immature (g m)]]+Table22[[#This Row],[Spotted (g m)]])/2)*0.176 -> 47.344 | BW9: 47.34 | BY9: =(BR9+BS9+BT9)*0.17637 -> 50.26545 | BZ9: =+((BP9+BM9+BR9+BS9+BT9))*0.17637 -> 59.08395 | CA9: =SUM(Table22[[#This Row],[Good Kernel (G M)]:[Spotted (g m)]])/1000*100 -> 28.5 | CB9: =(Table22[[#This Row],[BROWNS/Rejection (gm) (NUT)]]+Table22[[#This Row],[OIL (g m)]]+Table22[[#This Row],[Good Kernel (G M)]]+Table22[[#This Row],[Immature (g m)]]+Table22[[#This Row],[Spotted (g m)]])/1000*100 -> 33.5 | CC9: 7.6 | CD9: 174 | CE9: 582 | CH9: =TODAY()-Table22[[#This Row],[Discharge Date]] -> 175
A10: 6 | B10: YAMOUSSOUKRO | C10: ANAGROCI-01 | D10: 6 | F10: 856 | H10: 25/02/2026 | K10: OK | L10: B3 | M10: 77591 | N10: BIN-03A | O10: 2319 LR 02 | P10: 46081 | Q10: 46081 | R10: VAVOUA | S10: SCAAMT COOP CA | V10: LBA-002-SCA | W10: 493 | X10: 35 | Y10: =W10+X10 -> 528 | Z10: 53 | AA10: =W10+Z10 -> 546 | AB10: =Z10 -> 53 | AC10: 531 | AD10: 0 | AE10: 15 | AF10: 53 | AH10: =+AC10+AD10+AE10+AG10 -> 546 | AI10: 0 | AJ10: 0 | AK10: 546 | AL10: =+AI10+AJ10+AK10 -> 546 | AM10: 39560 | AN10: =(AD10*40)+(AE10*4)+(AG10*0)+(AH10*1) -> 606 | AO10: =AM10-AH10 -> 39014 | AP10: =AM10-AN10 -> 38954 | AQ10: =+AO10-AE10*4 -> 38954 | AR10: =(AD10*40)+(AE10*4)+(AG10*0) -> 60 | AS10: =Table22[[#This Row],[GROSS WT]]-Table22[[#This Row],[Total Bag Discharged (Truck)]] -> 39032 | AT10: =+AO10 -> 39014 | AV10: 7.3 | AW10: 7 | AX10: 28 | AY10: =+AV10+AW10+AX10 -> 42.3 | AZ10: 251 | BA10: 14 | BB10: 8 | BC10: =+AZ10+BA10+BB10 -> 273 | BD10: =SUM(Table22[[#This Row],[Good Kernel (gm)]]+(Table22[[#This Row],[Immature (gm)]]+Table22[[#This Row],[Spotted (gm)]])/2)*0.176 -> 46.112 | BE10: 46.11 | BF10: =(AZ10+BA10+BB10)*0.17637 -> 48.14901 | BG10: =+((AX10+AV10+AZ10+BA10+BB10))*0.17637 -> 54.374871 | BH10: =SUM(Table22[[#This Row],[Good Kernel (gm)]:[Spotted (gm)]])/1000*100 -> 27.3 | BI10: =SUM(AV10,AX10,AZ10:BB10)/1000*100 -> 30.83 | BJ10: 8.3 | BK10: 181 | BL10: 612 | BM10: 26 | BN10: 0.1 | BO10: 16 | BP10: 23 | BQ10: =+BM10+BO10+BP10 -> 65 | BR10: 246 | BS10: 22 | BT10: 12 | BU10: =+BR10+BS10+BT10 -> 280 | BV10: =SUM(Table22[[#This Row],[Good Kernel (G M)]]+(Table22[[#This Row],[Immature (g m)]]+Table22[[#This Row],[Spotted (g m)]])/2)*0.176 -> 46.288 | BW10: 46.28 | BY10: =(BR10+BS10+BT10)*0.17637 -> 49.3836 | BZ10: =+((BP10+BM10+BR10+BS10+BT10))*0.17637 -> 58.02573 | CA10: =SUM(Table22[[#This Row],[Good Kernel (G M)]:[Spotted (g m)]])/1000*100 -> 28 | CB10: =(Table22[[#This Row],[BROWNS/Rejection (gm) (NUT)]]+Table22[[#This Row],[OIL (g m)]]+Table22[[#This Row],[Good Kernel (G M)]]+Table22[[#This Row],[Immature (g m)]]+Table22[[#This Row],[Spotted (g m)]])/1000*100 -> 32.9 | CC10: 7.8 | CD10: 185 | CE10: 575 | CH10: =TODAY()-Table22[[#This Row],[Discharge Date]] -> 174
A11: 7 | B11: YAMOUSSOUKRO | C11: ANAGROCI-01 | D11: 7 | F11: 857 | H11: 26/02/2026 | K11: OK | L11: B3 | M11: 72555 | N11: BIN-03A | O11: 285 LA 01 | P11: 46081 | Q11: 46081 | R11: VAVOUA | S11: COP JAVA SCOOP | V11: LBA-005-JAV | W11: 568 | X11: 9 | Y11: =W11+X11 -> 577 | Z11: 15 | AA11: =W11+Z11 -> 583 | AB11: =Z11 -> 15 | AC11: 573 | AD11: 0 | AE11: 10 | AF11: 15 | AH11: =+AC11+AD11+AE11+AG11 -> 583 | AI11: 0 | AJ11: 0 | AK11: 583 | AL11: =+AI11+AJ11+AK11 -> 583 | AM11: 42640 | AN11: =(AD11*40)+(AE11*4)+(AG11*0)+(AH11*1) -> 623 | AO11: =AM11-AH11 -> 42057 | AP11: =AM11-AN11 -> 42017 | AQ11: =+AO11-AE11*4 -> 42017 | AR11: =(AD11*40)+(AE11*4)+(AG11*0) -> 40 | AS11: =Table22[[#This Row],[GROSS WT]]-Table22[[#This Row],[Total Bag Discharged (Truck)]] -> 42063 | AT11: =+AO11 -> 42057 | AV11: 7.7 | AW11: 5 | AX11: 8 | AY11: =+AV11+AW11+AX11 -> 20.7 | AZ11: 257 | BA11: 10 | BB11: 13 | BC11: =+AZ11+BA11+BB11 -> 280 | BD11: =SUM(Table22[[#This Row],[Good Kernel (gm)]]+(Table22[[#This Row],[Immature (gm)]]+Table22[[#This Row],[Spotted (gm)]])/2)*0.176 -> 47.256 | BE11: 47.25 | BF11: =(AZ11+BA11+BB11)*0.17637 -> 49.3836 | BG11: =+((AX11+AV11+AZ11+BA11+BB11))*0.17637 -> 52.152609 | BH11: =SUM(Table22[[#This Row],[Good Kernel (gm)]:[Spotted (gm)]])/1000*100 -> 28 | BI11: =SUM(AV11,AX11,AZ11:BB11)/1000*100 -> 29.57 | BJ11: 8.8 | BK11: 176 | BL11: 623 | BM11: 19 | BN11: 0.077 | BO11: 0 | BP11: 11 | BQ11: =+BM11+BO11+BP11 -> 30 | BR11: 256 | BS11: 18 | BT11: 8 | BU11: =+BR11+BS11+BT11 -> 282 | BV11: =SUM(Table22[[#This Row],[Good Kernel (G M)]]+(Table22[[#This Row],[Immature (g m)]]+Table22[[#This Row],[Spotted (g m)]])/2)*0.176 -> 47.344 | BW11: 47.34 | BY11: =(BR11+BS11+BT11)*0.17637 -> 49.73634 | BZ11: =+((BP11+BM11+BR11+BS11+BT11))*0.17637 -> 55.02744 | CA11: =SUM(Table22[[#This Row],[Good Kernel (G M)]:[Spotted (g m)]])/1000*100 -> 28.2 | CB11: =(Table22[[#This Row],[BROWNS/Rejection (gm) (NUT)]]+Table22[[#This Row],[OIL (g m)]]+Table22[[#This Row],[Good Kernel (G M)]]+Table22[[#This Row],[Immature (g m)]]+Table22[[#This Row],[Spotted (g m)]])/1000*100 -> 31.2 | CC11: 8.4 | CD11: 181 | CE11: 607 | CH11: =TODAY()-Table22[[#This Row],[Discharge Date]] -> 174
A12: 8 | B12: YAMOUSSOUKRO | C12: ANAGROCI-01 | D12: 8 | F12: 858 | H12: 46084 | K12: OK | L12: B3 | M12: 77583 | N12: BIN-03A | O12: 285 LA 01 | P12: 46085 | Q12: 46085 | R12: VAVOUA | S12: COP JAVA SCOOP | V12: LBA-005-JAV | W12: 543 | X12: 41 | Y12: =W12+X12 -> 584 | Z12: 54 | AA12: =W12+Z12 -> 597 | AB12: =Z12 -> 54 | AC12: 564 | AD12: 0 | AE12: 20 | AF12: 54 | AH12: =+AC12+AD12+AE12+AG12 -> 584 | AI12: 0 | AJ12: 0 | AK12: 584 | AL12: =+AI12+AJ12+AK12 -> 584 | AM12: 45760 | AN12: =(AD12*40)+(AE12*4)+(AG12*0)+(AH12*1) -> 664 | AO12: =AM12-AH12 -> 45176 | AP12: =AM12-AN12 -> 45096 | AQ12: =+AO12-AE12*4 -> 45096 | AR12: =(AD12*40)+(AE12*4)+(AG12*0) -> 80 | AS12: =Table22[[#This Row],[GROSS WT]]-Table22[[#This Row],[Total Bag Discharged (Truck)]] -> 45176 | AT12: =+AO12 -> 45176 | AV12: 8.2 | AW12: 7 | AX12: 0 | AY12: =+AV12+AW12+AX12 -> 15.2 | AZ12: 239 | BA12: 36 | BB12: 6 | BC12: =+AZ12+BA12+BB12 -> 281 | BD12: =SUM(Table22[[#This Row],[Good Kernel (gm)]]+(Table22[[#This Row],[Immature (gm)]]+Table22[[#This Row],[Spotted (gm)]])/2)*0.176 -> 45.76 | BE12: 45.76 | BF12: =(AZ12+BA12+BB12)*0.17637 -> 49.55997 | BG12: =+((AX12+AV12+AZ12+BA12+BB12))*0.17637 -> 51.006204 | BH12: =SUM(Table22[[#This Row],[Good Kernel (gm)]:[Spotted (gm)]])/1000*100 -> 28.1 | BI12: =SUM(AV12,AX12,AZ12:BB12)/1000*100 -> 28.92 | BJ12: 8.7 | BK12: 181 | BL12: 624 | BM12: 29 | BN12: 0.098 | BO12: 8 | BP12: 20 | BQ12: =+BM12+BO12+BP12 -> 57 | BR12: 238 | BS12: 32 | BT12: 10 | BU12: =+BR12+BS12+BT12 -> 280 | BV12: =SUM(Table22[[#This Row],[Good Kernel (G M)]]+(Table22[[#This Row],[Immature (g m)]]+Table22[[#This Row],[Spotted (g m)]])/2)*0.176 -> 45.584 | BW12: 45.58 | BY12: =(BR12+BS12+BT12)*0.17637 -> 49.3836 | BZ12: =+((BP12+BM12+BR12+BS12+BT12))*0.17637 -> 58.02573 | CA12: =SUM(Table22[[#This Row],[Good Kernel (G M)]:[Spotted (g m)]])/1000*100 -> 28 | CB12: =(Table22[[#This Row],[BROWNS/Rejection (gm) (NUT)]]+Table22[[#This Row],[OIL (g m)]]+Table22[[#This Row],[Good Kernel (G M)]]+Table22[[#This Row],[Immature (g m)]]+Table22[[#This Row],[Spotted (g m)]])/1000*100 -> 32.9 | CC12: 9.1 | CD12: 187 | CE12: 604 | CH12: =TODAY()-Table22[[#This Row],[Discharge Date]] -> 170
A13: 9 | B13: YAMOUSSOUKRO | C13: ANAGROCI-01 | D13: 9 | F13: 859 | H13: 46084 | K13: OK | L13: B3 | M13: 77665 | N13: BIN-04A | O13: 2744 KK02 | P13: 46085 | Q13: 46085 | R13: VAVOUA | S13: SCAAMT COOP CA | V13: LBA-002-SCA | W13: 488 | X13: 100 | Y13: =W13+X13 -> 588 | Z13: 108 | AA13: =W13+Z13 -> 596 | AB13: =Z13 -> 108 | AC13: 473 | AD13: 0 | AE13: 15 | AF13: 108 | AH13: =+AC13+AD13+AE13+AG13 -> 488 | AI13: 0 | AJ13: 0 | AK13: 488 | AL13: =+AI13+AJ13+AK13 -> 488 | AM13: 42080 | AN13: =(AD13*40)+(AE13*4)+(AG13*0)+(AH13*1) -> 548 | AO13: =AM13-AH13 -> 41592 | AP13: =AM13-AN13 -> 41532 | AQ13: =+AO13-AE13*4 -> 41532 | AR13: =(AD13*40)+(AE13*4)+(AG13*0) -> 60 | AS13: =Table22[[#This Row],[GROSS WT]]-Table22[[#This Row],[Total Bag Discharged (Truck)]] -> 41492 | AT13: =+AO13 -> 41592 | AV13: 8.4 | AW13: 11 | AX13: 12 | AY13: =+AV13+AW13+AX13 -> 31.4 | AZ13: 245 | BA13: 24 | BB13: 4 | BC13: =+AZ13+BA13+BB13 -> 273 | BD13: =SUM(Table22[[#This Row],[Good Kernel (gm)]]+(Table22[[#This Row],[Immature (gm)]]+Table22[[#This Row],[Spotted (gm)]])/2)*0.176 -> 45.584 | BE13: 45.58 | BF13: =(AZ13+BA13+BB13)*0.17637 -> 48.14901 | BG13: =+((AX13+AV13+AZ13+BA13+BB13))*0.17637 -> 51.746958 | BH13: =SUM(Table22[[#This Row],[Good Kernel (gm)]:[Spotted (gm)]])/1000*100 -> 27.3 | BI13: =SUM(AV13,AX13,AZ13:BB13)/1000*100 -> 29.34 | BJ13: 9 | BK13: 180 | BL13: 614 | BM13: 24 | BN13: 0.082 | BO13: 14 | BP13: 15 | BQ13: =+BM13+BO13+BP13 -> 53 | BR13: 244 | BS13: 24 | BT13: 10 | BU13: =+BR13+BS13+BT13 -> 278 | BV13: =SUM(Table22[[#This Row],[Good Kernel (G M)]]+(Table22[[#This Row],[Immature (g m)]]+Table22[[#This Row],[Spotted (g m)]])/2)*0.176 -> 45.936 | BW13: 45.93 | BY13: =(BR13+BS13+BT13)*0.17637 -> 49.03086 | BZ13: =+((BP13+BM13+BR13+BS13+BT13))*0.17637 -> 55.90929 | CA13: =SUM(Table22[[#This Row],[Good Kernel (G M)]:[Spotted (g m)]])/1000*100 -> 27.8 | CB13: =(Table22[[#This Row],[BROWNS/Rejection (gm) (NUT)]]+Table22[[#This Row],[OIL (g m)]]+Table22[[#This Row],[Good Kernel (G M)]]+Table22[[#This Row],[Immature (g m)]]+Table22[[#This Row],[Spotted (g m)]])/1000*100 -> 31.7 | CC13: 8.8 | CD13: 189 | CE13: 605 | CH13: =TODAY()-Table22[[#This Row],[Discharge Date]] -> 170
A14: 10 | B14: YAMOUSSOUKRO | C14: ANAGROCI-01 | D14: 10 | F14: 860 | H14: 46115 | K14: OK | L14: B3 | M14: 77667 | N14: BIN-03A | O14: 2744 KK 02 | P14: 46085 | Q14: 46087 | R14: VAVOUA | S14: SCAAMT COOP CA | V14: LBA-002-SCA | W14: 512 | X14: 39 | Y14: =W14+X14 -> 551 | Z14: 37 | AA14: =W14+Z14 -> 549 | AB14: =Z14 -> 37 | AC14: 536 | AD14: 0 | AE14: 15 | AF14: 37 | AH14: =+AC14+AD14+AE14+AG14 -> 551 | AI14: 0 | AJ14: 0 | AK14: 551 | AL14: =+AI14+AJ14+AK14 -> 551 | AM14: 42220 | AN14: =(AD14*40)+(AE14*4)+(AG14*0)+(AH14*1) -> 611 | AO14: =AM14-AH14 -> 41669 | AP14: =AM14-AN14 -> 41609 | AQ14: =+AO14-AE14*4 -> 41609 | AR14: =(AD14*40)+(AE14*4)+(AG14*0) -> 60 | AS14: =Table22[[#This Row],[GROSS WT]]-Table22[[#This Row],[Total Bag Discharged (Truck)]] -> 41669 | AT14: =+AO14 -> 41669 | AV14: 8.3 | AW14: 15 | AX14: 0 | AY14: =+AV14+AW14+AX14 -> 23.3 | AZ14: 243 | BA14: 26 | BB14: 8 | BC14: =+AZ14+BA14+BB14 -> 277 | BD14: =SUM(Table22[[#This Row],[Good Kernel (gm)]]+(Table22[[#This Row],[Immature (gm)]]+Table22[[#This Row],[Spotted (gm)]])/2)*0.176 -> 45.76 | BE14: 45.76 | BF14: =(AZ14+BA14+BB14)*0.17637 -> 48.85449 | BG14: =+((AX14+AV14+AZ14+BA14+BB14))*0.17637 -> 50.318361 | BH14: =SUM(Table22[[#This Row],[Good Kernel (gm)]:[Spotted (gm)]])/1000*100 -> 27.7 | BI14: =SUM(AV14,AX14,AZ14:BB14)/1000*100 -> 28.53 | BJ14: 8.9 | BK14: 179 | BL14: 620 | BM14: 31 | BN14: 0.098 | BO14: 12 | BP14: 0 | BQ14: =+BM14+BO14+BP14 -> 43 | BR14: 256 | BS14: 14 | BT14: 8 | BU14: =+BR14+BS14+BT14 -> 278 | BV14: =SUM(Table22[[#This Row],[Good Kernel (G M)]]+(Table22[[#This Row],[Immature (g m)]]+Table22[[#This Row],[Spotted (g m)]])/2)*0.176 -> 46.992 | BW14: 46.99 | BY14: =(BR14+BS14+BT14)*0.17637 -> 49.03086 | BZ14: =+((BP14+BM14+BR14+BS14+BT14))*0.17637 -> 54.49833 | CA14: =SUM(Table22[[#This Row],[Good Kernel (G M)]:[Spotted (g m)]])/1000*100 -> 27.8 | CB14: =(Table22[[#This Row],[BROWNS/Rejection (gm) (NUT)]]+Table22[[#This Row],[OIL (g m)]]+Table22[[#This Row],[Good Kernel (G M)]]+Table22[[#This Row],[Immature (g m)]]+Table22[[#This Row],[Spotted (g m)]])/1000*100 -> 30.9 | CC14: 8.6 | CD14: 184 | CE14: 606 | CH14: =TODAY()-Table22[[#This Row],[Discharge Date]] -> 168
A15: 11 | B15: YAMOUSSOUKRO | C15: ANAGROCI-01 | D15: 11 | F15: 861 | H15: 46115 | K15: OK | L15: B3 | M15: 77669 | N15: BIN-02A | O15: 7727 GR 01 | P15: 46087 | Q15: 46087 | R15: KOUNAHIRI | S15: RCN SOCOSAM | V15: DIS-011-SAM | W15: 354 | X15: 12 | Y15: =W15+X15 -> 366 | Z15: 23 | AA15: =W15+Z15 -> 377 | AB15: =Z15 -> 23 | AC15: 354 | AD15: 0 | AE15: 12 | AF15: 23 | AH15: =+AC15+AD15+AE15+AG15 -> 366 | AI15: 0 | AJ15: 0 | AK15: 366 | AL15: =+AI15+AJ15+AK15 -> 366 | AM15: 33020 | AN15: =(AD15*40)+(AE15*4)+(AG15*0)+(AH15*1) -> 414 | AO15: =AM15-AH15 -> 32654 | AP15: =AM15-AN15 -> 32606 | AQ15: =+AO15-AE15*4 -> 32606 | AR15: =(AD15*40)+(AE15*4)+(AG15*0) -> 48 | AS15: =Table22[[#This Row],[GROSS WT]]-Table22[[#This Row],[Total Bag Discharged (Truck)]] -> 32654 | AT15: =+AO15 -> 32654 | AV15: 9.1 | AW15: 5 | AX15: 16 | AY15: =+AV15+AW15+AX15 -> 30.1 | AZ15: 240 | BA15: 28 | BB15: 10 | BC15: =+AZ15+BA15+BB15 -> 278 | BD15: =SUM(Table22[[#This Row],[Good Kernel (gm)]]+(Table22[[#This Row],[Immature (gm)]]+Table22[[#This Row],[Spotted (gm)]])/2)*0.176 -> 45.584 | BE15: 45.58 | BF15: =(AZ15+BA15+BB15)*0.17637 -> 49.03086 | BG15: =+((AX15+AV15+AZ15+BA15+BB15))*0.17637 -> 53.457747 | BH15: =SUM(Table22[[#This Row],[Good Kernel (gm)]:[Spotted (gm)]])/1000*100 -> 27.8 | BI15: =SUM(AV15,AX15,AZ15:BB15)/1000*100 -> 30.31 | BJ15: 9.3 | BK15: 174 | BL15: 604 | BM15: 29 | BN15: 0.104 | BO15: 17 | BP15: 0 | BQ15: =+BM15+BO15+BP15 -> 46 | BR15: 245 | BS15: 20 | BT15: 4 | BU15: =+BR15+BS15+BT15 -> 269 | BV15: =SUM(Table22[[#This Row],[Good Kernel (G M)]]+(Table22[[#This Row],[Immature (g m)]]+Table22[[#This Row],[Spotted (g m)]])/2)*0.176 -> 45.232 | BW15: 45.23 | BY15: =(BR15+BS15+BT15)*0.17637 -> 47.44353 | BZ15: =+((BP15+BM15+BR15+BS15+BT15))*0.17637 -> 52.55826 | CA15: =SUM(Table22[[#This Row],[Good Kernel (G M)]:[Spotted (g m)]])/1000*100 -> 26.9 | CB15: =(Table22[[#This Row],[BROWNS/Rejection (gm) (NUT)]]+Table22[[#This Row],[OIL (g m)]]+Table22[[#This Row],[Good Kernel (G M)]]+Table22[[#This Row],[Immature (g m)]]+Table22[[#This Row],[Spotted (g m)]])/1000*100 -> 29.8 | CC15: 9.3 | CD15: 170 | CE15: 604 | CH15: =TODAY()-Table22[[#This Row],[Discharge Date]] -> 168
A16: 12 | B16: YAMOUSSOUKRO | C16: ANAGROCI-01 | D16: 12 | F16: 862 | H16: 46145 | K16: OK | L16: B3 | M16: 77582 | N16: BIN-03A | O16: 285 LA 01 | P16: 46087 | Q16: 46087 | R16: VAVOUA | S16: COP JAVA SCOOP | V16: LBA-005-JAV | W16: 505 | X16: 1 | Y16: =W16+X16 -> 506 | Z16: 2 | AA16: =W16+Z16 -> 507 | AB16: =Z16 -> 2 | AC16: 557 | AD16: 0 | AE16: 1 | AF16: 2 | AH16: =+AC16+AD16+AE16+AG16 -> 558 | AI16: 0 | AJ16: 0 | AK16: 558 | AL16: =+AI16+AJ16+AK16 -> 558 | AM16: 45960 | AN16: =(AD16*40)+(AE16*4)+(AG16*0)+(AH16*1) -> 562 | AO16: =AM16-AH16 -> 45402 | AP16: =AM16-AN16 -> 45398 | AQ16: =+AO16-AE16*4 -> 45398 | AR16: =(AD16*40)+(AE16*4)+(AG16*0) -> 4 | AS16: =Table22[[#This Row],[GROSS WT]]-Table22[[#This Row],[Total Bag Discharged (Truck)]] -> 45454 | AT16: =+AO16 -> 45402 | AV16: 8.9 | AW16: 0 | AX16: 8 | AY16: =+AV16+AW16+AX16 -> 16.9 | AZ16: 248 | BA16: 24 | BB16: 4 | BC16: =+AZ16+BA16+BB16 -> 276 | BD16: =SUM(Table22[[#This Row],[Good Kernel (gm)]]+(Table22[[#This Row],[Immature (gm)]]+Table22[[#This Row],[Spotted (gm)]])/2)*0.176 -> 46.112 | BE16: 46.11 | BF16: =(AZ16+BA16+BB16)*0.17637 -> 48.67812 | BG16: =+((AX16+AV16+AZ16+BA16+BB16))*0.17637 -> 51.658773 | BH16: =SUM(Table22[[#This Row],[Good Kernel (gm)]:[Spotted (gm)]])/1000*100 -> 27.6 | BI16: =SUM(AV16,AX16,AZ16:BB16)/1000*100 -> 29.29 | BJ16: 9 | BK16: 181 | BL16: 621 | BM16: 22 | BN16: 0.079 | BO16: 8 | BP16: 8 | BQ16: =+BM16+BO16+BP16 -> 38 | BR16: 254 | BS16: 20 | BT16: 7 | BU16: =+BR16+BS16+BT16 -> 281 | BV16: =SUM(Table22[[#This Row],[Good Kernel (G M)]]+(Table22[[#This Row],[Immature (g m)]]+Table22[[#This Row],[Spotted (g m)]])/2)*0.176 -> 47.08 | BW16: 47.08 | BY16: =(BR16+BS16+BT16)*0.17637 -> 49.55997 | BZ16: =+((BP16+BM16+BR16+BS16+BT16))*0.17637 -> 54.85107 | CA16: =SUM(Table22[[#This Row],[Good Kernel (G M)]:[Spotted (g m)]])/1000*100 -> 28.1 | CB16: =(Table22[[#This Row],[BROWNS/Rejection (gm) (NUT)]]+Table22[[#This Row],[OIL (g m)]]+Table22[[#This Row],[Good Kernel (G M)]]+Table22[[#This Row],[Immature (g m)]]+Table22[[#This Row],[Spotted (g m)]])/1000*100 -> 31.1 | CC16: 9 | CD16: 181 | CE16: 617 | CH16: =TODAY()-Table22[[#This Row],[Discharge Date]] -> 168
A17: 13 | B17: YAMOUSSOUKRO | C17: ANAGROCI-01 | D17: 13 | F17: 863 | H17: 27/02/2026 | K17: OK | L17: B3 | M17: 77588 | N17: BIN-02A | O17: 2319 LR 02 | P17: 46087 | Q17: 46087 | R17: VAVOUA | S17: SCAAMT COOP CA | V17: LBA-002-SCA | W17: 450 | X17: 107 | Y17: =W17+X17 -> 557 | Z17: 81 | AA17: =W17+Z17 -> 531 | AB17: =Z17 -> 81 | AC17: 542 | AD17: 0 | AE17: 15 | AF17: 81 | AH17: =+AC17+AD17+AE17+AG17 -> 557 | AI17: 0 | AJ17: 0 | AK17: 557 | AL17: =+AI17+AJ17+AK17 -> 557 | AM17: 40960 | AN17: =(AD17*40)+(AE17*4)+(AG17*0)+(AH17*1) -> 617 | AO17: =AM17-AH17 -> 40403 | AP17: =AM17-AN17 -> 40343 | AQ17: =+AO17-AE17*4 -> 40343 | AR17: =(AD17*40)+(AE17*4)+(AG17*0) -> 60 | AS17: =Table22[[#This Row],[GROSS WT]]-Table22[[#This Row],[Total Bag Discharged (Truck)]] -> 40403 | AT17: =+AO17 -> 40403 | AV17: 9.9 | AW17: 3 | AX17: 0 | AY17: =+AV17+AW17+AX17 -> 12.9 | AZ17: 240 | BA17: 28 | BB17: 10 | BC17: =+AZ17+BA17+BB17 -> 278 | BD17: =SUM(Table22[[#This Row],[Good Kernel (gm)]]+(Table22[[#This Row],[Immature (gm)]]+Table22[[#This Row],[Spotted (gm)]])/2)*0.176 -> 45.584 | BE17: 45.58 | BF17: =(AZ17+BA17+BB17)*0.17637 -> 49.03086 | BG17: =+((AX17+AV17+AZ17+BA17+BB17))*0.17637 -> 50.776923 | BH17: =SUM(Table22[[#This Row],[Good Kernel (gm)]:[Spotted (gm)]])/1000*100 -> 27.8 | BI17: =SUM(AV17,AX17,AZ17:BB17)/1000*100 -> 28.79 | BJ17: 10.1 | BK17: 187 | BL17: 614 | BM17: 29 | BN17: 0.09 | BO17: 13 | BP17: 16 | BQ17: =+BM17+BO17+BP17 -> 58 | BR17: 239 | BS17: 28 | BT17: 8 | BU17: =+BR17+BS17+BT17 -> 275 | BV17: =SUM(Table22[[#This Row],[Good Kernel (G M)]]+(Table22[[#This Row],[Immature (g m)]]+Table22[[#This Row],[Spotted (g m)]])/2)*0.176 -> 45.232 | BW17: 45.23 | BY17: =(BR17+BS17+BT17)*0.17637 -> 48.50175 | BZ17: =+((BP17+BM17+BR17+BS17+BT17))*0.17637 -> 56.4384 | CA17: =SUM(Table22[[#This Row],[Good Kernel (G M)]:[Spotted (g m)]])/1000*100 -> 27.5 | CB17: =(Table22[[#This Row],[BROWNS/Rejection (gm) (NUT)]]+Table22[[#This Row],[OIL (g m)]]+Table22[[#This Row],[Good Kernel (G M)]]+Table22[[#This Row],[Immature (g m)]]+Table22[[#This Row],[Spotted (g m)]])/1000*100 -> 32 | CC17: 9.1 | CD17: 182 | CE17: 600 | CH17: =TODAY()-Table22[[#This Row],[Discharge Date]] -> 168
A18: 14 | B18: YAMOUSSOUKRO | C18: ANAGROCI-01 | D18: 14 | F18: 864 | H18: 46115 | K18: OK | L18: B3 | M18: 77666 | N18: BIN-02A | O18: AA 721 PZ 01 | P18: 46087 | Q18: 46087 | R18: VAVOUA | S18: SCAAMT COOP CA | V18: LBA-002-SCA | W18: 488 | X18: 150 | Y18: =W18+X18 -> 638 | Z18: 162 | AA18: =W18+Z18 -> 650 | AB18: =Z18 -> 162 | AC18: 488 | AD18: 0 | AE18: 12 | AF18: 162 | AH18: =+AC18+AD18+AE18+AG18 -> 500 | AI18: 0 | AJ18: 0 | AK18: 500 | AL18: =+AI18+AJ18+AK18 -> 500 | AM18: 52400 | AN18: =(AD18*40)+(AE18*4)+(AG18*0)+(AH18*1) -> 548 | AO18: =AM18-AH18 -> 51900 | AP18: =AM18-AN18 -> 51852 | AQ18: =+AO18-AE18*4 -> 51852 | AR18: =(AD18*40)+(AE18*4)+(AG18*0) -> 48 | AS18: =Table22[[#This Row],[GROSS WT]]-Table22[[#This Row],[Total Bag Discharged (Truck)]] -> 51762 | AT18: =+AO18 -> 51900 | AV18: 9.4 | AW18: 7 | AX18: 0 | AY18: =+AV18+AW18+AX18 -> 16.4 | AZ18: 238 | BA18: 26 | BB18: 14 | BC18: =+AZ18+BA18+BB18 -> 278 | BD18: =SUM(Table22[[#This Row],[Good Kernel (gm)]]+(Table22[[#This Row],[Immature (gm)]]+Table22[[#This Row],[Spotted (gm)]])/2)*0.176 -> 45.408 | BE18: 45.4 | BF18: =(AZ18+BA18+BB18)*0.17637 -> 49.03086 | BG18: =+((AX18+AV18+AZ18+BA18+BB18))*0.17637 -> 50.688738 | BH18: =SUM(Table22[[#This Row],[Good Kernel (gm)]:[Spotted (gm)]])/1000*100 -> 27.8 | BI18: =SUM(AV18,AX18,AZ18:BB18)/1000*100 -> 28.74 | BJ18: 8.5 | BK18: 189 | BL18: 614 | BM18: 28 | BN18: 0.101 | BO18: 16 | BP18: 0 | BQ18: =+BM18+BO18+BP18 -> 44 | BR18: 244 | BS18: 20 | BT18: 10 | BU18: =+BR18+BS18+BT18 -> 274 | BV18: =SUM(Table22[[#This Row],[Good Kernel (G M)]]+(Table22[[#This Row],[Immature (g m)]]+Table22[[#This Row],[Spotted (g m)]])/2)*0.176 -> 45.584 | BW18: 45.58 | BY18: =(BR18+BS18+BT18)*0.17637 -> 48.32538 | BZ18: =+((BP18+BM18+BR18+BS18+BT18))*0.17637 -> 53.26374 | CA18: =SUM(Table22[[#This Row],[Good Kernel (G M)]:[Spotted (g m)]])/1000*100 -> 27.4 | CB18: =(Table22[[#This Row],[BROWNS/Rejection (gm) (NUT)]]+Table22[[#This Row],[OIL (g m)]]+Table22[[#This Row],[Good Kernel (G M)]]+Table22[[#This Row],[Immature (g m)]]+Table22[[#This Row],[Spotted (g m)]])/1000*100 -> 30.2 | CC18: 8.6 | CD18: 190 | CE18: 604 | CH18: =TODAY()-Table22[[#This Row],[Discharge Date]] -> 168
A19: 15 | B19: YAMOUSSOUKRO | C19: ANAGROCI-01 | D19: 15 | F19: 865 | H19: 23/02/2026 | K19: OK | L19: B3 | M19: 68686 | N19: BIN-03A | O19: AA 944 AR 02 | P19: 46088 | Q19: 46088 | R19: VAVOUA | S19: SCAAMT COOP CA | V19: LBA-002-SCA | W19: 583 | X19: 50 | Y19: =W19+X19 -> 633 | Z19: 83 | AA19: =W19+Z19 -> 666 | AB19: =Z19 -> 83 | AC19: 583 | AD19: 0 | AE19: 15 | AF19: 83 | AH19: =+AC19+AD19+AE19+AG19 -> 598 | AI19: 0 | AJ19: 0 | AK19: 598 | AL19: =+AI19+AJ19+AK19 -> 598 | AM19: 49620 | AN19: =(AD19*40)+(AE19*4)+(AG19*0)+(AH19*1) -> 658 | AO19: =AM19-AH19 -> 49022 | AP19: =AM19-AN19 -> 48962 | AQ19: =+AO19-AE19*4 -> 48962 | AR19: =(AD19*40)+(AE19*4)+(AG19*0) -> 60 | AS19: =Table22[[#This Row],[GROSS WT]]-Table22[[#This Row],[Total Bag Discharged (Truck)]] -> 48987 | AT19: =+AO19 -> 49022 | AV19: 9.8 | AW19: 9 | AX19: 0 | AY19: =+AV19+AW19+AX19 -> 18.8 | AZ19: 247 | BA19: 20 | BB19: 6 | BC19: =+AZ19+BA19+BB19 -> 273 | BD19: =SUM(Table22[[#This Row],[Good Kernel (gm)]]+(Table22[[#This Row],[Immature (gm)]]+Table22[[#This Row],[Spotted (gm)]])/2)*0.176 -> 45.76 | BE19: 45.76 | BF19: =(AZ19+BA19+BB19)*0.17637 -> 48.14901 | BG19: =+((AX19+AV19+AZ19+BA19+BB19))*0.17637 -> 49.877436 | BH19: =SUM(Table22[[#This Row],[Good Kernel (gm)]:[Spotted (gm)]])/1000*100 -> 27.3 | BI19: =SUM(AV19,AX19,AZ19:BB19)/1000*100 -> 28.28 | BJ19: 9.4 | BK19: 187 | BL19: 615 | BM19: 8.7 | BN19: 0.087 | BO19: 17 | BP19: 0 | BQ19: =+BM19+BO19+BP19 -> 25.7 | BR19: 245 | BS19: 28 | BT19: 8 | BU19: =+BR19+BS19+BT19 -> 281 | BV19: =SUM(Table22[[#This Row],[Good Kernel (G M)]]+(Table22[[#This Row],[Immature (g m)]]+Table22[[#This Row],[Spotted (g m)]])/2)*0.176 -> 46.288 | BW19: 46.11 | BY19: =(BR19+BS19+BT19)*0.17637 -> 49.55997 | BZ19: =+((BP19+BM19+BR19+BS19+BT19))*0.17637 -> 51.094389 | CA19: =SUM(Table22[[#This Row],[Good Kernel (G M)]:[Spotted (g m)]])/1000*100 -> 28.1 | CB19: =(Table22[[#This Row],[BROWNS/Rejection (gm) (NUT)]]+Table22[[#This Row],[OIL (g m)]]+Table22[[#This Row],[Good Kernel (G M)]]+Table22[[#This Row],[Immature (g m)]]+Table22[[#This Row],[Spotted (g m)]])/1000*100 -> 28.97 | CC19: 9.2 | CD19: 185 | CE19: 610 | CF19: 20 | CG19: 677 | CH19: =TODAY()-Table22[[#This Row],[Discharge Date]] -> 167
A20: 16 | B20: YAMOUSSOUKRO | C20: ANAGROCI-01 | D20: 16 | F20: 866 | H20: 46206 | K20: OK | L20: B3 | M20: 77678 | N20: BIN-03A | O20: 2744KK02 | P20: 46089 | Q20: 46089 | R20: VAVOUA | S20: SCAAMT COOP CA | V20: LBA-002-SCA | W20: 497 | X20: 24 | Y20: =W20+X20 -> 521 | Z20: 43 | AA20: =W20+Z20 -> 540 | AB20: =Z20 -> 43 | AC20: 501 | AD20: 0 | AE20: 20 | AF20: 43 | AH20: =+AC20+AD20+AE20+AG20 -> 521 | AI20: 0 | AJ20: 0 | AK20: 521 | AL20: =+AI20+AJ20+AK20 -> 521 | AM20: 41800 | AN20: =(AD20*40)+(AE20*4)+(AG20*0)+(AH20*1) -> 601 | AO20: =AM20-AH20 -> 41279 | AP20: =AM20-AN20 -> 41199 | AQ20: =+AO20-AE20*4 -> 41199 | AR20: =(AD20*40)+(AE20*4)+(AG20*0) -> 80 | AS20: =Table22[[#This Row],[GROSS WT]]-Table22[[#This Row],[Total Bag Discharged (Truck)]] -> 41279 | AT20: =+AO20 -> 41279 | AV20: 8.9 | AW20: 4 | AX20: 0 | AY20: =+AV20+AW20+AX20 -> 12.9 | AZ20: 252 | BA20: 20 | BB20: 8 | BC20: =+AZ20+BA20+BB20 -> 280 | BD20: =SUM(Table22[[#This Row],[Good Kernel (gm)]]+(Table22[[#This Row],[Immature (gm)]]+Table22[[#This Row],[Spotted (gm)]])/2)*0.176 -> 46.816 | BE20: 46.81 | BF20: =(AZ20+BA20+BB20)*0.17637 -> 49.3836 | BG20: =+((AX20+AV20+AZ20+BA20+BB20))*0.17637 -> 50.953293 | BH20: =SUM(Table22[[#This Row],[Good Kernel (gm)]:[Spotted (gm)]])/1000*100 -> 28 | BI20: =SUM(AV20,AX20,AZ20:BB20)/1000*100 -> 28.89 | BJ20: 9.7 | BK20: 182 | BL20: 621 | BM20: 9.8 | BN20: 0.098 | BO20: 0 | BP20: 0 | BQ20: =+BM20+BO20+BP20 -> 9.8 | BR20: 247 | BS20: 26 | BT20: 8 | BU20: =+BR20+BS20+BT20 -> 281 | BV20: =SUM(Table22[[#This Row],[Good Kernel (G M)]]+(Table22[[#This Row],[Immature (g m)]]+Table22[[#This Row],[Spotted (g m)]])/2)*0.176 -> 46.464 | BW20: 46.46 | BY20: =(BR20+BS20+BT20)*0.17637 -> 49.55997 | BZ20: =+((BP20+BM20+BR20+BS20+BT20))*0.17637 -> 51.288396 | CA20: =SUM(Table22[[#This Row],[Good Kernel (G M)]:[Spotted (g m)]])/1000*100 -> 28.1 | CB20: =(Table22[[#This Row],[BROWNS/Rejection (gm) (NUT)]]+Table22[[#This Row],[OIL (g m)]]+Table22[[#This Row],[Good Kernel (G M)]]+Table22[[#This Row],[Immature (g m)]]+Table22[[#This Row],[Spotted (g m)]])/1000*100 -> 29.08 | CC20: 9.9 | CD20: 189 | CE20: 617 | CF20: 19 | CG20: 696 | CH20: =TODAY()-Table22[[#This Row],[Discharge Date]] -> 166
A21: 17 | B21: YAMOUSSOUKRO | C21: ANAGROCI-01 | D21: 17 | F21: 867 | H21: 46237 | K21: OK | L21: B3 | M21: 77581 | N21: BIN-03A | O21: 285 LA 01 | P21: 46090 | Q21: 46090 | R21: VAVOUA | S21: COP JAVA SCOOP | V21: LBA-005-JAV | W21: 529 | X21: 75 | Y21: =W21+X21 -> 604 | Z21: 81 | AA21: =W21+Z21 -> 610 | AB21: =Z21 -> 81 | AC21: 584 | AD21: 0 | AE21: 20 | AF21: 81 | AH21: =+AC21+AD21+AE21+AG21 -> 604 | AI21: 0 | AJ21: 0 | AK21: 604 | AL21: =+AI21+AJ21+AK21 -> 604 | AM21: 45400 | AN21: =(AD21*40)+(AE21*4)+(AG21*0)+(AH21*1) -> 684 | AO21: =AM21-AH21 -> 44796 | AP21: =AM21-AN21 -> 44716 | AQ21: =+AO21-AE21*4 -> 44716 | AR21: =(AD21*40)+(AE21*4)+(AG21*0) -> 80 | AS21: =Table22[[#This Row],[GROSS WT]]-Table22[[#This Row],[Total Bag Discharged (Truck)]] -> 44796 | AT21: =+AO21 -> 44796 | AV21: 9.7 | AW21: 4 | AX21: 5 | AY21: =+AV21+AW21+AX21 -> 18.7 | AZ21: 242 | BA21: 26 | BB21: 6 | BC21: =+AZ21+BA21+BB21 -> 274 | BD21: =SUM(Table22[[#This Row],[Good Kernel (gm)]]+(Table22[[#This Row],[Immature (gm)]]+Table22[[#This Row],[Spotted (gm)]])/2)*0.176 -> 45.408 | BE21: 45.4 | BF21: =(AZ21+BA21+BB21)*0.17637 -> 48.32538 | BG21: =+((AX21+AV21+AZ21+BA21+BB21))*0.17637 -> 50.918019 | BH21: =SUM(Table22[[#This Row],[Good Kernel (gm)]:[Spotted (gm)]])/1000*100 -> 27.4 | BI21: =SUM(AV21,AX21,AZ21:BB21)/1000*100 -> 28.87 | BJ21: 11.3 | BK21: 178 | BL21: 615 | BM21: 8.6 | BN21: 0.086 | BO21: 10 | BP21: 7 | BQ21: =+BM21+BO21+BP21 -> 25.6 | BR21: 253 | BS21: 20 | BT21: 8 | BU21: =+BR21+BS21+BT21 -> 281 | BV21: =SUM(Table22[[#This Row],[Good Kernel (G M)]]+(Table22[[#This Row],[Immature (g m)]]+Table22[[#This Row],[Spotted (g m)]])/2)*0.176 -> 46.992 | BW21: 46.99 | BY21: =(BR21+BS21+BT21)*0.17637 -> 49.55997 | BZ21: =+((BP21+BM21+BR21+BS21+BT21))*0.17637 -> 52.311342 | CA21: =SUM(Table22[[#This Row],[Good Kernel (G M)]:[Spotted (g m)]])/1000*100 -> 28.1 | CB21: =(Table22[[#This Row],[BROWNS/Rejection (gm) (NUT)]]+Table22[[#This Row],[OIL (g m)]]+Table22[[#This Row],[Good Kernel (G M)]]+Table22[[#This Row],[Immature (g m)]]+Table22[[#This Row],[Spotted (g m)]])/1000*100 -> 29.66 | CC21: 11.2 | CD21: 181 | CE21: 609 | CF21: 22 | CG21: 675 | CH21: =TODAY()-Table22[[#This Row],[Discharge Date]] -> 165
A22: 18 | B22: YAMOUSSOUKRO | C22: ANAGROCI-01 | D22: 18 | F22: 868 | H22: 46237 | K22: OK | L22: B3 | M22: 68685 | N22: BIN-03A | O22: AA 721 PZ 01 | P22: 46090 | Q22: 46090 | R22: VAVOUA | S22: SCAAMT COOP CA | V22: LBA-002-SCA | W22: 560 | X22: 54 | Y22: =W22+X22 -> 614 | Z22: 93 | AA22: =W22+Z22 -> 653 | AB22: =Z22 -> 93 | AC22: 596 | AD22: 0 | AE22: 18 | AF22: 93 | AH22: =+AC22+AD22+AE22+AG22 -> 614 | AI22: 0 | AJ22: 0 | AK22: 614 | AL22: =+AI22+AJ22+AK22 -> 614 | AM22: 51260 | AN22: =(AD22*40)+(AE22*4)+(AG22*0)+(AH22*1) -> 686 | AO22: =AM22-AH22 -> 50646 | AP22: =AM22-AN22 -> 50574 | AQ22: =+AO22-AE22*4 -> 50574 | AR22: =(AD22*40)+(AE22*4)+(AG22*0) -> 72 | AS22: =Table22[[#This Row],[GROSS WT]]-Table22[[#This Row],[Total Bag Discharged (Truck)]] -> 50646 | AT22: =+AO22 -> 50646 | AV22: 9.5 | AW22: 21 | AX22: 8 | AY22: =+AV22+AW22+AX22 -> 38.5 | AZ22: 248 | BA22: 16 | BB22: 10 | BC22: =+AZ22+BA22+BB22 -> 274 | BD22: =SUM(Table22[[#This Row],[Good Kernel (gm)]]+(Table22[[#This Row],[Immature (gm)]]+Table22[[#This Row],[Spotted (gm)]])/2)*0.176 -> 45.936 | BE22: 45.93 | BF22: =(AZ22+BA22+BB22)*0.17637 -> 48.32538 | BG22: =+((AX22+AV22+AZ22+BA22+BB22))*0.17637 -> 51.411855 | BH22: =SUM(Table22[[#This Row],[Good Kernel (gm)]:[Spotted (gm)]])/1000*100 -> 27.4 | BI22: =SUM(AV22,AX22,AZ22:BB22)/1000*100 -> 29.15 | BJ22: 10.4 | BK22: 185 | BL22: 596 | BM22: 9.1 | BN22: 0.091 | BO22: 8 | BP22: 0 | BQ22: =+BM22+BO22+BP22 -> 17.1 | BR22: 248 | BS22: 22 | BT22: 12 | BU22: =+BR22+BS22+BT22 -> 282 | BV22: =SUM(Table22[[#This Row],[Good Kernel (G M)]]+(Table22[[#This Row],[Immature (g m)]]+Table22[[#This Row],[Spotted (g m)]])/2)*0.176 -> 46.64 | BW22: 46.64 | BY22: =(BR22+BS22+BT22)*0.17637 -> 49.73634 | BZ22: =+((BP22+BM22+BR22+BS22+BT22))*0.17637 -> 51.341307 | CA22: =SUM(Table22[[#This Row],[Good Kernel (G M)]:[Spotted (g m)]])/1000*100 -> 28.2 | CB22: =(Table22[[#This Row],[BROWNS/Rejection (gm) (NUT)]]+Table22[[#This Row],[OIL (g m)]]+Table22[[#This Row],[Good Kernel (G M)]]+Table22[[#This Row],[Immature (g m)]]+Table22[[#This Row],[Spotted (g m)]])/1000*100 -> 29.11 | CC22: 10.3 | CD22: 177 | CE22: 614 | CF22: 19 | CG22: 687 | CH22: =TODAY()-Table22[[#This Row],[Discharge Date]] -> 165
A23: 19 | B23: YAMOUSSOUKRO | C23: ANAGROCI-01 | D23: 19 | F23: 869 | H23: 46237 | K23: OK | L23: B3 | M23: 66643 | N23: BIN-04A | O23: AA 944 AK | P23: 46090 | Q23: 46090 | R23: VAVOUA | S23: SCAAMT COOP CA | V23: LBA-002-SCA | W23: 545 | X23: 220 | Y23: =W23+X23 -> 765 | Z23: 199 | AA23: =W23+Z23 -> 744 | AB23: =Z23 -> 199 | AC23: 747 | AD23: 0 | AE23: 18 | AF23: 199 | AH23: 765 | AI23: 0 | AJ23: 0 | AK23: 765 | AL23: =+AI23+AJ23+AK23 -> 765 | AM23: 52860 | AN23: =(AD23*40)+(AE23*4)+(AG23*0)+(AH23*1) -> 837 | AO23: =AM23-AH23 -> 52095 | AP23: =AM23-AN23 -> 52023 | AQ23: =+AO23-AE23*4 -> 52023 | AR23: =(AD23*40)+(AE23*4)+(AG23*0) -> 72 | AS23: =Table22[[#This Row],[GROSS WT]]-Table22[[#This Row],[Total Bag Discharged (Truck)]] -> 52095 | AT23: =+AO23 -> 52095 | AV23: 8.8 | AW23: 0 | AX23: 6 | AY23: =+AV23+AW23+AX23 -> 14.8 | AZ23: 246 | BA23: 18 | BB23: 8 | BC23: =+AZ23+BA23+BB23 -> 272 | BD23: =SUM(Table22[[#This Row],[Good Kernel (gm)]]+(Table22[[#This Row],[Immature (gm)]]+Table22[[#This Row],[Spotted (gm)]])/2)*0.176 -> 45.584 | BE23: 45.58 | BF23: =(AZ23+BA23+BB23)*0.17637 -> 47.97264 | BG23: =+((AX23+AV23+AZ23+BA23+BB23))*0.17637 -> 50.582916 | BH23: =SUM(Table22[[#This Row],[Good Kernel (gm)]:[Spotted (gm)]])/1000*100 -> 27.2 | BI23: =SUM(AV23,AX23,AZ23:BB23)/1000*100 -> 28.68 | BJ23: 10.8 | BK23: 186 | BL23: 627 | BM23: 10.5 | BN23: 0.105 | BO23: 18 | BP23: 0 | BQ23: =+BM23+BO23+BP23 -> 28.5 | BR23: 241 | BS23: 24 | BT23: 8 | BU23: =+BR23+BS23+BT23 -> 273 | BV23: =SUM(Table22[[#This Row],[Good Kernel (G M)]]+(Table22[[#This Row],[Immature (g m)]]+Table22[[#This Row],[Spotted (g m)]])/2)*0.176 -> 45.232 | BW23: 45.23 | BY23: =(BR23+BS23+BT23)*0.17637 -> 48.14901 | BZ23: =+((BP23+BM23+BR23+BS23+BT23))*0.17637 -> 50.000895 | CA23: =SUM(Table22[[#This Row],[Good Kernel (G M)]:[Spotted (g m)]])/1000*100 -> 27.3 | CB23: =(Table22[[#This Row],[BROWNS/Rejection (gm) (NUT)]]+Table22[[#This Row],[OIL (g m)]]+Table22[[#This Row],[Good Kernel (G M)]]+Table22[[#This Row],[Immature (g m)]]+Table22[[#This Row],[Spotted (g m)]])/1000*100 -> 28.35 | CC23: 10.8 | CD23: 189 | CE23: 597 | CF23: 26 | CG23: 678 | CH23: =TODAY()-Table22[[#This Row],[Discharge Date]] -> 165
A24: 20 | B24: YAMOUSSOUKRO | C24: ANAGROCI-01 | D24: 20 | F24: 870 | H24: 46237 | K24: OK | L24: B3 | M24: 77630 | N24: BIN-04A | O24: 8867 GY 03 | P24: 46091 | Q24: 46091 | R24: KOROGHO | S24: RCN SCOOPS SKS | V24: LBA-020-SKS | W24: 390 | X24: 37 | Y24: =W24+X24 -> 427 | Z24: 88 | AA24: =W24+Z24 -> 478 | AB24: =Z24 -> 88 | AC24: 407 | AD24: 0 | AE24: 20 | AF24: 88 | AH24: 427 | AI24: 0 | AJ24: 0 | AK24: 427 | AL24: =+AI24+AJ24+AK24 -> 427 | AM24: 40040 | AN24: =(AD24*40)+(AE24*4)+(AG24*0)+(AH24*1) -> 507 | AO24: =AM24-AH24 -> 39613 | AP24: =AM24-AN24 -> 39533 | AQ24: =+AO24-AE24*4 -> 39533 | AR24: =(AD24*40)+(AE24*4)+(AG24*0) -> 80 | AS24: =Table22[[#This Row],[GROSS WT]]-Table22[[#This Row],[Total Bag Discharged (Truck)]] -> 39613 | AT24: =+AO24 -> 39613 | AV24: 14 | AW24: 24 | AX24: 0 | AY24: =+AV24+AW24+AX24 -> 38 | AZ24: 245 | BA24: 12 | BB24: 8 | BC24: =+AZ24+BA24+BB24 -> 265 | BD24: =SUM(Table22[[#This Row],[Good Kernel (gm)]]+(Table22[[#This Row],[Immature (gm)]]+Table22[[#This Row],[Spotted (gm)]])/2)*0.176 -> 44.88 | BE24: 44.88 | BF24: =(AZ24+BA24+BB24)*0.17637 -> 46.73805 | BG24: =+((AX24+AV24+AZ24+BA24+BB24))*0.17637 -> 49.20723 | BH24: =SUM(Table22[[#This Row],[Good Kernel (gm)]:[Spotted (gm)]])/1000*100 -> 26.5 | BI24: =SUM(AV24,AX24,AZ24:BB24)/1000*100 -> 27.9 | BJ24: 9.9 | BK24: 170 | BL24: 644 | BM24: 17 | BN24: 0.073 | BO24: 20 | BP24: 0 | BQ24: =+BM24+BO24+BP24 -> 37 | BR24: 239 | BS24: 20 | BT24: 15 | BU24: =+BR24+BS24+BT24 -> 274 | BV24: =SUM(Table22[[#This Row],[Good Kernel (G M)]]+(Table22[[#This Row],[Immature (g m)]]+Table22[[#This Row],[Spotted (g m)]])/2)*0.176 -> 45.144 | BW24: 45.14 | BY24: =(BR24+BS24+BT24)*0.17637 -> 48.32538 | BZ24: =+((BP24+BM24+BR24+BS24+BT24))*0.17637 -> 51.32367 | CA24: =SUM(Table22[[#This Row],[Good Kernel (G M)]:[Spotted (g m)]])/1000*100 -> 27.4 | CB24: =(Table22[[#This Row],[BROWNS/Rejection (gm) (NUT)]]+Table22[[#This Row],[OIL (g m)]]+Table22[[#This Row],[Good Kernel (G M)]]+Table22[[#This Row],[Immature (g m)]]+Table22[[#This Row],[Spotted (g m)]])/1000*100 -> 29.1 | CC24: 9.9 | CD24: 175 | CE24: 627 | CH24: =TODAY()-Table22[[#This Row],[Discharge Date]] -> 164
A25: 21 | B25: YAMOUSSOUKRO | C25: ANAGROCI-01 | D25: 21 | F25: 871 | H25: 46206 | K25: OK | L25: B3 | M25: 77677 | N25: BIN-03A | O25: 5739 GH 01 | P25: 46089 | Q25: 46092 | R25: VAVOUA | S25: SCAAMT COOP CA | V25: LBA-002-SCA | W25: 570 | X25: 97 | Y25: =W25+X25 -> 667 | Z25: 88 | AA25: =W25+Z25 -> 658 | AB25: =Z25 -> 88 | AC25: 647 | AD25: 0 | AE25: 20 | AF25: 88 | AH25: 667 | AI25: 0 | AJ25: 0 | AK25: 667 | AL25: =+AI25+AJ25+AK25 -> 667 | AM25: 52040 | AN25: =(AD25*40)+(AE25*4)+(AG25*0)+(AH25*1) -> 747 | AO25: =AM25-AH25 -> 51373 | AP25: =AM25-AN25 -> 51293 | AQ25: =+AO25-AE25*4 -> 51293 | AR25: =(AD25*40)+(AE25*4)+(AG25*0) -> 80 | AS25: =Table22[[#This Row],[GROSS WT]]-Table22[[#This Row],[Total Bag Discharged (Truck)]] -> 51373 | AT25: =+AO25 -> 51373 | AV25: 8.9 | AW25: 13 | AX25: 3 | AY25: =+AV25+AW25+AX25 -> 24.9 | AZ25: 243 | BA25: 26 | BB25: 6 | BC25: =+AZ25+BA25+BB25 -> 275 | BD25: =SUM(Table22[[#This Row],[Good Kernel (gm)]]+(Table22[[#This Row],[Immature (gm)]]+Table22[[#This Row],[Spotted (gm)]])/2)*0.176 -> 45.584 | BE25: 45.58 | BF25: =(AZ25+BA25+BB25)*0.17637 -> 48.50175 | BG25: =+((AX25+AV25+AZ25+BA25+BB25))*0.17637 -> 50.600553 | BH25: =SUM(Table22[[#This Row],[Good Kernel (gm)]:[Spotted (gm)]])/1000*100 -> 27.5 | BI25: =SUM(AV25,AX25,AZ25:BB25)/1000*100 -> 28.69 | BJ25: 9.8 | BK25: 181 | BL25: 614 | BM25: 20 | BN25: 0.081 | BO25: 4 | BP25: 0 | BQ25: =+BM25+BO25+BP25 -> 24 | BR25: 250 | BS25: 18 | BT25: 6 | BU25: =+BR25+BS25+BT25 -> 274 | BV25: =SUM(Table22[[#This Row],[Good Kernel (G M)]]+(Table22[[#This Row],[Immature (g m)]]+Table22[[#This Row],[Spotted (g m)]])/2)*0.176 -> 46.112 | BW25: 46.11 | BY25: =(BR25+BS25+BT25)*0.17637 -> 48.32538 | BZ25: =+((BP25+BM25+BR25+BS25+BT25))*0.17637 -> 51.85278 | CA25: =SUM(Table22[[#This Row],[Good Kernel (G M)]:[Spotted (g m)]])/1000*100 -> 27.4 | CB25: =(Table22[[#This Row],[BROWNS/Rejection (gm) (NUT)]]+Table22[[#This Row],[OIL (g m)]]+Table22[[#This Row],[Good Kernel (G M)]]+Table22[[#This Row],[Immature (g m)]]+Table22[[#This Row],[Spotted (g m)]])/1000*100 -> 29.4 | CC25: 9.3 | CD25: 188 | CE25: 634 | CH25: =TODAY()-Table22[[#This Row],[Discharge Date]] -> 163
A26: 22 | B26: YAMOUSSOUKRO | C26: ANAGROCI-01 | D26: 22 | F26: 872 | H26: 46298 | K26: OK | L26: B3 | M26: 82102 | N26: BIN-02A | O26: 2319 LR 02 | P26: 46092 | Q26: 46092 | R26: VAVOUA | S26: SCAAMT COOP CA | V26: LBA-002-SCA | W26: 473 | X26: 63 | Y26: =W26+X26 -> 536 | Z26: 90 | AA26: =W26+Z26 -> 563 | AB26: =Z26 -> 90 | AC26: 516 | AD26: 0 | AE26: 20 | AF26: 90 | AH26: 536 | AI26: 0 | AJ26: 0 | AK26: 536 | AL26: =+AI26+AJ26+AK26 -> 536 | AM26: 41160 | AN26: =(AD26*40)+(AE26*4)+(AG26*0)+(AH26*1) -> 616 | AO26: =AM26-AH26 -> 40624 | AP26: =AM26-AN26 -> 40544 | AQ26: =+AO26-AE26*4 -> 40544 | AR26: =(AD26*40)+(AE26*4)+(AG26*0) -> 80 | AS26: =Table22[[#This Row],[GROSS WT]]-Table22[[#This Row],[Total Bag Discharged (Truck)]] -> 40624 | AT26: =+AO26 -> 40624 | AV26: 10.9 | AW26: 7 | AX26: 4 | AY26: =+AV26+AW26+AX26 -> 21.9 | AZ26: 242 | BA26: 20 | BB26: 10 | BC26: =+AZ26+BA26+BB26 -> 272 | BD26: =SUM(Table22[[#This Row],[Good Kernel (gm)]]+(Table22[[#This Row],[Immature (gm)]]+Table22[[#This Row],[Spotted (gm)]])/2)*0.176 -> 45.232 | BE26: 45.23 | BF26: =(AZ26+BA26+BB26)*0.17637 -> 47.97264 | BG26: =+((AX26+AV26+AZ26+BA26+BB26))*0.17637 -> 50.600553 | BH26: =SUM(Table22[[#This Row],[Good Kernel (gm)]:[Spotted (gm)]])/1000*100 -> 27.2 | BI26: =SUM(AV26,AX26,AZ26:BB26)/1000*100 -> 28.69 | BJ26: 10.6 | BK26: 190 | BL26: 601 | BM26: 24 | BN26: 0.092 | BO26: 13 | BP26: 0 | BQ26: =+BM26+BO26+BP26 -> 37 | BR26: 251 | BS26: 12 | BT26: 8 | BU26: =+BR26+BS26+BT26 -> 271 | BV26: =SUM(Table22[[#This Row],[Good Kernel (G M)]]+(Table22[[#This Row],[Immature (g m)]]+Table22[[#This Row],[Spotted (g m)]])/2)*0.176 -> 45.936 | BW26: 45.93 | BY26: =(BR26+BS26+BT26)*0.17637 -> 47.79627 | BZ26: =+((BP26+BM26+BR26+BS26+BT26))*0.17637 -> 52.02915 | CA26: =SUM(Table22[[#This Row],[Good Kernel (G M)]:[Spotted (g m)]])/1000*100 -> 27.1 | CB26: =(Table22[[#This Row],[BROWNS/Rejection (gm) (NUT)]]+Table22[[#This Row],[OIL (g m)]]+Table22[[#This Row],[Good Kernel (G M)]]+Table22[[#This Row],[Immature (g m)]]+Table22[[#This Row],[Spotted (g m)]])/1000*100 -> 29.5 | CC26: 10.3 | CD26: 184 | CE26: 618 | CH26: =TODAY()-Table22[[#This Row],[Discharge Date]] -> 163
A27: 23 | B27: YAMOUSSOUKRO | C27: ANAGROCI-01 | D27: 23 | E27: Dry Lot | F27: 873 | H27: 46298 | K27: OK | L27: B3 | M27: 77676 | N27: BIN-002 | O27: 4379 LL 02 | P27: 46093 | Q27: 46093 | R27: WOROBOUGOU | S27: SCAAMT COOP CA | V27: LBA-002-SCA | W27: 561 | X27: 35 | Y27: =W27+X27 -> 596 | Z27: 67 | AA27: =W27+Z27 -> 628 | AB27: =Z27 -> 67 | AC27: 576 | AD27: 0 | AE27: 20 | AF27: 67 | AH27: 596 | AJ27: 0 | AK27: 596 | AL27: =+AI27+AJ27+AK27 -> 596 | AM27: 49460 | AN27: =(AD27*40)+(AE27*4)+(AG27*0)+(AH27*1) -> 676 | AO27: =AM27-AH27 -> 48864 | AP27: =AM27-AN27 -> 48784 | AQ27: =+AO27-AE27*4 -> 48784 | AR27: =(AD27*40)+(AE27*4)+(AG27*0) -> 80 | AS27: =Table22[[#This Row],[GROSS WT]]-Table22[[#This Row],[Total Bag Discharged (Truck)]] -> 48864 | AT27: =+AO27 -> 48864 | AV27: 8.3 | AW27: 17 | AX27: 0 | AY27: =+AV27+AW27+AX27 -> 25.3 | AZ27: 246 | BA27: 16 | BB27: 6 | BC27: =+AZ27+BA27+BB27 -> 268 | BD27: =SUM(Table22[[#This Row],[Good Kernel (gm)]]+(Table22[[#This Row],[Immature (gm)]]+Table22[[#This Row],[Spotted (gm)]])/2)*0.176 -> 45.232 | BE27: 45.23 | BF27: =(AZ27+BA27+BB27)*0.17637 -> 47.26716 | BG27: =+((AX27+AV27+AZ27+BA27+BB27))*0.17637 -> 48.731031 | BH27: =SUM(Table22[[#This Row],[Good Kernel (gm)]:[Spotted (gm)]])/1000*100 -> 26.8 | BI27: =SUM(AV27,AX27,AZ27:BB27)/1000*100 -> 27.63 | BJ27: 11 | BK27: 177 | BL27: 625 | BM27: 23 | BN27: 0.081 | BO27: 21 | BP27: 0 | BQ27: =+BM27+BO27+BP27 -> 44 | BR27: 243 | BS27: 18 | BT27: 9 | BU27: =+BR27+BS27+BT27 -> 270 | BV27: =SUM(Table22[[#This Row],[Good Kernel (G M)]]+(Table22[[#This Row],[Immature (g m)]]+Table22[[#This Row],[Spotted (g m)]])/2)*0.176 -> 45.144 | BW27: 45.14 | BX27: 45.67 | BY27: =(BR27+BS27+BT27)*0.17637 -> 47.6199 | BZ27: =+((BP27+BM27+BR27+BS27+BT27))*0.17637 -> 51.67641 | CA27: =SUM(Table22[[#This Row],[Good Kernel (G M)]:[Spotted (g m)]])/1000*100 -> 27 | CB27: =(Table22[[#This Row],[BROWNS/Rejection (gm) (NUT)]]+Table22[[#This Row],[OIL (g m)]]+Table22[[#This Row],[Good Kernel (G M)]]+Table22[[#This Row],[Immature (g m)]]+Table22[[#This Row],[Spotted (g m)]])/1000*100 -> 29.3 | CC27: 11 | CD27: 171 | CE27: 612 | CH27: =TODAY()-Table22[[#This Row],[Discharge Date]] -> 162
A28: 24 | B28: YAMOUSSOUKRO | C28: ANAGROCI-01 | D28: 24 | F28: 874 | K28: OK | L28: B3 | M28: 82161 | N28: BIN-04A | O28: 285 LA 01 | P28: 46094 | Q28: 46094 | R28: VAVOUA | S28: COP JAVA SCOOP | V28: LBA-005-JAV | W28: 531 | X28: 58 | Y28: =W28+X28 -> 589 | Z28: 58 | AA28: =W28+Z28 -> 589 | AB28: =Z28 -> 58 | AC28: 569 | AD28: 0 | AE28: 20 | AF28: 58 | AH28: 589 | AI28: 0 | AJ28: 0 | AK28: 589 | AL28: =+AI28+AJ28+AK28 -> 589 | AM28: 46220 | AN28: =(AD28*40)+(AE28*4)+(AG28*0)+(AH28*1) -> 669 | AO28: =AM28-AH28 -> 45631 | AP28: =AM28-AN28 -> 45551 | AQ28: =+AO28-AE28*4 -> 45551 | AR28: =(AD28*40)+(AE28*4)+(AG28*0) -> 80 | AS28: =Table22[[#This Row],[GROSS WT]]-Table22[[#This Row],[Total Bag Discharged (Truck)]] -> 45631 | AT28: =+AO28 -> 45631 | AV28: 23 | AW28: 19 | AX28: 3 | AY28: =+AV28+AW28+AX28 -> 45 | AZ28: 244 | BA28: 20 | BB28: 8 | BC28: =+AZ28+BA28+BB28 -> 272 | BD28: =SUM(Table22[[#This Row],[Good Kernel (gm)]]+(Table22[[#This Row],[Immature (gm)]]+Table22[[#This Row],[Spotted (gm)]])/2)*0.176 -> 45.408 | BE28: 45.4 | BF28: =(AZ28+BA28+BB28)*0.17637 -> 47.97264 | BG28: =+((AX28+AV28+AZ28+BA28+BB28))*0.17637 -> 52.55826 | BH28: =SUM(Table22[[#This Row],[Good Kernel (gm)]:[Spotted (gm)]])/1000*100 -> 27.2 | BI28: =SUM(AV28,AX28,AZ28:BB28)/1000*100 -> 29.8 | BJ28: 10.1 | BK28: 182 | BL28: 616 | BM28: 21 | BO28: 29 | BP28: 0 | BQ28: =+BM28+BO28+BP28 -> 50 | BR28: 250 | BS28: 12 | BT28: 6 | BU28: =+BR28+BS28+BT28 -> 268 | BV28: =SUM(Table22[[#This Row],[Good Kernel (G M)]]+(Table22[[#This Row],[Immature (g m)]]+Table22[[#This Row],[Spotted (g m)]])/2)*0.176 -> 45.584 | BW28: 45.58 | BY28: =(BR28+BS28+BT28)*0.17637 -> 47.26716 | BZ28: =+((BP28+BM28+BR28+BS28+BT28))*0.17637 -> 50.97093 | CA28: =SUM(Table22[[#This Row],[Good Kernel (G M)]:[Spotted (g m)]])/1000*100 -> 26.8 | CB28: =(Table22[[#This Row],[BROWNS/Rejection (gm) (NUT)]]+Table22[[#This Row],[OIL (g m)]]+Table22[[#This Row],[Good Kernel (G M)]]+Table22[[#This Row],[Immature (g m)]]+Table22[[#This Row],[Spotted (g m)]])/1000*100 -> 28.9 | CC28: 10.1 | CD28: 181 | CE28: 615 | CH28: =TODAY()-Table22[[#This Row],[Discharge Date]] -> 161
A29: 25 | B29: YAMOUSSOUKRO | C29: ANAGROCI-01 | D29: 25 | F29: 876 | K29: OK | L29: B3 | M29: 82103 | N29: BIN-001A | O29: 5739 GN 01 | P29: 46094 | Q29: 46094 | R29: VAVOUA | S29: SCAAMT COOP CA | V29: LBA-002-SCA | W29: 560 | X29: 27 | Y29: =W29+X29 -> 587 | Z29: 28 | AA29: =W29+Z29 -> 588 | AB29: =Z29 -> 28 | AC29: 567 | AD29: 0 | AE29: 20 | AF29: 28 | AH29: 587 | AI29: 0 | AJ29: 0 | AK29: 587 | AL29: =+AI29+AJ29+AK29 -> 587 | AM29: 49740 | AN29: =(AD29*40)+(AE29*4)+(AG29*0)+(AH29*1) -> 667 | AO29: =AM29-AH29 -> 49153 | AP29: =AM29-AN29 -> 49073 | AQ29: =+AO29-AE29*4 -> 49073 | AR29: =(AD29*40)+(AE29*4)+(AG29*0) -> 80 | AS29: =Table22[[#This Row],[GROSS WT]]-Table22[[#This Row],[Total Bag Discharged (Truck)]] -> 49153 | AT29: =+AO29 -> 49153 | AV29: 20 | AW29: 17 | AX29: 3 | AY29: =+AV29+AW29+AX29 -> 40 | AZ29: 249 | BA29: 16 | BB29: 8 | BC29: =+AZ29+BA29+BB29 -> 273 | BD29: =SUM(Table22[[#This Row],[Good Kernel (gm)]]+(Table22[[#This Row],[Immature (gm)]]+Table22[[#This Row],[Spotted (gm)]])/2)*0.176 -> 45.936 | BE29: 45.93 | BF29: =(AZ29+BA29+BB29)*0.17637 -> 48.14901 | BG29: =+((AX29+AV29+AZ29+BA29+BB29))*0.17637 -> 52.20552 | BH29: =SUM(Table22[[#This Row],[Good Kernel (gm)]:[Spotted (gm)]])/1000*100 -> 27.3 | BI29: =SUM(AV29,AX29,AZ29:BB29)/1000*100 -> 29.6 | BJ29: 10 | BK29: 175 | BL29: 630 | BM29: 12 | BO29: 24 | BP29: 2 | BQ29: =+BM29+BO29+BP29 -> 38 | BR29: 260 | BS29: 8 | BT29: 12 | BU29: =+BR29+BS29+BT29 -> 280 | BV29: =SUM(Table22[[#This Row],[Good Kernel (G M)]]+(Table22[[#This Row],[Immature (g m)]]+Table22[[#This Row],[Spotted (g m)]])/2)*0.176 -> 47.52 | BW29: 47.52 | BY29: =(BR29+BS29+BT29)*0.17637 -> 49.3836 | BZ29: =+((BP29+BM29+BR29+BS29+BT29))*0.17637 -> 51.85278 | CA29: =SUM(Table22[[#This Row],[Good Kernel (G M)]:[Spotted (g m)]])/1000*100 -> 28 | CB29: =(Table22[[#This Row],[BROWNS/Rejection (gm) (NUT)]]+Table22[[#This Row],[OIL (g m)]]+Table22[[#This Row],[Good Kernel (G M)]]+Table22[[#This Row],[Immature (g m)]]+Table22[[#This Row],[Spotted (g m)]])/1000*100 -> 29.4 | CC29: 10 | CD29: 175 | CE29: 626 | CH29: =TODAY()-Table22[[#This Row],[Discharge Date]] -> 161
